2025-09-17 09:18:09 - INFO - ###############################
2025-09-17 09:18:09 - INFO - TEST INFO LOGGING FINALLY
2025-09-17 09:18:09 - WARNING - TEST WARNING LOGGING FINALLY
2025-09-17 09:18:09 - ERROR - Error to: utils.my_logger | Index: 0
NoneType: None
2025-09-17 09:18:09 - CRITICAL - TEST FATAL LOGGING FINALLY
2025-09-17 09:18:09 - INFO - LOGGER STARTED
2025-09-17 09:18:09 - INFO - ###############################
2025-09-17 09:18:10 - INFO - Stated connect to db
2025-09-17 09:18:10 - INFO - Users db created/exist
2025-09-17 09:18:10 - INFO - WS Parser started!
2025-09-17 09:18:10 - INFO - Getting data from server
2025-09-17 09:18:11 - INFO - 488635832 used HELP MESSAGE FUNC
2025-09-17 09:18:11 - ERROR - Infinity polling exception: UNIQUE constraint failed: users.tg_id
2025-09-17 09:18:11 - ERROR - Exception traceback:
Traceback (most recent call last):
  File "K:\Scedule_Bot_1.0\.venv\Lib\site-packages\telebot\__init__.py", line 1110, in infinity_polling
    self.polling(non_stop=True, timeout=timeout, long_polling_timeout=long_polling_timeout,
  File "K:\Scedule_Bot_1.0\.venv\Lib\site-packages\telebot\__init__.py", line 1198, in polling
    self.__threaded_polling(non_stop=non_stop, interval=interval, timeout=timeout, long_polling_timeout=long_polling_timeout,
  File "K:\Scedule_Bot_1.0\.venv\Lib\site-packages\telebot\__init__.py", line 1273, in __threaded_polling
    raise e
  File "K:\Scedule_Bot_1.0\.venv\Lib\site-packages\telebot\__init__.py", line 1235, in __threaded_polling
    self.worker_pool.raise_exceptions()
  File "K:\Scedule_Bot_1.0\.venv\Lib\site-packages\telebot\util.py", line 150, in raise_exceptions
    raise self.exception_info
  File "K:\Scedule_Bot_1.0\.venv\Lib\site-packages\telebot\util.py", line 93, in run
    task(*args, **kwargs)
  File "K:\Scedule_Bot_1.0\.venv\Lib\site-packages\telebot\__init__.py", line 9759, in _run_middlewares_and_handler
    result = handler['function'](message)
             ^^^^^^^^^^^^^^^^^^^^^^^^^^^^
  File "K:\Scedule_Bot_1.0\telegram_bot\main.py", line 61, in start_func
    update_user_data(message)
  File "K:\Scedule_Bot_1.0\utils\sql_use.py", line 56, in update_user_data
    cur_us.execute("""
sqlite3.IntegrityError: UNIQUE constraint failed: users.tg_id

2025-09-17 09:18:11 - INFO - Start schedule normalization
2025-09-17 09:18:11 - INFO - Schedule is the same. Cancel.
2025-09-17 09:18:11 - INFO - Data received from server
2025-09-17 09:18:16 - ERROR - Infinity polling exception: database is locked
2025-09-17 09:18:16 - ERROR - Exception traceback:
Traceback (most recent call last):
  File "K:\Scedule_Bot_1.0\.venv\Lib\site-packages\telebot\__init__.py", line 1110, in infinity_polling
    self.polling(non_stop=True, timeout=timeout, long_polling_timeout=long_polling_timeout,
  File "K:\Scedule_Bot_1.0\.venv\Lib\site-packages\telebot\__init__.py", line 1198, in polling
    self.__threaded_polling(non_stop=non_stop, interval=interval, timeout=timeout, long_polling_timeout=long_polling_timeout,
  File "K:\Scedule_Bot_1.0\.venv\Lib\site-packages\telebot\__init__.py", line 1273, in __threaded_polling
    raise e
  File "K:\Scedule_Bot_1.0\.venv\Lib\site-packages\telebot\__init__.py", line 1235, in __threaded_polling
    self.worker_pool.raise_exceptions()
  File "K:\Scedule_Bot_1.0\.venv\Lib\site-packages\telebot\util.py", line 150, in raise_exceptions
    raise self.exception_info
  File "K:\Scedule_Bot_1.0\.venv\Lib\site-packages\telebot\util.py", line 93, in run
    task(*args, **kwargs)
  File "K:\Scedule_Bot_1.0\.venv\Lib\site-packages\telebot\__init__.py", line 9759, in _run_middlewares_and_handler
    result = handler['function'](message)
             ^^^^^^^^^^^^^^^^^^^^^^^^^^^^
  File "K:\Scedule_Bot_1.0\telegram_bot\main.py", line 61, in start_func
    update_user_data(message)
  File "K:\Scedule_Bot_1.0\utils\sql_use.py", line 71, in update_user_data
    cur_us.execute("""
sqlite3.OperationalError: database is locked

2025-09-17 09:18:19 - ERROR - Infinity polling exception: database is locked
2025-09-17 09:18:19 - ERROR - Exception traceback:
Traceback (most recent call last):
  File "K:\Scedule_Bot_1.0\.venv\Lib\site-packages\telebot\__init__.py", line 1110, in infinity_polling
    self.polling(non_stop=True, timeout=timeout, long_polling_timeout=long_polling_timeout,
  File "K:\Scedule_Bot_1.0\.venv\Lib\site-packages\telebot\__init__.py", line 1198, in polling
    self.__threaded_polling(non_stop=non_stop, interval=interval, timeout=timeout, long_polling_timeout=long_polling_timeout,
  File "K:\Scedule_Bot_1.0\.venv\Lib\site-packages\telebot\__init__.py", line 1273, in __threaded_polling
    raise e
  File "K:\Scedule_Bot_1.0\.venv\Lib\site-packages\telebot\__init__.py", line 1235, in __threaded_polling
    self.worker_pool.raise_exceptions()
  File "K:\Scedule_Bot_1.0\.venv\Lib\site-packages\telebot\util.py", line 150, in raise_exceptions
    raise self.exception_info
  File "K:\Scedule_Bot_1.0\.venv\Lib\site-packages\telebot\util.py", line 93, in run
    task(*args, **kwargs)
  File "K:\Scedule_Bot_1.0\.venv\Lib\site-packages\telebot\__init__.py", line 9759, in _run_middlewares_and_handler
    result = handler['function'](message)
             ^^^^^^^^^^^^^^^^^^^^^^^^^^^^
  File "K:\Scedule_Bot_1.0\telegram_bot\main.py", line 61, in start_func
    update_user_data(message)
  File "K:\Scedule_Bot_1.0\utils\sql_use.py", line 71, in update_user_data
    cur_us.execute("""
sqlite3.OperationalError: database is locked

2025-09-17 09:18:22 - ERROR - Infinity polling exception: database is locked
2025-09-17 09:18:22 - ERROR - Exception traceback:
Traceback (most recent call last):
  File "K:\Scedule_Bot_1.0\.venv\Lib\site-packages\telebot\__init__.py", line 1110, in infinity_polling
    self.polling(non_stop=True, timeout=timeout, long_polling_timeout=long_polling_timeout,
  File "K:\Scedule_Bot_1.0\.venv\Lib\site-packages\telebot\__init__.py", line 1198, in polling
    self.__threaded_polling(non_stop=non_stop, interval=interval, timeout=timeout, long_polling_timeout=long_polling_timeout,
  File "K:\Scedule_Bot_1.0\.venv\Lib\site-packages\telebot\__init__.py", line 1273, in __threaded_polling
    raise e
  File "K:\Scedule_Bot_1.0\.venv\Lib\site-packages\telebot\__init__.py", line 1235, in __threaded_polling
    self.worker_pool.raise_exceptions()
  File "K:\Scedule_Bot_1.0\.venv\Lib\site-packages\telebot\util.py", line 150, in raise_exceptions
    raise self.exception_info
  File "K:\Scedule_Bot_1.0\.venv\Lib\site-packages\telebot\util.py", line 93, in run
    task(*args, **kwargs)
  File "K:\Scedule_Bot_1.0\.venv\Lib\site-packages\telebot\__init__.py", line 9759, in _run_middlewares_and_handler
    result = handler['function'](message)
             ^^^^^^^^^^^^^^^^^^^^^^^^^^^^
  File "K:\Scedule_Bot_1.0\telegram_bot\main.py", line 90, in help_func
    update_user_data(message)
  File "K:\Scedule_Bot_1.0\utils\sql_use.py", line 71, in update_user_data
    cur_us.execute("""
sqlite3.OperationalError: database is locked

2025-09-17 09:18:28 - ERROR - Infinity polling exception: database is locked
2025-09-17 09:18:28 - ERROR - Exception traceback:
Traceback (most recent call last):
  File "K:\Scedule_Bot_1.0\.venv\Lib\site-packages\telebot\__init__.py", line 1110, in infinity_polling
    self.polling(non_stop=True, timeout=timeout, long_polling_timeout=long_polling_timeout,
  File "K:\Scedule_Bot_1.0\.venv\Lib\site-packages\telebot\__init__.py", line 1198, in polling
    self.__threaded_polling(non_stop=non_stop, interval=interval, timeout=timeout, long_polling_timeout=long_polling_timeout,
  File "K:\Scedule_Bot_1.0\.venv\Lib\site-packages\telebot\__init__.py", line 1273, in __threaded_polling
    raise e
  File "K:\Scedule_Bot_1.0\.venv\Lib\site-packages\telebot\__init__.py", line 1235, in __threaded_polling
    self.worker_pool.raise_exceptions()
  File "K:\Scedule_Bot_1.0\.venv\Lib\site-packages\telebot\util.py", line 150, in raise_exceptions
    raise self.exception_info
  File "K:\Scedule_Bot_1.0\.venv\Lib\site-packages\telebot\util.py", line 93, in run
    task(*args, **kwargs)
  File "K:\Scedule_Bot_1.0\.venv\Lib\site-packages\telebot\__init__.py", line 9759, in _run_middlewares_and_handler
    result = handler['function'](message)
             ^^^^^^^^^^^^^^^^^^^^^^^^^^^^
  File "K:\Scedule_Bot_1.0\telegram_bot\main.py", line 61, in start_func
    update_user_data(message)
  File "K:\Scedule_Bot_1.0\utils\sql_use.py", line 71, in update_user_data
    cur_us.execute("""
sqlite3.OperationalError: database is locked

2025-09-17 09:18:34 - INFO - ###############################
2025-09-17 09:18:34 - INFO - TEST INFO LOGGING FINALLY
2025-09-17 09:18:34 - WARNING - TEST WARNING LOGGING FINALLY
2025-09-17 09:18:34 - ERROR - Error to: utils.my_logger | Index: 0
NoneType: None
2025-09-17 09:18:34 - CRITICAL - TEST FATAL LOGGING FINALLY
2025-09-17 09:18:34 - INFO - LOGGER STARTED
2025-09-17 09:18:34 - INFO - ###############################
2025-09-17 09:18:34 - INFO - Stated connect to db
2025-09-17 09:18:34 - INFO - Users db created/exist
2025-09-17 09:18:34 - INFO - WS Parser started!
2025-09-17 09:18:34 - INFO - Getting data from server
2025-09-17 09:18:36 - INFO - Start schedule normalization
2025-09-17 09:18:36 - INFO - Schedule is the same. Cancel.
2025-09-17 09:18:36 - INFO - Data received from server
2025-09-17 09:23:36 - INFO - Getting data from server
2025-09-17 09:23:37 - INFO - Start schedule normalization
2025-09-17 09:23:37 - INFO - Schedule is the same. Cancel.
2025-09-17 09:23:37 - INFO - Data received from server
2025-09-17 09:28:37 - INFO - Getting data from server
2025-09-17 09:28:39 - INFO - Start schedule normalization
2025-09-17 09:28:39 - INFO - Schedule is the same. Cancel.
2025-09-17 09:28:39 - INFO - Data received from server
2025-09-17 09:33:39 - INFO - Getting data from server
2025-09-17 09:33:40 - INFO - Start schedule normalization
2025-09-17 09:33:40 - INFO - Schedule is the same. Cancel.
2025-09-17 09:33:40 - INFO - Data received from server
2025-09-17 09:38:40 - INFO - Getting data from server
2025-09-17 09:38:42 - INFO - Start schedule normalization
2025-09-17 09:38:42 - INFO - Schedule is the same. Cancel.
2025-09-17 09:38:42 - INFO - Data received from server
2025-09-17 09:43:42 - INFO - Getting data from server
2025-09-17 09:43:43 - INFO - Start schedule normalization
2025-09-17 09:43:43 - INFO - Schedule is the same. Cancel.
2025-09-17 09:43:43 - INFO - Data received from server
2025-09-17 09:48:43 - INFO - Getting data from server
2025-09-17 09:48:45 - INFO - Start schedule normalization
2025-09-17 09:48:45 - INFO - Schedule is the same. Cancel.
2025-09-17 09:48:45 - INFO - Data received from server
2025-09-17 09:53:45 - INFO - Getting data from server
2025-09-17 09:53:46 - INFO - Start schedule normalization
2025-09-17 09:53:46 - INFO - Schedule is the same. Cancel.
2025-09-17 09:53:46 - INFO - Data received from server
2025-09-17 09:58:46 - INFO - Getting data from server
2025-09-17 09:58:48 - INFO - Start schedule normalization
2025-09-17 09:58:48 - INFO - Schedule is the same. Cancel.
2025-09-17 09:58:48 - INFO - Data received from server
2025-09-17 10:03:48 - INFO - Getting data from server
2025-09-17 10:03:49 - INFO - Start schedule normalization
2025-09-17 10:03:49 - INFO - Schedule is the same. Cancel.
2025-09-17 10:03:49 - INFO - Data received from server
2025-09-17 10:08:49 - INFO - Getting data from server
2025-09-17 10:08:51 - INFO - Start schedule normalization
2025-09-17 10:08:51 - INFO - Schedule is the same. Cancel.
2025-09-17 10:08:51 - INFO - Data received from server
2025-09-17 10:13:51 - INFO - Getting data from server
2025-09-17 10:13:52 - INFO - Start schedule normalization
2025-09-17 10:13:53 - INFO - Schedule is the same. Cancel.
2025-09-17 10:13:53 - INFO - Data received from server
2025-09-17 10:18:53 - INFO - Getting data from server
2025-09-17 10:18:54 - INFO - Start schedule normalization
2025-09-17 10:18:54 - INFO - Schedule is the same. Cancel.
2025-09-17 10:18:54 - INFO - Data received from server
2025-09-17 10:23:54 - INFO - Getting data from server
2025-09-17 10:23:56 - INFO - Start schedule normalization
2025-09-17 10:23:56 - INFO - Schedule is the same. Cancel.
2025-09-17 10:23:56 - INFO - Data received from server
2025-09-17 10:28:56 - INFO - Getting data from server
2025-09-17 10:28:57 - INFO - Start schedule normalization
2025-09-17 10:28:57 - INFO - Schedule is the same. Cancel.
2025-09-17 10:28:57 - INFO - Data received from server
2025-09-17 10:33:57 - INFO - Getting data from server
2025-09-17 10:33:59 - INFO - Start schedule normalization
2025-09-17 10:33:59 - INFO - Schedule is the same. Cancel.
2025-09-17 10:33:59 - INFO - Data received from server
2025-09-17 10:38:59 - INFO - Getting data from server
2025-09-17 10:39:00 - INFO - Start schedule normalization
2025-09-17 10:39:00 - INFO - Schedule is the same. Cancel.
2025-09-17 10:39:00 - INFO - Data received from server
2025-09-17 10:44:00 - INFO - Getting data from server
2025-09-17 10:44:02 - INFO - Start schedule normalization
2025-09-17 10:44:02 - INFO - Schedule is the same. Cancel.
2025-09-17 10:44:02 - INFO - Data received from server
2025-09-17 10:49:02 - INFO - Getting data from server
2025-09-17 10:49:03 - INFO - Start schedule normalization
2025-09-17 10:49:03 - INFO - Schedule is the same. Cancel.
2025-09-17 10:49:03 - INFO - Data received from server
2025-09-17 10:54:03 - INFO - Getting data from server
2025-09-17 10:54:05 - INFO - Start schedule normalization
2025-09-17 10:54:05 - INFO - Schedule is the same. Cancel.
2025-09-17 10:54:05 - INFO - Data received from server
2025-09-17 10:59:05 - INFO - Getting data from server
2025-09-17 10:59:06 - INFO - Start schedule normalization
2025-09-17 10:59:06 - INFO - Schedule is the same. Cancel.
2025-09-17 10:59:06 - INFO - Data received from server
2025-09-17 11:04:06 - INFO - Getting data from server
2025-09-17 11:04:07 - INFO - Start schedule normalization
2025-09-17 11:04:08 - INFO - Schedule is the same. Cancel.
2025-09-17 11:04:08 - INFO - Data received from server
2025-09-17 11:09:08 - INFO - Getting data from server
2025-09-17 11:09:09 - INFO - Start schedule normalization
2025-09-17 11:09:09 - INFO - Schedule is the same. Cancel.
2025-09-17 11:09:09 - INFO - Data received from server
2025-09-17 11:14:09 - INFO - Getting data from server
2025-09-17 11:14:11 - INFO - Start schedule normalization
2025-09-17 11:14:11 - INFO - Schedule is the same. Cancel.
2025-09-17 11:14:11 - INFO - Data received from server
2025-09-17 11:19:11 - INFO - Getting data from server
2025-09-17 11:19:12 - INFO - Start schedule normalization
2025-09-17 11:19:12 - INFO - Schedule is the same. Cancel.
2025-09-17 11:19:12 - INFO - Data received from server
2025-09-17 11:24:12 - INFO - Getting data from server
2025-09-17 11:24:14 - INFO - Start schedule normalization
2025-09-17 11:24:14 - INFO - Schedule is the same. Cancel.
2025-09-17 11:24:14 - INFO - Data received from server
2025-09-17 11:29:14 - INFO - Getting data from server
2025-09-17 11:29:15 - INFO - Start schedule normalization
2025-09-17 11:29:15 - INFO - Schedule is the same. Cancel.
2025-09-17 11:29:15 - INFO - Data received from server
2025-09-17 11:34:15 - INFO - Getting data from server
2025-09-17 11:34:17 - INFO - Start schedule normalization
2025-09-17 11:34:17 - INFO - Schedule is the same. Cancel.
2025-09-17 11:34:17 - INFO - Data received from server
2025-09-17 11:39:17 - INFO - Getting data from server
2025-09-17 11:39:18 - INFO - Start schedule normalization
2025-09-17 11:39:19 - INFO - Schedule is the same. Cancel.
2025-09-17 11:39:19 - INFO - Data received from server
2025-09-17 11:41:10 - INFO - 6983370282 used GET SCHEDULE FUNC and choice Четверг
2025-09-17 11:41:13 - INFO - 6983370282 used GET SCHEDULE FUNC and choice Среда
2025-09-17 11:42:05 - INFO - ###############################
2025-09-17 11:42:05 - INFO - TEST INFO LOGGING FINALLY
2025-09-17 11:42:05 - WARNING - TEST WARNING LOGGING FINALLY
2025-09-17 11:42:05 - ERROR - Error to: utils.my_logger | Index: 0
NoneType: None
2025-09-17 11:42:05 - CRITICAL - TEST FATAL LOGGING FINALLY
2025-09-17 11:42:05 - INFO - LOGGER STARTED
2025-09-17 11:42:05 - INFO - ###############################
2025-09-17 11:42:05 - INFO - Stated connect to db
2025-09-17 11:42:05 - INFO - Users db created/exist
2025-09-17 11:42:05 - INFO - WS Parser started!
2025-09-17 11:42:05 - INFO - Getting data from server
2025-09-17 11:42:06 - INFO - Start schedule normalization
2025-09-17 11:42:07 - INFO - Schedule is the same. Cancel.
2025-09-17 11:42:07 - INFO - Data received from server
2025-09-17 11:42:55 - INFO - 6983370282 used GET SCHEDULE FUNC and choice Среда
2025-09-17 11:47:07 - INFO - Getting data from server
2025-09-17 11:47:08 - INFO - Start schedule normalization
2025-09-17 11:47:08 - INFO - Schedule is the same. Cancel.
2025-09-17 11:47:08 - INFO - Data received from server
2025-09-17 11:52:08 - INFO - Getting data from server
2025-09-17 11:52:10 - INFO - Start schedule normalization
2025-09-17 11:52:10 - INFO - Schedule is the same. Cancel.
2025-09-17 11:52:10 - INFO - Data received from server
2025-09-17 11:57:10 - INFO - Getting data from server
2025-09-17 11:57:12 - INFO - Start schedule normalization
2025-09-17 11:57:12 - INFO - Schedule is the same. Cancel.
2025-09-17 11:57:12 - INFO - Data received from server
2025-09-17 12:02:12 - INFO - Getting data from server
2025-09-17 12:02:13 - INFO - Start schedule normalization
2025-09-17 12:02:13 - INFO - Schedule is the same. Cancel.
2025-09-17 12:02:13 - INFO - Data received from server
2025-09-17 12:07:13 - INFO - Getting data from server
2025-09-17 12:07:15 - INFO - Start schedule normalization
2025-09-17 12:07:15 - INFO - Schedule is the same. Cancel.
2025-09-17 12:07:15 - INFO - Data received from server
2025-09-17 12:12:15 - INFO - Getting data from server
2025-09-17 12:12:16 - INFO - Start schedule normalization
2025-09-17 12:12:16 - INFO - Schedule is the same. Cancel.
2025-09-17 12:12:16 - INFO - Data received from server
2025-09-17 12:17:16 - INFO - Getting data from server
2025-09-17 12:17:38 - INFO - Data received from server
2025-09-17 12:22:38 - INFO - Getting data from server
2025-09-17 12:22:39 - INFO - Start schedule normalization
2025-09-17 12:22:39 - INFO - Schedule is the same. Cancel.
2025-09-17 12:22:39 - INFO - Data received from server
2025-09-17 12:25:42 - INFO - 6983370282 used GET SCHEDULE FUNC and choice Среда
2025-09-17 12:25:42 - ERROR - Infinity polling exception: HTTPSConnectionPool(host='api.telegram.org', port=443): Max retries exceeded with url: /bot8004422788:***********************************/sendMessage?chat_id=6983370282&text=%3Ccode%3E%D0%A0%D0%B0%D1%81%D0%BF.+%D0%B4%D0%BB%D1%8F+8%D0%9A+%D0%BD%D0%B0+%D0%A1%D1%80%D0%B5%D0%B4%D0%B0%3A%0A%E2%84%96.+%D0%9A%D0%B0%D0%B1%D0%B8%D0%BD%D0%B5%D1%82++%7C+%D0%9F%D1%80%D0%B5%D0%B4%D0%BC%D0%B5%D1%82%0A1.+---++++++%7C+---%0A2.+---++++++%7C+---%0A3.+207%D0%96+++++%7C+%D0%90%D0%BD%D0%B3%D0%BB%D0%B8%D0%B9%D1%81%D0%BA%D0%B8%D0%B9+%D1%8F%D0%B7%D1%8B%D0%BA%0A%7C++301%D0%92+++++%7C%0A4.+103%D0%92+++++%7C+%D0%91%D0%B8%D0%BE%D0%BB%D0%BE%D0%B3%D0%B8%D1%8F%0A5.+107%D0%92+++++%7C+%D0%90%D0%BB%D0%B3%D0%B5%D0%B1%D1%80%D0%B0%0A6.+107%D0%92+++++%7C+%D0%93%D0%B5%D0%BE%D0%BC%D0%B5%D1%82%D1%80%D0%B8%D1%8F%0A7.+---++++++%7C+---%0A%3C%2Fcode%3E&parse_mode=HTML (Caused by NameResolutionError("<urllib3.connection.HTTPSConnection object at 0x00000247C33D1BB0>: Failed to resolve 'api.telegram.org' ([Errno 11001] getaddrinfo failed)"))
2025-09-17 12:25:42 - ERROR - Exception traceback:
Traceback (most recent call last):
  File "K:\Scedule_Bot_1.0\.venv\Lib\site-packages\urllib3\connection.py", line 198, in _new_conn
    sock = connection.create_connection(
           ^^^^^^^^^^^^^^^^^^^^^^^^^^^^^
  File "K:\Scedule_Bot_1.0\.venv\Lib\site-packages\urllib3\util\connection.py", line 60, in create_connection
    for res in socket.getaddrinfo(host, port, family, socket.SOCK_STREAM):
               ^^^^^^^^^^^^^^^^^^^^^^^^^^^^^^^^^^^^^^^^^^^^^^^^^^^^^^^^^^
  File "C:\Users\kazak\AppData\Local\Programs\Python\Python312\Lib\socket.py", line 978, in getaddrinfo
    for res in _socket.getaddrinfo(host, port, family, type, proto, flags):
               ^^^^^^^^^^^^^^^^^^^^^^^^^^^^^^^^^^^^^^^^^^^^^^^^^^^^^^^^^^^
socket.gaierror: [Errno 11001] getaddrinfo failed

The above exception was the direct cause of the following exception:

Traceback (most recent call last):
  File "K:\Scedule_Bot_1.0\.venv\Lib\site-packages\urllib3\connectionpool.py", line 787, in urlopen
    response = self._make_request(
               ^^^^^^^^^^^^^^^^^^^
  File "K:\Scedule_Bot_1.0\.venv\Lib\site-packages\urllib3\connectionpool.py", line 488, in _make_request
    raise new_e
  File "K:\Scedule_Bot_1.0\.venv\Lib\site-packages\urllib3\connectionpool.py", line 464, in _make_request
    self._validate_conn(conn)
  File "K:\Scedule_Bot_1.0\.venv\Lib\site-packages\urllib3\connectionpool.py", line 1093, in _validate_conn
    conn.connect()
  File "K:\Scedule_Bot_1.0\.venv\Lib\site-packages\urllib3\connection.py", line 753, in connect
    self.sock = sock = self._new_conn()
                       ^^^^^^^^^^^^^^^^
  File "K:\Scedule_Bot_1.0\.venv\Lib\site-packages\urllib3\connection.py", line 205, in _new_conn
    raise NameResolutionError(self.host, self, e) from e
urllib3.exceptions.NameResolutionError: <urllib3.connection.HTTPSConnection object at 0x00000247C33D1BB0>: Failed to resolve 'api.telegram.org' ([Errno 11001] getaddrinfo failed)

The above exception was the direct cause of the following exception:

Traceback (most recent call last):
  File "K:\Scedule_Bot_1.0\.venv\Lib\site-packages\requests\adapters.py", line 667, in send
    resp = conn.urlopen(
           ^^^^^^^^^^^^^
  File "K:\Scedule_Bot_1.0\.venv\Lib\site-packages\urllib3\connectionpool.py", line 841, in urlopen
    retries = retries.increment(
              ^^^^^^^^^^^^^^^^^^
  File "K:\Scedule_Bot_1.0\.venv\Lib\site-packages\urllib3\util\retry.py", line 519, in increment
    raise MaxRetryError(_pool, url, reason) from reason  # type: ignore[arg-type]
    ^^^^^^^^^^^^^^^^^^^^^^^^^^^^^^^^^^^^^^^^^^^^^^^^^^^
urllib3.exceptions.MaxRetryError: HTTPSConnectionPool(host='api.telegram.org', port=443): Max retries exceeded with url: /bot8004422788:***********************************/sendMessage?chat_id=6983370282&text=%3Ccode%3E%D0%A0%D0%B0%D1%81%D0%BF.+%D0%B4%D0%BB%D1%8F+8%D0%9A+%D0%BD%D0%B0+%D0%A1%D1%80%D0%B5%D0%B4%D0%B0%3A%0A%E2%84%96.+%D0%9A%D0%B0%D0%B1%D0%B8%D0%BD%D0%B5%D1%82++%7C+%D0%9F%D1%80%D0%B5%D0%B4%D0%BC%D0%B5%D1%82%0A1.+---++++++%7C+---%0A2.+---++++++%7C+---%0A3.+207%D0%96+++++%7C+%D0%90%D0%BD%D0%B3%D0%BB%D0%B8%D0%B9%D1%81%D0%BA%D0%B8%D0%B9+%D1%8F%D0%B7%D1%8B%D0%BA%0A%7C++301%D0%92+++++%7C%0A4.+103%D0%92+++++%7C+%D0%91%D0%B8%D0%BE%D0%BB%D0%BE%D0%B3%D0%B8%D1%8F%0A5.+107%D0%92+++++%7C+%D0%90%D0%BB%D0%B3%D0%B5%D0%B1%D1%80%D0%B0%0A6.+107%D0%92+++++%7C+%D0%93%D0%B5%D0%BE%D0%BC%D0%B5%D1%82%D1%80%D0%B8%D1%8F%0A7.+---++++++%7C+---%0A%3C%2Fcode%3E&parse_mode=HTML (Caused by NameResolutionError("<urllib3.connection.HTTPSConnection object at 0x00000247C33D1BB0>: Failed to resolve 'api.telegram.org' ([Errno 11001] getaddrinfo failed)"))

During handling of the above exception, another exception occurred:

Traceback (most recent call last):
  File "K:\Scedule_Bot_1.0\.venv\Lib\site-packages\telebot\__init__.py", line 1110, in infinity_polling
    self.polling(non_stop=True, timeout=timeout, long_polling_timeout=long_polling_timeout,
  File "K:\Scedule_Bot_1.0\.venv\Lib\site-packages\telebot\__init__.py", line 1198, in polling
    self.__threaded_polling(non_stop=non_stop, interval=interval, timeout=timeout, long_polling_timeout=long_polling_timeout,
  File "K:\Scedule_Bot_1.0\.venv\Lib\site-packages\telebot\__init__.py", line 1273, in __threaded_polling
    raise e
  File "K:\Scedule_Bot_1.0\.venv\Lib\site-packages\telebot\__init__.py", line 1235, in __threaded_polling
    self.worker_pool.raise_exceptions()
  File "K:\Scedule_Bot_1.0\.venv\Lib\site-packages\telebot\util.py", line 150, in raise_exceptions
    raise self.exception_info
  File "K:\Scedule_Bot_1.0\.venv\Lib\site-packages\telebot\util.py", line 93, in run
    task(*args, **kwargs)
  File "K:\Scedule_Bot_1.0\.venv\Lib\site-packages\telebot\__init__.py", line 9759, in _run_middlewares_and_handler
    result = handler['function'](message)
             ^^^^^^^^^^^^^^^^^^^^^^^^^^^^
  File "K:\Scedule_Bot_1.0\telegram_bot\main.py", line 273, in get_schedule_for_user
    bot.send_message(message.from_user.id,
  File "K:\Scedule_Bot_1.0\.venv\Lib\site-packages\telebot\__init__.py", line 1800, in send_message
    apihelper.send_message(
  File "K:\Scedule_Bot_1.0\.venv\Lib\site-packages\telebot\apihelper.py", line 275, in send_message
    return _make_request(token, method_url, params=payload, method='post')
           ^^^^^^^^^^^^^^^^^^^^^^^^^^^^^^^^^^^^^^^^^^^^^^^^^^^^^^^^^^^^^^^
  File "K:\Scedule_Bot_1.0\.venv\Lib\site-packages\telebot\apihelper.py", line 162, in _make_request
    result = _get_req_session().request(
             ^^^^^^^^^^^^^^^^^^^^^^^^^^^
  File "K:\Scedule_Bot_1.0\.venv\Lib\site-packages\requests\sessions.py", line 589, in request
    resp = self.send(prep, **send_kwargs)
           ^^^^^^^^^^^^^^^^^^^^^^^^^^^^^^
  File "K:\Scedule_Bot_1.0\.venv\Lib\site-packages\requests\sessions.py", line 703, in send
    r = adapter.send(request, **kwargs)
        ^^^^^^^^^^^^^^^^^^^^^^^^^^^^^^^
  File "K:\Scedule_Bot_1.0\.venv\Lib\site-packages\requests\adapters.py", line 700, in send
    raise ConnectionError(e, request=request)
requests.exceptions.ConnectionError: HTTPSConnectionPool(host='api.telegram.org', port=443): Max retries exceeded with url: /bot8004422788:***********************************/sendMessage?chat_id=6983370282&text=%3Ccode%3E%D0%A0%D0%B0%D1%81%D0%BF.+%D0%B4%D0%BB%D1%8F+8%D0%9A+%D0%BD%D0%B0+%D0%A1%D1%80%D0%B5%D0%B4%D0%B0%3A%0A%E2%84%96.+%D0%9A%D0%B0%D0%B1%D0%B8%D0%BD%D0%B5%D1%82++%7C+%D0%9F%D1%80%D0%B5%D0%B4%D0%BC%D0%B5%D1%82%0A1.+---++++++%7C+---%0A2.+---++++++%7C+---%0A3.+207%D0%96+++++%7C+%D0%90%D0%BD%D0%B3%D0%BB%D0%B8%D0%B9%D1%81%D0%BA%D0%B8%D0%B9+%D1%8F%D0%B7%D1%8B%D0%BA%0A%7C++301%D0%92+++++%7C%0A4.+103%D0%92+++++%7C+%D0%91%D0%B8%D0%BE%D0%BB%D0%BE%D0%B3%D0%B8%D1%8F%0A5.+107%D0%92+++++%7C+%D0%90%D0%BB%D0%B3%D0%B5%D0%B1%D1%80%D0%B0%0A6.+107%D0%92+++++%7C+%D0%93%D0%B5%D0%BE%D0%BC%D0%B5%D1%82%D1%80%D0%B8%D1%8F%0A7.+---++++++%7C+---%0A%3C%2Fcode%3E&parse_mode=HTML (Caused by NameResolutionError("<urllib3.connection.HTTPSConnection object at 0x00000247C33D1BB0>: Failed to resolve 'api.telegram.org' ([Errno 11001] getaddrinfo failed)"))

2025-09-17 12:25:45 - ERROR - Infinity polling exception: HTTPSConnectionPool(host='api.telegram.org', port=443): Max retries exceeded with url: /bot8004422788:***********************************/getUpdates?offset=218512129&timeout=20 (Caused by NameResolutionError("<urllib3.connection.HTTPSConnection object at 0x00000247C38D8C50>: Failed to resolve 'api.telegram.org' ([Errno 11001] getaddrinfo failed)"))
2025-09-17 12:25:45 - ERROR - Exception traceback:
Traceback (most recent call last):
  File "K:\Scedule_Bot_1.0\.venv\Lib\site-packages\urllib3\connection.py", line 198, in _new_conn
    sock = connection.create_connection(
           ^^^^^^^^^^^^^^^^^^^^^^^^^^^^^
  File "K:\Scedule_Bot_1.0\.venv\Lib\site-packages\urllib3\util\connection.py", line 60, in create_connection
    for res in socket.getaddrinfo(host, port, family, socket.SOCK_STREAM):
               ^^^^^^^^^^^^^^^^^^^^^^^^^^^^^^^^^^^^^^^^^^^^^^^^^^^^^^^^^^
  File "C:\Users\kazak\AppData\Local\Programs\Python\Python312\Lib\socket.py", line 978, in getaddrinfo
    for res in _socket.getaddrinfo(host, port, family, type, proto, flags):
               ^^^^^^^^^^^^^^^^^^^^^^^^^^^^^^^^^^^^^^^^^^^^^^^^^^^^^^^^^^^
socket.gaierror: [Errno 11001] getaddrinfo failed

The above exception was the direct cause of the following exception:

Traceback (most recent call last):
  File "K:\Scedule_Bot_1.0\.venv\Lib\site-packages\urllib3\connectionpool.py", line 787, in urlopen
    response = self._make_request(
               ^^^^^^^^^^^^^^^^^^^
  File "K:\Scedule_Bot_1.0\.venv\Lib\site-packages\urllib3\connectionpool.py", line 488, in _make_request
    raise new_e
  File "K:\Scedule_Bot_1.0\.venv\Lib\site-packages\urllib3\connectionpool.py", line 464, in _make_request
    self._validate_conn(conn)
  File "K:\Scedule_Bot_1.0\.venv\Lib\site-packages\urllib3\connectionpool.py", line 1093, in _validate_conn
    conn.connect()
  File "K:\Scedule_Bot_1.0\.venv\Lib\site-packages\urllib3\connection.py", line 753, in connect
    self.sock = sock = self._new_conn()
                       ^^^^^^^^^^^^^^^^
  File "K:\Scedule_Bot_1.0\.venv\Lib\site-packages\urllib3\connection.py", line 205, in _new_conn
    raise NameResolutionError(self.host, self, e) from e
urllib3.exceptions.NameResolutionError: <urllib3.connection.HTTPSConnection object at 0x00000247C38D8C50>: Failed to resolve 'api.telegram.org' ([Errno 11001] getaddrinfo failed)

The above exception was the direct cause of the following exception:

Traceback (most recent call last):
  File "K:\Scedule_Bot_1.0\.venv\Lib\site-packages\requests\adapters.py", line 667, in send
    resp = conn.urlopen(
           ^^^^^^^^^^^^^
  File "K:\Scedule_Bot_1.0\.venv\Lib\site-packages\urllib3\connectionpool.py", line 841, in urlopen
    retries = retries.increment(
              ^^^^^^^^^^^^^^^^^^
  File "K:\Scedule_Bot_1.0\.venv\Lib\site-packages\urllib3\util\retry.py", line 519, in increment
    raise MaxRetryError(_pool, url, reason) from reason  # type: ignore[arg-type]
    ^^^^^^^^^^^^^^^^^^^^^^^^^^^^^^^^^^^^^^^^^^^^^^^^^^^
urllib3.exceptions.MaxRetryError: HTTPSConnectionPool(host='api.telegram.org', port=443): Max retries exceeded with url: /bot8004422788:***********************************/getUpdates?offset=218512129&timeout=20 (Caused by NameResolutionError("<urllib3.connection.HTTPSConnection object at 0x00000247C38D8C50>: Failed to resolve 'api.telegram.org' ([Errno 11001] getaddrinfo failed)"))

During handling of the above exception, another exception occurred:

Traceback (most recent call last):
  File "K:\Scedule_Bot_1.0\.venv\Lib\site-packages\telebot\__init__.py", line 1110, in infinity_polling
    self.polling(non_stop=True, timeout=timeout, long_polling_timeout=long_polling_timeout,
  File "K:\Scedule_Bot_1.0\.venv\Lib\site-packages\telebot\__init__.py", line 1198, in polling
    self.__threaded_polling(non_stop=non_stop, interval=interval, timeout=timeout, long_polling_timeout=long_polling_timeout,
  File "K:\Scedule_Bot_1.0\.venv\Lib\site-packages\telebot\__init__.py", line 1273, in __threaded_polling
    raise e
  File "K:\Scedule_Bot_1.0\.venv\Lib\site-packages\telebot\__init__.py", line 1234, in __threaded_polling
    polling_thread.raise_exceptions()
  File "K:\Scedule_Bot_1.0\.venv\Lib\site-packages\telebot\util.py", line 111, in raise_exceptions
    raise self.exception_info
  File "K:\Scedule_Bot_1.0\.venv\Lib\site-packages\telebot\util.py", line 93, in run
    task(*args, **kwargs)
  File "K:\Scedule_Bot_1.0\.venv\Lib\site-packages\telebot\__init__.py", line 688, in __retrieve_updates
    updates = self.get_updates(offset=(self.last_update_id + 1),
             ^^^^^^^^^^^^^^^^^^^^^^^^^^^^^^^^^^^^^^^^^^^^^^^^^^
  File "K:\Scedule_Bot_1.0\.venv\Lib\site-packages\telebot\__init__.py", line 660, in get_updates
    json_updates = apihelper.get_updates(
                   ^^^^^^^^^^^^^^^^^^^^^^
  File "K:\Scedule_Bot_1.0\.venv\Lib\site-packages\telebot\apihelper.py", line 332, in get_updates
    return _make_request(token, method_url, params=payload)
           ^^^^^^^^^^^^^^^^^^^^^^^^^^^^^^^^^^^^^^^^^^^^^^^^
  File "K:\Scedule_Bot_1.0\.venv\Lib\site-packages\telebot\apihelper.py", line 162, in _make_request
    result = _get_req_session().request(
             ^^^^^^^^^^^^^^^^^^^^^^^^^^^
  File "K:\Scedule_Bot_1.0\.venv\Lib\site-packages\requests\sessions.py", line 589, in request
    resp = self.send(prep, **send_kwargs)
           ^^^^^^^^^^^^^^^^^^^^^^^^^^^^^^
  File "K:\Scedule_Bot_1.0\.venv\Lib\site-packages\requests\sessions.py", line 703, in send
    r = adapter.send(request, **kwargs)
        ^^^^^^^^^^^^^^^^^^^^^^^^^^^^^^^
  File "K:\Scedule_Bot_1.0\.venv\Lib\site-packages\requests\adapters.py", line 700, in send
    raise ConnectionError(e, request=request)
requests.exceptions.ConnectionError: HTTPSConnectionPool(host='api.telegram.org', port=443): Max retries exceeded with url: /bot8004422788:***********************************/getUpdates?offset=218512129&timeout=20 (Caused by NameResolutionError("<urllib3.connection.HTTPSConnection object at 0x00000247C38D8C50>: Failed to resolve 'api.telegram.org' ([Errno 11001] getaddrinfo failed)"))

2025-09-17 12:25:48 - ERROR - Infinity polling exception: HTTPSConnectionPool(host='api.telegram.org', port=443): Max retries exceeded with url: /bot8004422788:***********************************/getUpdates?offset=218512129&timeout=20 (Caused by NameResolutionError("<urllib3.connection.HTTPSConnection object at 0x00000247C38D9CD0>: Failed to resolve 'api.telegram.org' ([Errno 11001] getaddrinfo failed)"))
2025-09-17 12:25:48 - ERROR - Exception traceback:
Traceback (most recent call last):
  File "K:\Scedule_Bot_1.0\.venv\Lib\site-packages\urllib3\connection.py", line 198, in _new_conn
    sock = connection.create_connection(
           ^^^^^^^^^^^^^^^^^^^^^^^^^^^^^
  File "K:\Scedule_Bot_1.0\.venv\Lib\site-packages\urllib3\util\connection.py", line 60, in create_connection
    for res in socket.getaddrinfo(host, port, family, socket.SOCK_STREAM):
               ^^^^^^^^^^^^^^^^^^^^^^^^^^^^^^^^^^^^^^^^^^^^^^^^^^^^^^^^^^
  File "C:\Users\kazak\AppData\Local\Programs\Python\Python312\Lib\socket.py", line 978, in getaddrinfo
    for res in _socket.getaddrinfo(host, port, family, type, proto, flags):
               ^^^^^^^^^^^^^^^^^^^^^^^^^^^^^^^^^^^^^^^^^^^^^^^^^^^^^^^^^^^
socket.gaierror: [Errno 11001] getaddrinfo failed

The above exception was the direct cause of the following exception:

Traceback (most recent call last):
  File "K:\Scedule_Bot_1.0\.venv\Lib\site-packages\urllib3\connectionpool.py", line 787, in urlopen
    response = self._make_request(
               ^^^^^^^^^^^^^^^^^^^
  File "K:\Scedule_Bot_1.0\.venv\Lib\site-packages\urllib3\connectionpool.py", line 488, in _make_request
    raise new_e
  File "K:\Scedule_Bot_1.0\.venv\Lib\site-packages\urllib3\connectionpool.py", line 464, in _make_request
    self._validate_conn(conn)
  File "K:\Scedule_Bot_1.0\.venv\Lib\site-packages\urllib3\connectionpool.py", line 1093, in _validate_conn
    conn.connect()
  File "K:\Scedule_Bot_1.0\.venv\Lib\site-packages\urllib3\connection.py", line 753, in connect
    self.sock = sock = self._new_conn()
                       ^^^^^^^^^^^^^^^^
  File "K:\Scedule_Bot_1.0\.venv\Lib\site-packages\urllib3\connection.py", line 205, in _new_conn
    raise NameResolutionError(self.host, self, e) from e
urllib3.exceptions.NameResolutionError: <urllib3.connection.HTTPSConnection object at 0x00000247C38D9CD0>: Failed to resolve 'api.telegram.org' ([Errno 11001] getaddrinfo failed)

The above exception was the direct cause of the following exception:

Traceback (most recent call last):
  File "K:\Scedule_Bot_1.0\.venv\Lib\site-packages\requests\adapters.py", line 667, in send
    resp = conn.urlopen(
           ^^^^^^^^^^^^^
  File "K:\Scedule_Bot_1.0\.venv\Lib\site-packages\urllib3\connectionpool.py", line 841, in urlopen
    retries = retries.increment(
              ^^^^^^^^^^^^^^^^^^
  File "K:\Scedule_Bot_1.0\.venv\Lib\site-packages\urllib3\util\retry.py", line 519, in increment
    raise MaxRetryError(_pool, url, reason) from reason  # type: ignore[arg-type]
    ^^^^^^^^^^^^^^^^^^^^^^^^^^^^^^^^^^^^^^^^^^^^^^^^^^^
urllib3.exceptions.MaxRetryError: HTTPSConnectionPool(host='api.telegram.org', port=443): Max retries exceeded with url: /bot8004422788:***********************************/getUpdates?offset=218512129&timeout=20 (Caused by NameResolutionError("<urllib3.connection.HTTPSConnection object at 0x00000247C38D9CD0>: Failed to resolve 'api.telegram.org' ([Errno 11001] getaddrinfo failed)"))

During handling of the above exception, another exception occurred:

Traceback (most recent call last):
  File "K:\Scedule_Bot_1.0\.venv\Lib\site-packages\telebot\__init__.py", line 1110, in infinity_polling
    self.polling(non_stop=True, timeout=timeout, long_polling_timeout=long_polling_timeout,
  File "K:\Scedule_Bot_1.0\.venv\Lib\site-packages\telebot\__init__.py", line 1198, in polling
    self.__threaded_polling(non_stop=non_stop, interval=interval, timeout=timeout, long_polling_timeout=long_polling_timeout,
  File "K:\Scedule_Bot_1.0\.venv\Lib\site-packages\telebot\__init__.py", line 1273, in __threaded_polling
    raise e
  File "K:\Scedule_Bot_1.0\.venv\Lib\site-packages\telebot\__init__.py", line 1234, in __threaded_polling
    polling_thread.raise_exceptions()
  File "K:\Scedule_Bot_1.0\.venv\Lib\site-packages\telebot\util.py", line 111, in raise_exceptions
    raise self.exception_info
  File "K:\Scedule_Bot_1.0\.venv\Lib\site-packages\telebot\util.py", line 93, in run
    task(*args, **kwargs)
  File "K:\Scedule_Bot_1.0\.venv\Lib\site-packages\telebot\__init__.py", line 688, in __retrieve_updates
    updates = self.get_updates(offset=(self.last_update_id + 1),
             ^^^^^^^^^^^^^^^^^^^^^^^^^^^^^^^^^^^^^^^^^^^^^^^^^^
  File "K:\Scedule_Bot_1.0\.venv\Lib\site-packages\telebot\__init__.py", line 660, in get_updates
    json_updates = apihelper.get_updates(
                   ^^^^^^^^^^^^^^^^^^^^^^
  File "K:\Scedule_Bot_1.0\.venv\Lib\site-packages\telebot\apihelper.py", line 332, in get_updates
    return _make_request(token, method_url, params=payload)
           ^^^^^^^^^^^^^^^^^^^^^^^^^^^^^^^^^^^^^^^^^^^^^^^^
  File "K:\Scedule_Bot_1.0\.venv\Lib\site-packages\telebot\apihelper.py", line 162, in _make_request
    result = _get_req_session().request(
             ^^^^^^^^^^^^^^^^^^^^^^^^^^^
  File "K:\Scedule_Bot_1.0\.venv\Lib\site-packages\requests\sessions.py", line 589, in request
    resp = self.send(prep, **send_kwargs)
           ^^^^^^^^^^^^^^^^^^^^^^^^^^^^^^
  File "K:\Scedule_Bot_1.0\.venv\Lib\site-packages\requests\sessions.py", line 703, in send
    r = adapter.send(request, **kwargs)
        ^^^^^^^^^^^^^^^^^^^^^^^^^^^^^^^
  File "K:\Scedule_Bot_1.0\.venv\Lib\site-packages\requests\adapters.py", line 700, in send
    raise ConnectionError(e, request=request)
requests.exceptions.ConnectionError: HTTPSConnectionPool(host='api.telegram.org', port=443): Max retries exceeded with url: /bot8004422788:***********************************/getUpdates?offset=218512129&timeout=20 (Caused by NameResolutionError("<urllib3.connection.HTTPSConnection object at 0x00000247C38D9CD0>: Failed to resolve 'api.telegram.org' ([Errno 11001] getaddrinfo failed)"))

2025-09-17 12:25:49 - INFO - 6983370282 used GET SCHEDULE FUNC and choice Среда
2025-09-17 12:25:51 - ERROR - Infinity polling exception: HTTPSConnectionPool(host='api.telegram.org', port=443): Max retries exceeded with url: /bot8004422788:***********************************/sendMessage?chat_id=6983370282&text=%3Ccode%3E%D0%A0%D0%B0%D1%81%D0%BF.+%D0%B4%D0%BB%D1%8F+8%D0%9A+%D0%BD%D0%B0+%D0%A1%D1%80%D0%B5%D0%B4%D0%B0%3A%0A%E2%84%96.+%D0%9A%D0%B0%D0%B1%D0%B8%D0%BD%D0%B5%D1%82++%7C+%D0%9F%D1%80%D0%B5%D0%B4%D0%BC%D0%B5%D1%82%0A1.+---++++++%7C+---%0A2.+---++++++%7C+---%0A3.+207%D0%96+++++%7C+%D0%90%D0%BD%D0%B3%D0%BB%D0%B8%D0%B9%D1%81%D0%BA%D0%B8%D0%B9+%D1%8F%D0%B7%D1%8B%D0%BA%0A%7C++301%D0%92+++++%7C%0A4.+103%D0%92+++++%7C+%D0%91%D0%B8%D0%BE%D0%BB%D0%BE%D0%B3%D0%B8%D1%8F%0A5.+107%D0%92+++++%7C+%D0%90%D0%BB%D0%B3%D0%B5%D0%B1%D1%80%D0%B0%0A6.+107%D0%92+++++%7C+%D0%93%D0%B5%D0%BE%D0%BC%D0%B5%D1%82%D1%80%D0%B8%D1%8F%0A7.+---++++++%7C+---%0A%3C%2Fcode%3E&parse_mode=HTML (Caused by NameResolutionError("<urllib3.connection.HTTPSConnection object at 0x00000247C38D8950>: Failed to resolve 'api.telegram.org' ([Errno 11001] getaddrinfo failed)"))
2025-09-17 12:25:51 - ERROR - Exception traceback:
Traceback (most recent call last):
  File "K:\Scedule_Bot_1.0\.venv\Lib\site-packages\urllib3\connection.py", line 198, in _new_conn
    sock = connection.create_connection(
           ^^^^^^^^^^^^^^^^^^^^^^^^^^^^^
  File "K:\Scedule_Bot_1.0\.venv\Lib\site-packages\urllib3\util\connection.py", line 60, in create_connection
    for res in socket.getaddrinfo(host, port, family, socket.SOCK_STREAM):
               ^^^^^^^^^^^^^^^^^^^^^^^^^^^^^^^^^^^^^^^^^^^^^^^^^^^^^^^^^^
  File "C:\Users\kazak\AppData\Local\Programs\Python\Python312\Lib\socket.py", line 978, in getaddrinfo
    for res in _socket.getaddrinfo(host, port, family, type, proto, flags):
               ^^^^^^^^^^^^^^^^^^^^^^^^^^^^^^^^^^^^^^^^^^^^^^^^^^^^^^^^^^^
socket.gaierror: [Errno 11001] getaddrinfo failed

The above exception was the direct cause of the following exception:

Traceback (most recent call last):
  File "K:\Scedule_Bot_1.0\.venv\Lib\site-packages\urllib3\connectionpool.py", line 787, in urlopen
    response = self._make_request(
               ^^^^^^^^^^^^^^^^^^^
  File "K:\Scedule_Bot_1.0\.venv\Lib\site-packages\urllib3\connectionpool.py", line 488, in _make_request
    raise new_e
  File "K:\Scedule_Bot_1.0\.venv\Lib\site-packages\urllib3\connectionpool.py", line 464, in _make_request
    self._validate_conn(conn)
  File "K:\Scedule_Bot_1.0\.venv\Lib\site-packages\urllib3\connectionpool.py", line 1093, in _validate_conn
    conn.connect()
  File "K:\Scedule_Bot_1.0\.venv\Lib\site-packages\urllib3\connection.py", line 753, in connect
    self.sock = sock = self._new_conn()
                       ^^^^^^^^^^^^^^^^
  File "K:\Scedule_Bot_1.0\.venv\Lib\site-packages\urllib3\connection.py", line 205, in _new_conn
    raise NameResolutionError(self.host, self, e) from e
urllib3.exceptions.NameResolutionError: <urllib3.connection.HTTPSConnection object at 0x00000247C38D8950>: Failed to resolve 'api.telegram.org' ([Errno 11001] getaddrinfo failed)

The above exception was the direct cause of the following exception:

Traceback (most recent call last):
  File "K:\Scedule_Bot_1.0\.venv\Lib\site-packages\requests\adapters.py", line 667, in send
    resp = conn.urlopen(
           ^^^^^^^^^^^^^
  File "K:\Scedule_Bot_1.0\.venv\Lib\site-packages\urllib3\connectionpool.py", line 841, in urlopen
    retries = retries.increment(
              ^^^^^^^^^^^^^^^^^^
  File "K:\Scedule_Bot_1.0\.venv\Lib\site-packages\urllib3\util\retry.py", line 519, in increment
    raise MaxRetryError(_pool, url, reason) from reason  # type: ignore[arg-type]
    ^^^^^^^^^^^^^^^^^^^^^^^^^^^^^^^^^^^^^^^^^^^^^^^^^^^
urllib3.exceptions.MaxRetryError: HTTPSConnectionPool(host='api.telegram.org', port=443): Max retries exceeded with url: /bot8004422788:***********************************/sendMessage?chat_id=6983370282&text=%3Ccode%3E%D0%A0%D0%B0%D1%81%D0%BF.+%D0%B4%D0%BB%D1%8F+8%D0%9A+%D0%BD%D0%B0+%D0%A1%D1%80%D0%B5%D0%B4%D0%B0%3A%0A%E2%84%96.+%D0%9A%D0%B0%D0%B1%D0%B8%D0%BD%D0%B5%D1%82++%7C+%D0%9F%D1%80%D0%B5%D0%B4%D0%BC%D0%B5%D1%82%0A1.+---++++++%7C+---%0A2.+---++++++%7C+---%0A3.+207%D0%96+++++%7C+%D0%90%D0%BD%D0%B3%D0%BB%D0%B8%D0%B9%D1%81%D0%BA%D0%B8%D0%B9+%D1%8F%D0%B7%D1%8B%D0%BA%0A%7C++301%D0%92+++++%7C%0A4.+103%D0%92+++++%7C+%D0%91%D0%B8%D0%BE%D0%BB%D0%BE%D0%B3%D0%B8%D1%8F%0A5.+107%D0%92+++++%7C+%D0%90%D0%BB%D0%B3%D0%B5%D0%B1%D1%80%D0%B0%0A6.+107%D0%92+++++%7C+%D0%93%D0%B5%D0%BE%D0%BC%D0%B5%D1%82%D1%80%D0%B8%D1%8F%0A7.+---++++++%7C+---%0A%3C%2Fcode%3E&parse_mode=HTML (Caused by NameResolutionError("<urllib3.connection.HTTPSConnection object at 0x00000247C38D8950>: Failed to resolve 'api.telegram.org' ([Errno 11001] getaddrinfo failed)"))

During handling of the above exception, another exception occurred:

Traceback (most recent call last):
  File "K:\Scedule_Bot_1.0\.venv\Lib\site-packages\telebot\__init__.py", line 1110, in infinity_polling
    self.polling(non_stop=True, timeout=timeout, long_polling_timeout=long_polling_timeout,
  File "K:\Scedule_Bot_1.0\.venv\Lib\site-packages\telebot\__init__.py", line 1198, in polling
    self.__threaded_polling(non_stop=non_stop, interval=interval, timeout=timeout, long_polling_timeout=long_polling_timeout,
  File "K:\Scedule_Bot_1.0\.venv\Lib\site-packages\telebot\__init__.py", line 1273, in __threaded_polling
    raise e
  File "K:\Scedule_Bot_1.0\.venv\Lib\site-packages\telebot\__init__.py", line 1235, in __threaded_polling
    self.worker_pool.raise_exceptions()
  File "K:\Scedule_Bot_1.0\.venv\Lib\site-packages\telebot\util.py", line 150, in raise_exceptions
    raise self.exception_info
  File "K:\Scedule_Bot_1.0\.venv\Lib\site-packages\telebot\util.py", line 93, in run
    task(*args, **kwargs)
  File "K:\Scedule_Bot_1.0\.venv\Lib\site-packages\telebot\__init__.py", line 9759, in _run_middlewares_and_handler
    result = handler['function'](message)
             ^^^^^^^^^^^^^^^^^^^^^^^^^^^^
  File "K:\Scedule_Bot_1.0\telegram_bot\main.py", line 273, in get_schedule_for_user
    bot.send_message(message.from_user.id,
  File "K:\Scedule_Bot_1.0\.venv\Lib\site-packages\telebot\__init__.py", line 1800, in send_message
    apihelper.send_message(
  File "K:\Scedule_Bot_1.0\.venv\Lib\site-packages\telebot\apihelper.py", line 275, in send_message
    return _make_request(token, method_url, params=payload, method='post')
           ^^^^^^^^^^^^^^^^^^^^^^^^^^^^^^^^^^^^^^^^^^^^^^^^^^^^^^^^^^^^^^^
  File "K:\Scedule_Bot_1.0\.venv\Lib\site-packages\telebot\apihelper.py", line 162, in _make_request
    result = _get_req_session().request(
             ^^^^^^^^^^^^^^^^^^^^^^^^^^^
  File "K:\Scedule_Bot_1.0\.venv\Lib\site-packages\requests\sessions.py", line 589, in request
    resp = self.send(prep, **send_kwargs)
           ^^^^^^^^^^^^^^^^^^^^^^^^^^^^^^
  File "K:\Scedule_Bot_1.0\.venv\Lib\site-packages\requests\sessions.py", line 703, in send
    r = adapter.send(request, **kwargs)
        ^^^^^^^^^^^^^^^^^^^^^^^^^^^^^^^
  File "K:\Scedule_Bot_1.0\.venv\Lib\site-packages\requests\adapters.py", line 700, in send
    raise ConnectionError(e, request=request)
requests.exceptions.ConnectionError: HTTPSConnectionPool(host='api.telegram.org', port=443): Max retries exceeded with url: /bot8004422788:***********************************/sendMessage?chat_id=6983370282&text=%3Ccode%3E%D0%A0%D0%B0%D1%81%D0%BF.+%D0%B4%D0%BB%D1%8F+8%D0%9A+%D0%BD%D0%B0+%D0%A1%D1%80%D0%B5%D0%B4%D0%B0%3A%0A%E2%84%96.+%D0%9A%D0%B0%D0%B1%D0%B8%D0%BD%D0%B5%D1%82++%7C+%D0%9F%D1%80%D0%B5%D0%B4%D0%BC%D0%B5%D1%82%0A1.+---++++++%7C+---%0A2.+---++++++%7C+---%0A3.+207%D0%96+++++%7C+%D0%90%D0%BD%D0%B3%D0%BB%D0%B8%D0%B9%D1%81%D0%BA%D0%B8%D0%B9+%D1%8F%D0%B7%D1%8B%D0%BA%0A%7C++301%D0%92+++++%7C%0A4.+103%D0%92+++++%7C+%D0%91%D0%B8%D0%BE%D0%BB%D0%BE%D0%B3%D0%B8%D1%8F%0A5.+107%D0%92+++++%7C+%D0%90%D0%BB%D0%B3%D0%B5%D0%B1%D1%80%D0%B0%0A6.+107%D0%92+++++%7C+%D0%93%D0%B5%D0%BE%D0%BC%D0%B5%D1%82%D1%80%D0%B8%D1%8F%0A7.+---++++++%7C+---%0A%3C%2Fcode%3E&parse_mode=HTML (Caused by NameResolutionError("<urllib3.connection.HTTPSConnection object at 0x00000247C38D8950>: Failed to resolve 'api.telegram.org' ([Errno 11001] getaddrinfo failed)"))

2025-09-17 12:25:54 - ERROR - Infinity polling exception: HTTPSConnectionPool(host='api.telegram.org', port=443): Max retries exceeded with url: /bot8004422788:***********************************/getUpdates?offset=218512130&timeout=20 (Caused by NameResolutionError("<urllib3.connection.HTTPSConnection object at 0x00000247C38DBD40>: Failed to resolve 'api.telegram.org' ([Errno 11001] getaddrinfo failed)"))
2025-09-17 12:25:54 - ERROR - Exception traceback:
Traceback (most recent call last):
  File "K:\Scedule_Bot_1.0\.venv\Lib\site-packages\urllib3\connection.py", line 198, in _new_conn
    sock = connection.create_connection(
           ^^^^^^^^^^^^^^^^^^^^^^^^^^^^^
  File "K:\Scedule_Bot_1.0\.venv\Lib\site-packages\urllib3\util\connection.py", line 60, in create_connection
    for res in socket.getaddrinfo(host, port, family, socket.SOCK_STREAM):
               ^^^^^^^^^^^^^^^^^^^^^^^^^^^^^^^^^^^^^^^^^^^^^^^^^^^^^^^^^^
  File "C:\Users\kazak\AppData\Local\Programs\Python\Python312\Lib\socket.py", line 978, in getaddrinfo
    for res in _socket.getaddrinfo(host, port, family, type, proto, flags):
               ^^^^^^^^^^^^^^^^^^^^^^^^^^^^^^^^^^^^^^^^^^^^^^^^^^^^^^^^^^^
socket.gaierror: [Errno 11001] getaddrinfo failed

The above exception was the direct cause of the following exception:

Traceback (most recent call last):
  File "K:\Scedule_Bot_1.0\.venv\Lib\site-packages\urllib3\connectionpool.py", line 787, in urlopen
    response = self._make_request(
               ^^^^^^^^^^^^^^^^^^^
  File "K:\Scedule_Bot_1.0\.venv\Lib\site-packages\urllib3\connectionpool.py", line 488, in _make_request
    raise new_e
  File "K:\Scedule_Bot_1.0\.venv\Lib\site-packages\urllib3\connectionpool.py", line 464, in _make_request
    self._validate_conn(conn)
  File "K:\Scedule_Bot_1.0\.venv\Lib\site-packages\urllib3\connectionpool.py", line 1093, in _validate_conn
    conn.connect()
  File "K:\Scedule_Bot_1.0\.venv\Lib\site-packages\urllib3\connection.py", line 753, in connect
    self.sock = sock = self._new_conn()
                       ^^^^^^^^^^^^^^^^
  File "K:\Scedule_Bot_1.0\.venv\Lib\site-packages\urllib3\connection.py", line 205, in _new_conn
    raise NameResolutionError(self.host, self, e) from e
urllib3.exceptions.NameResolutionError: <urllib3.connection.HTTPSConnection object at 0x00000247C38DBD40>: Failed to resolve 'api.telegram.org' ([Errno 11001] getaddrinfo failed)

The above exception was the direct cause of the following exception:

Traceback (most recent call last):
  File "K:\Scedule_Bot_1.0\.venv\Lib\site-packages\requests\adapters.py", line 667, in send
    resp = conn.urlopen(
           ^^^^^^^^^^^^^
  File "K:\Scedule_Bot_1.0\.venv\Lib\site-packages\urllib3\connectionpool.py", line 841, in urlopen
    retries = retries.increment(
              ^^^^^^^^^^^^^^^^^^
  File "K:\Scedule_Bot_1.0\.venv\Lib\site-packages\urllib3\util\retry.py", line 519, in increment
    raise MaxRetryError(_pool, url, reason) from reason  # type: ignore[arg-type]
    ^^^^^^^^^^^^^^^^^^^^^^^^^^^^^^^^^^^^^^^^^^^^^^^^^^^
urllib3.exceptions.MaxRetryError: HTTPSConnectionPool(host='api.telegram.org', port=443): Max retries exceeded with url: /bot8004422788:***********************************/getUpdates?offset=218512130&timeout=20 (Caused by NameResolutionError("<urllib3.connection.HTTPSConnection object at 0x00000247C38DBD40>: Failed to resolve 'api.telegram.org' ([Errno 11001] getaddrinfo failed)"))

During handling of the above exception, another exception occurred:

Traceback (most recent call last):
  File "K:\Scedule_Bot_1.0\.venv\Lib\site-packages\telebot\__init__.py", line 1110, in infinity_polling
    self.polling(non_stop=True, timeout=timeout, long_polling_timeout=long_polling_timeout,
  File "K:\Scedule_Bot_1.0\.venv\Lib\site-packages\telebot\__init__.py", line 1198, in polling
    self.__threaded_polling(non_stop=non_stop, interval=interval, timeout=timeout, long_polling_timeout=long_polling_timeout,
  File "K:\Scedule_Bot_1.0\.venv\Lib\site-packages\telebot\__init__.py", line 1273, in __threaded_polling
    raise e
  File "K:\Scedule_Bot_1.0\.venv\Lib\site-packages\telebot\__init__.py", line 1234, in __threaded_polling
    polling_thread.raise_exceptions()
  File "K:\Scedule_Bot_1.0\.venv\Lib\site-packages\telebot\util.py", line 111, in raise_exceptions
    raise self.exception_info
  File "K:\Scedule_Bot_1.0\.venv\Lib\site-packages\telebot\util.py", line 93, in run
    task(*args, **kwargs)
  File "K:\Scedule_Bot_1.0\.venv\Lib\site-packages\telebot\__init__.py", line 688, in __retrieve_updates
    updates = self.get_updates(offset=(self.last_update_id + 1),
             ^^^^^^^^^^^^^^^^^^^^^^^^^^^^^^^^^^^^^^^^^^^^^^^^^^
  File "K:\Scedule_Bot_1.0\.venv\Lib\site-packages\telebot\__init__.py", line 660, in get_updates
    json_updates = apihelper.get_updates(
                   ^^^^^^^^^^^^^^^^^^^^^^
  File "K:\Scedule_Bot_1.0\.venv\Lib\site-packages\telebot\apihelper.py", line 332, in get_updates
    return _make_request(token, method_url, params=payload)
           ^^^^^^^^^^^^^^^^^^^^^^^^^^^^^^^^^^^^^^^^^^^^^^^^
  File "K:\Scedule_Bot_1.0\.venv\Lib\site-packages\telebot\apihelper.py", line 162, in _make_request
    result = _get_req_session().request(
             ^^^^^^^^^^^^^^^^^^^^^^^^^^^
  File "K:\Scedule_Bot_1.0\.venv\Lib\site-packages\requests\sessions.py", line 589, in request
    resp = self.send(prep, **send_kwargs)
           ^^^^^^^^^^^^^^^^^^^^^^^^^^^^^^
  File "K:\Scedule_Bot_1.0\.venv\Lib\site-packages\requests\sessions.py", line 703, in send
    r = adapter.send(request, **kwargs)
        ^^^^^^^^^^^^^^^^^^^^^^^^^^^^^^^
  File "K:\Scedule_Bot_1.0\.venv\Lib\site-packages\requests\adapters.py", line 700, in send
    raise ConnectionError(e, request=request)
requests.exceptions.ConnectionError: HTTPSConnectionPool(host='api.telegram.org', port=443): Max retries exceeded with url: /bot8004422788:***********************************/getUpdates?offset=218512130&timeout=20 (Caused by NameResolutionError("<urllib3.connection.HTTPSConnection object at 0x00000247C38DBD40>: Failed to resolve 'api.telegram.org' ([Errno 11001] getaddrinfo failed)"))

2025-09-17 12:25:57 - ERROR - Infinity polling exception: HTTPSConnectionPool(host='api.telegram.org', port=443): Max retries exceeded with url: /bot8004422788:***********************************/getUpdates?offset=218512130&timeout=20 (Caused by NameResolutionError("<urllib3.connection.HTTPSConnection object at 0x00000247C38DBA10>: Failed to resolve 'api.telegram.org' ([Errno 11001] getaddrinfo failed)"))
2025-09-17 12:25:57 - ERROR - Exception traceback:
Traceback (most recent call last):
  File "K:\Scedule_Bot_1.0\.venv\Lib\site-packages\urllib3\connection.py", line 198, in _new_conn
    sock = connection.create_connection(
           ^^^^^^^^^^^^^^^^^^^^^^^^^^^^^
  File "K:\Scedule_Bot_1.0\.venv\Lib\site-packages\urllib3\util\connection.py", line 60, in create_connection
    for res in socket.getaddrinfo(host, port, family, socket.SOCK_STREAM):
               ^^^^^^^^^^^^^^^^^^^^^^^^^^^^^^^^^^^^^^^^^^^^^^^^^^^^^^^^^^
  File "C:\Users\kazak\AppData\Local\Programs\Python\Python312\Lib\socket.py", line 978, in getaddrinfo
    for res in _socket.getaddrinfo(host, port, family, type, proto, flags):
               ^^^^^^^^^^^^^^^^^^^^^^^^^^^^^^^^^^^^^^^^^^^^^^^^^^^^^^^^^^^
socket.gaierror: [Errno 11001] getaddrinfo failed

The above exception was the direct cause of the following exception:

Traceback (most recent call last):
  File "K:\Scedule_Bot_1.0\.venv\Lib\site-packages\urllib3\connectionpool.py", line 787, in urlopen
    response = self._make_request(
               ^^^^^^^^^^^^^^^^^^^
  File "K:\Scedule_Bot_1.0\.venv\Lib\site-packages\urllib3\connectionpool.py", line 488, in _make_request
    raise new_e
  File "K:\Scedule_Bot_1.0\.venv\Lib\site-packages\urllib3\connectionpool.py", line 464, in _make_request
    self._validate_conn(conn)
  File "K:\Scedule_Bot_1.0\.venv\Lib\site-packages\urllib3\connectionpool.py", line 1093, in _validate_conn
    conn.connect()
  File "K:\Scedule_Bot_1.0\.venv\Lib\site-packages\urllib3\connection.py", line 753, in connect
    self.sock = sock = self._new_conn()
                       ^^^^^^^^^^^^^^^^
  File "K:\Scedule_Bot_1.0\.venv\Lib\site-packages\urllib3\connection.py", line 205, in _new_conn
    raise NameResolutionError(self.host, self, e) from e
urllib3.exceptions.NameResolutionError: <urllib3.connection.HTTPSConnection object at 0x00000247C38DBA10>: Failed to resolve 'api.telegram.org' ([Errno 11001] getaddrinfo failed)

The above exception was the direct cause of the following exception:

Traceback (most recent call last):
  File "K:\Scedule_Bot_1.0\.venv\Lib\site-packages\requests\adapters.py", line 667, in send
    resp = conn.urlopen(
           ^^^^^^^^^^^^^
  File "K:\Scedule_Bot_1.0\.venv\Lib\site-packages\urllib3\connectionpool.py", line 841, in urlopen
    retries = retries.increment(
              ^^^^^^^^^^^^^^^^^^
  File "K:\Scedule_Bot_1.0\.venv\Lib\site-packages\urllib3\util\retry.py", line 519, in increment
    raise MaxRetryError(_pool, url, reason) from reason  # type: ignore[arg-type]
    ^^^^^^^^^^^^^^^^^^^^^^^^^^^^^^^^^^^^^^^^^^^^^^^^^^^
urllib3.exceptions.MaxRetryError: HTTPSConnectionPool(host='api.telegram.org', port=443): Max retries exceeded with url: /bot8004422788:***********************************/getUpdates?offset=218512130&timeout=20 (Caused by NameResolutionError("<urllib3.connection.HTTPSConnection object at 0x00000247C38DBA10>: Failed to resolve 'api.telegram.org' ([Errno 11001] getaddrinfo failed)"))

During handling of the above exception, another exception occurred:

Traceback (most recent call last):
  File "K:\Scedule_Bot_1.0\.venv\Lib\site-packages\telebot\__init__.py", line 1110, in infinity_polling
    self.polling(non_stop=True, timeout=timeout, long_polling_timeout=long_polling_timeout,
  File "K:\Scedule_Bot_1.0\.venv\Lib\site-packages\telebot\__init__.py", line 1198, in polling
    self.__threaded_polling(non_stop=non_stop, interval=interval, timeout=timeout, long_polling_timeout=long_polling_timeout,
  File "K:\Scedule_Bot_1.0\.venv\Lib\site-packages\telebot\__init__.py", line 1273, in __threaded_polling
    raise e
  File "K:\Scedule_Bot_1.0\.venv\Lib\site-packages\telebot\__init__.py", line 1234, in __threaded_polling
    polling_thread.raise_exceptions()
  File "K:\Scedule_Bot_1.0\.venv\Lib\site-packages\telebot\util.py", line 111, in raise_exceptions
    raise self.exception_info
  File "K:\Scedule_Bot_1.0\.venv\Lib\site-packages\telebot\util.py", line 93, in run
    task(*args, **kwargs)
  File "K:\Scedule_Bot_1.0\.venv\Lib\site-packages\telebot\__init__.py", line 688, in __retrieve_updates
    updates = self.get_updates(offset=(self.last_update_id + 1),
             ^^^^^^^^^^^^^^^^^^^^^^^^^^^^^^^^^^^^^^^^^^^^^^^^^^
  File "K:\Scedule_Bot_1.0\.venv\Lib\site-packages\telebot\__init__.py", line 660, in get_updates
    json_updates = apihelper.get_updates(
                   ^^^^^^^^^^^^^^^^^^^^^^
  File "K:\Scedule_Bot_1.0\.venv\Lib\site-packages\telebot\apihelper.py", line 332, in get_updates
    return _make_request(token, method_url, params=payload)
           ^^^^^^^^^^^^^^^^^^^^^^^^^^^^^^^^^^^^^^^^^^^^^^^^
  File "K:\Scedule_Bot_1.0\.venv\Lib\site-packages\telebot\apihelper.py", line 162, in _make_request
    result = _get_req_session().request(
             ^^^^^^^^^^^^^^^^^^^^^^^^^^^
  File "K:\Scedule_Bot_1.0\.venv\Lib\site-packages\requests\sessions.py", line 589, in request
    resp = self.send(prep, **send_kwargs)
           ^^^^^^^^^^^^^^^^^^^^^^^^^^^^^^
  File "K:\Scedule_Bot_1.0\.venv\Lib\site-packages\requests\sessions.py", line 703, in send
    r = adapter.send(request, **kwargs)
        ^^^^^^^^^^^^^^^^^^^^^^^^^^^^^^^
  File "K:\Scedule_Bot_1.0\.venv\Lib\site-packages\requests\adapters.py", line 700, in send
    raise ConnectionError(e, request=request)
requests.exceptions.ConnectionError: HTTPSConnectionPool(host='api.telegram.org', port=443): Max retries exceeded with url: /bot8004422788:***********************************/getUpdates?offset=218512130&timeout=20 (Caused by NameResolutionError("<urllib3.connection.HTTPSConnection object at 0x00000247C38DBA10>: Failed to resolve 'api.telegram.org' ([Errno 11001] getaddrinfo failed)"))

2025-09-17 12:26:30 - INFO - 6983370282 used GET SCHEDULE FUNC and choice Среда
2025-09-17 12:27:39 - INFO - Getting data from server
2025-09-17 12:27:41 - INFO - Start schedule normalization
2025-09-17 12:27:41 - INFO - Schedule normalized
2025-09-17 12:27:41 - INFO - Data received from server
2025-09-17 12:32:41 - INFO - Getting data from server
2025-09-17 12:32:42 - INFO - Start schedule normalization
2025-09-17 12:32:42 - INFO - Schedule is the same. Cancel.
2025-09-17 12:32:42 - INFO - Data received from server
2025-09-17 12:37:42 - INFO - Getting data from server
2025-09-17 12:37:44 - INFO - Start schedule normalization
2025-09-17 12:37:44 - INFO - Schedule is the same. Cancel.
2025-09-17 12:37:44 - INFO - Data received from server
2025-09-17 12:42:44 - INFO - Getting data from server
2025-09-17 12:42:45 - INFO - Start schedule normalization
2025-09-17 12:42:45 - INFO - Schedule is the same. Cancel.
2025-09-17 12:42:45 - INFO - Data received from server
2025-09-17 12:47:45 - INFO - Getting data from server
2025-09-17 12:47:47 - INFO - Start schedule normalization
2025-09-17 12:47:47 - INFO - Schedule is the same. Cancel.
2025-09-17 12:47:47 - INFO - Data received from server
2025-09-17 12:52:47 - INFO - Getting data from server
2025-09-17 12:52:48 - INFO - Start schedule normalization
2025-09-17 12:52:48 - INFO - Schedule is the same. Cancel.
2025-09-17 12:52:48 - INFO - Data received from server
2025-09-17 12:57:48 - INFO - Getting data from server
2025-09-17 12:57:49 - INFO - Start schedule normalization
2025-09-17 12:57:50 - INFO - Schedule is the same. Cancel.
2025-09-17 12:57:50 - INFO - Data received from server
2025-09-17 13:02:50 - INFO - Getting data from server
2025-09-17 13:02:51 - INFO - Start schedule normalization
2025-09-17 13:02:51 - INFO - Schedule is the same. Cancel.
2025-09-17 13:02:51 - INFO - Data received from server
2025-09-17 13:07:51 - INFO - Getting data from server
2025-09-17 13:07:53 - INFO - Start schedule normalization
2025-09-17 13:07:53 - INFO - Schedule is the same. Cancel.
2025-09-17 13:07:53 - INFO - Data received from server
2025-09-17 13:12:53 - INFO - Getting data from server
2025-09-17 13:12:54 - INFO - Start schedule normalization
2025-09-17 13:12:54 - INFO - Schedule is the same. Cancel.
2025-09-17 13:12:54 - INFO - Data received from server
2025-09-17 13:17:54 - INFO - Getting data from server
2025-09-17 13:17:56 - INFO - Start schedule normalization
2025-09-17 13:17:56 - INFO - Schedule is the same. Cancel.
2025-09-17 13:17:56 - INFO - Data received from server
2025-09-17 13:22:56 - INFO - Getting data from server
2025-09-17 13:22:57 - INFO - Start schedule normalization
2025-09-17 13:22:57 - INFO - Schedule is the same. Cancel.
2025-09-17 13:22:57 - INFO - Data received from server
2025-09-17 13:27:57 - INFO - Getting data from server
2025-09-17 13:27:59 - INFO - Start schedule normalization
2025-09-17 13:27:59 - INFO - Schedule normalized
2025-09-17 13:27:59 - INFO - Data received from server
2025-09-17 13:32:59 - INFO - Getting data from server
2025-09-17 13:33:00 - INFO - Start schedule normalization
2025-09-17 13:33:01 - INFO - Schedule normalized
2025-09-17 13:33:01 - INFO - Data received from server
2025-09-17 13:38:01 - INFO - Getting data from server
2025-09-17 13:38:02 - INFO - Start schedule normalization
2025-09-17 13:38:02 - INFO - Schedule is the same. Cancel.
2025-09-17 13:38:02 - INFO - Data received from server
2025-09-17 13:43:02 - INFO - Getting data from server
2025-09-17 13:43:04 - INFO - Start schedule normalization
2025-09-17 13:43:04 - INFO - Schedule is the same. Cancel.
2025-09-17 13:43:04 - INFO - Data received from server
2025-09-17 13:48:04 - INFO - Getting data from server
2025-09-17 13:48:05 - INFO - Start schedule normalization
2025-09-17 13:48:05 - INFO - Schedule is the same. Cancel.
2025-09-17 13:48:05 - INFO - Data received from server
2025-09-17 13:53:05 - INFO - Getting data from server
2025-09-17 13:53:07 - INFO - Start schedule normalization
2025-09-17 13:53:07 - INFO - Schedule is the same. Cancel.
2025-09-17 13:53:07 - INFO - Data received from server
2025-09-17 13:58:07 - INFO - Getting data from server
2025-09-17 13:58:08 - INFO - Start schedule normalization
2025-09-17 13:58:08 - INFO - Schedule is the same. Cancel.
2025-09-17 13:58:08 - INFO - Data received from server
2025-09-17 14:03:08 - INFO - Getting data from server
2025-09-17 14:03:10 - INFO - Start schedule normalization
2025-09-17 14:03:10 - INFO - Schedule is the same. Cancel.
2025-09-17 14:03:10 - INFO - Data received from server
2025-09-17 14:08:10 - INFO - Getting data from server
2025-09-17 14:08:11 - INFO - Start schedule normalization
2025-09-17 14:08:11 - INFO - Schedule is the same. Cancel.
2025-09-17 14:08:11 - INFO - Data received from server
2025-09-17 14:13:11 - INFO - Getting data from server
2025-09-17 14:13:13 - INFO - Start schedule normalization
2025-09-17 14:13:13 - INFO - Schedule normalized
2025-09-17 14:13:13 - INFO - Data received from server
2025-09-17 14:18:13 - INFO - Getting data from server
2025-09-17 14:18:14 - INFO - Start schedule normalization
2025-09-17 14:18:14 - INFO - Schedule normalized
2025-09-17 14:18:14 - INFO - Data received from server
2025-09-17 14:23:14 - INFO - Getting data from server
2025-09-17 14:23:16 - INFO - Start schedule normalization
2025-09-17 14:23:16 - INFO - Schedule is the same. Cancel.
2025-09-17 14:23:16 - INFO - Data received from server
2025-09-17 14:28:16 - INFO - Getting data from server
2025-09-17 14:28:17 - INFO - Start schedule normalization
2025-09-17 14:28:17 - INFO - Schedule is the same. Cancel.
2025-09-17 14:28:17 - INFO - Data received from server
2025-09-17 14:28:50 - ERROR - Infinity polling: polling exited
2025-09-17 14:28:50 - ERROR - Break infinity polling
2025-09-17 17:56:00 - INFO - ###############################
2025-09-17 17:56:00 - INFO - TEST INFO LOGGING FINALLY
2025-09-17 17:56:00 - WARNING - TEST WARNING LOGGING FINALLY
2025-09-17 17:56:00 - ERROR - Error to: utils.my_logger | Index: 0
NoneType: None
2025-09-17 17:56:00 - CRITICAL - TEST FATAL LOGGING FINALLY
2025-09-17 17:56:00 - INFO - LOGGER STARTED
2025-09-17 17:56:00 - INFO - ###############################
2025-09-17 17:56:00 - INFO - Stated connect to db
2025-09-17 17:56:00 - INFO - Users db created/exist
2025-09-17 17:56:00 - INFO - WS Parser started!
2025-09-17 17:56:00 - INFO - Getting data from server
2025-09-17 17:56:02 - INFO - Start schedule normalization
2025-09-17 17:56:03 - INFO - Schedule normalized
2025-09-17 17:56:03 - INFO - Data received from server
2025-09-17 17:56:06 - INFO - 6983370282 used GET SCHEDULE FUNC and choice Четверг
2025-09-17 18:01:03 - INFO - Getting data from server
2025-09-17 18:01:04 - INFO - Start schedule normalization
2025-09-17 18:01:04 - INFO - Schedule is the same. Cancel.
2025-09-17 18:01:04 - INFO - Data received from server
2025-09-17 18:06:04 - INFO - Getting data from server
2025-09-17 18:06:06 - INFO - Start schedule normalization
2025-09-17 18:06:06 - INFO - Schedule is the same. Cancel.
2025-09-17 18:06:06 - INFO - Data received from server
2025-09-17 18:11:06 - INFO - Getting data from server
2025-09-17 18:11:07 - INFO - Start schedule normalization
2025-09-17 18:11:07 - INFO - Schedule is the same. Cancel.
2025-09-17 18:11:07 - INFO - Data received from server
2025-09-17 18:16:07 - INFO - Getting data from server
2025-09-17 18:16:09 - INFO - Start schedule normalization
2025-09-17 18:16:09 - INFO - Schedule is the same. Cancel.
2025-09-17 18:16:09 - INFO - Data received from server
2025-09-17 18:21:09 - INFO - Getting data from server
2025-09-17 18:21:10 - INFO - Start schedule normalization
2025-09-17 18:21:10 - INFO - Schedule is the same. Cancel.
2025-09-17 18:21:10 - INFO - Data received from server
2025-09-17 18:26:10 - INFO - Getting data from server
2025-09-17 18:26:12 - INFO - Start schedule normalization
2025-09-17 18:26:12 - INFO - Schedule is the same. Cancel.
2025-09-17 18:26:12 - INFO - Data received from server
2025-09-17 18:31:12 - INFO - Getting data from server
2025-09-17 18:31:13 - INFO - Start schedule normalization
2025-09-17 18:31:13 - INFO - Schedule is the same. Cancel.
2025-09-17 18:31:13 - INFO - Data received from server
2025-09-17 18:36:13 - INFO - Getting data from server
2025-09-17 18:36:14 - INFO - Start schedule normalization
2025-09-17 18:36:14 - INFO - Schedule is the same. Cancel.
2025-09-17 18:36:14 - INFO - Data received from server
2025-09-17 18:41:14 - INFO - Getting data from server
2025-09-17 18:41:16 - INFO - Start schedule normalization
2025-09-17 18:41:16 - INFO - Schedule is the same. Cancel.
2025-09-17 18:41:16 - INFO - Data received from server
2025-09-17 18:46:16 - INFO - Getting data from server
2025-09-17 18:46:17 - INFO - Start schedule normalization
2025-09-17 18:46:17 - INFO - Schedule is the same. Cancel.
2025-09-17 18:46:17 - INFO - Data received from server
2025-09-17 18:51:17 - INFO - Getting data from server
2025-09-17 18:51:19 - INFO - Start schedule normalization
2025-09-17 18:51:19 - INFO - Schedule is the same. Cancel.
2025-09-17 18:51:19 - INFO - Data received from server
2025-09-17 18:56:19 - INFO - Getting data from server
2025-09-17 18:56:20 - INFO - Start schedule normalization
2025-09-17 18:56:20 - INFO - Schedule is the same. Cancel.
2025-09-17 18:56:20 - INFO - Data received from server
2025-09-17 19:01:20 - INFO - Getting data from server
2025-09-17 19:01:22 - INFO - Start schedule normalization
2025-09-17 19:01:22 - INFO - Schedule is the same. Cancel.
2025-09-17 19:01:22 - INFO - Data received from server
2025-09-17 19:06:22 - INFO - Getting data from server
2025-09-17 19:06:23 - INFO - Start schedule normalization
2025-09-17 19:06:23 - INFO - Schedule is the same. Cancel.
2025-09-17 19:06:23 - INFO - Data received from server
2025-09-17 19:11:23 - INFO - Getting data from server
2025-09-17 19:11:25 - INFO - Start schedule normalization
2025-09-17 19:11:25 - INFO - Schedule is the same. Cancel.
2025-09-17 19:11:25 - INFO - Data received from server
2025-09-17 19:16:25 - INFO - Getting data from server
2025-09-17 19:16:26 - INFO - Start schedule normalization
2025-09-17 19:16:26 - INFO - Schedule is the same. Cancel.
2025-09-17 19:16:26 - INFO - Data received from server
2025-09-17 19:21:26 - INFO - Getting data from server
2025-09-17 19:21:28 - INFO - Start schedule normalization
2025-09-17 19:21:28 - INFO - Schedule is the same. Cancel.
2025-09-17 19:21:28 - INFO - Data received from server
2025-09-17 19:26:28 - INFO - Getting data from server
2025-09-17 19:26:29 - INFO - Start schedule normalization
2025-09-17 19:26:29 - INFO - Schedule is the same. Cancel.
2025-09-17 19:26:29 - INFO - Data received from server
2025-09-17 19:31:29 - INFO - Getting data from server
2025-09-17 19:31:31 - INFO - Start schedule normalization
2025-09-17 19:31:31 - INFO - Schedule is the same. Cancel.
2025-09-17 19:31:31 - INFO - Data received from server
2025-09-17 19:36:31 - INFO - Getting data from server
2025-09-17 19:36:32 - INFO - Start schedule normalization
2025-09-17 19:36:32 - INFO - Schedule is the same. Cancel.
2025-09-17 19:36:32 - INFO - Data received from server
2025-09-17 19:41:32 - INFO - Getting data from server
2025-09-17 19:41:34 - INFO - Start schedule normalization
2025-09-17 19:41:34 - INFO - Schedule is the same. Cancel.
2025-09-17 19:41:34 - INFO - Data received from server
2025-09-17 19:46:34 - INFO - Getting data from server
2025-09-17 19:46:35 - INFO - Start schedule normalization
2025-09-17 19:46:35 - INFO - Schedule is the same. Cancel.
2025-09-17 19:46:35 - INFO - Data received from server
2025-09-17 19:51:35 - INFO - Getting data from server
2025-09-17 19:51:57 - INFO - Data received from server
2025-09-17 19:56:57 - INFO - Getting data from server
2025-09-17 19:56:58 - INFO - Start schedule normalization
2025-09-17 19:56:58 - INFO - Schedule is the same. Cancel.
2025-09-17 19:56:58 - INFO - Data received from server
2025-09-17 20:01:58 - INFO - Getting data from server
2025-09-17 20:02:00 - INFO - Start schedule normalization
2025-09-17 20:02:00 - INFO - Schedule is the same. Cancel.
2025-09-17 20:02:00 - INFO - Data received from server
2025-09-17 20:07:00 - INFO - Getting data from server
2025-09-17 20:07:01 - INFO - Start schedule normalization
2025-09-17 20:07:01 - INFO - Schedule is the same. Cancel.
2025-09-17 20:07:01 - INFO - Data received from server
2025-09-17 20:12:01 - INFO - Getting data from server
2025-09-17 20:12:03 - INFO - Start schedule normalization
2025-09-17 20:12:03 - INFO - Schedule is the same. Cancel.
2025-09-17 20:12:03 - INFO - Data received from server
2025-09-17 20:12:27 - ERROR - Infinity polling exception: HTTPSConnectionPool(host='api.telegram.org', port=443): Read timed out. (read timeout=25)
2025-09-17 20:12:27 - ERROR - Exception traceback:
Traceback (most recent call last):
  File "K:\Scedule_Bot_1.0\.venv\Lib\site-packages\urllib3\connectionpool.py", line 534, in _make_request
    response = conn.getresponse()
               ^^^^^^^^^^^^^^^^^^
  File "K:\Scedule_Bot_1.0\.venv\Lib\site-packages\urllib3\connection.py", line 565, in getresponse
    httplib_response = super().getresponse()
                       ^^^^^^^^^^^^^^^^^^^^^
  File "C:\Users\kazak\AppData\Local\Programs\Python\Python312\Lib\http\client.py", line 1430, in getresponse
    response.begin()
  File "C:\Users\kazak\AppData\Local\Programs\Python\Python312\Lib\http\client.py", line 331, in begin
    version, status, reason = self._read_status()
                              ^^^^^^^^^^^^^^^^^^^
  File "C:\Users\kazak\AppData\Local\Programs\Python\Python312\Lib\http\client.py", line 292, in _read_status
    line = str(self.fp.readline(_MAXLINE + 1), "iso-8859-1")
               ^^^^^^^^^^^^^^^^^^^^^^^^^^^^^^
  File "C:\Users\kazak\AppData\Local\Programs\Python\Python312\Lib\socket.py", line 720, in readinto
    return self._sock.recv_into(b)
           ^^^^^^^^^^^^^^^^^^^^^^^
  File "C:\Users\kazak\AppData\Local\Programs\Python\Python312\Lib\ssl.py", line 1251, in recv_into
    return self.read(nbytes, buffer)
           ^^^^^^^^^^^^^^^^^^^^^^^^^
  File "C:\Users\kazak\AppData\Local\Programs\Python\Python312\Lib\ssl.py", line 1103, in read
    return self._sslobj.read(len, buffer)
           ^^^^^^^^^^^^^^^^^^^^^^^^^^^^^^
TimeoutError: The read operation timed out

The above exception was the direct cause of the following exception:

Traceback (most recent call last):
  File "K:\Scedule_Bot_1.0\.venv\Lib\site-packages\requests\adapters.py", line 667, in send
    resp = conn.urlopen(
           ^^^^^^^^^^^^^
  File "K:\Scedule_Bot_1.0\.venv\Lib\site-packages\urllib3\connectionpool.py", line 841, in urlopen
    retries = retries.increment(
              ^^^^^^^^^^^^^^^^^^
  File "K:\Scedule_Bot_1.0\.venv\Lib\site-packages\urllib3\util\retry.py", line 474, in increment
    raise reraise(type(error), error, _stacktrace)
          ^^^^^^^^^^^^^^^^^^^^^^^^^^^^^^^^^^^^^^^^
  File "K:\Scedule_Bot_1.0\.venv\Lib\site-packages\urllib3\util\util.py", line 39, in reraise
    raise value
  File "K:\Scedule_Bot_1.0\.venv\Lib\site-packages\urllib3\connectionpool.py", line 787, in urlopen
    response = self._make_request(
               ^^^^^^^^^^^^^^^^^^^
  File "K:\Scedule_Bot_1.0\.venv\Lib\site-packages\urllib3\connectionpool.py", line 536, in _make_request
    self._raise_timeout(err=e, url=url, timeout_value=read_timeout)
  File "K:\Scedule_Bot_1.0\.venv\Lib\site-packages\urllib3\connectionpool.py", line 367, in _raise_timeout
    raise ReadTimeoutError(
urllib3.exceptions.ReadTimeoutError: HTTPSConnectionPool(host='api.telegram.org', port=443): Read timed out. (read timeout=25)

During handling of the above exception, another exception occurred:

Traceback (most recent call last):
  File "K:\Scedule_Bot_1.0\.venv\Lib\site-packages\telebot\__init__.py", line 1110, in infinity_polling
    self.polling(non_stop=True, timeout=timeout, long_polling_timeout=long_polling_timeout,
  File "K:\Scedule_Bot_1.0\.venv\Lib\site-packages\telebot\__init__.py", line 1198, in polling
    self.__threaded_polling(non_stop=non_stop, interval=interval, timeout=timeout, long_polling_timeout=long_polling_timeout,
  File "K:\Scedule_Bot_1.0\.venv\Lib\site-packages\telebot\__init__.py", line 1273, in __threaded_polling
    raise e
  File "K:\Scedule_Bot_1.0\.venv\Lib\site-packages\telebot\__init__.py", line 1234, in __threaded_polling
    polling_thread.raise_exceptions()
  File "K:\Scedule_Bot_1.0\.venv\Lib\site-packages\telebot\util.py", line 111, in raise_exceptions
    raise self.exception_info
  File "K:\Scedule_Bot_1.0\.venv\Lib\site-packages\telebot\util.py", line 93, in run
    task(*args, **kwargs)
  File "K:\Scedule_Bot_1.0\.venv\Lib\site-packages\telebot\__init__.py", line 688, in __retrieve_updates
    updates = self.get_updates(offset=(self.last_update_id + 1),
             ^^^^^^^^^^^^^^^^^^^^^^^^^^^^^^^^^^^^^^^^^^^^^^^^^^
  File "K:\Scedule_Bot_1.0\.venv\Lib\site-packages\telebot\__init__.py", line 660, in get_updates
    json_updates = apihelper.get_updates(
                   ^^^^^^^^^^^^^^^^^^^^^^
  File "K:\Scedule_Bot_1.0\.venv\Lib\site-packages\telebot\apihelper.py", line 332, in get_updates
    return _make_request(token, method_url, params=payload)
           ^^^^^^^^^^^^^^^^^^^^^^^^^^^^^^^^^^^^^^^^^^^^^^^^
  File "K:\Scedule_Bot_1.0\.venv\Lib\site-packages\telebot\apihelper.py", line 162, in _make_request
    result = _get_req_session().request(
             ^^^^^^^^^^^^^^^^^^^^^^^^^^^
  File "K:\Scedule_Bot_1.0\.venv\Lib\site-packages\requests\sessions.py", line 589, in request
    resp = self.send(prep, **send_kwargs)
           ^^^^^^^^^^^^^^^^^^^^^^^^^^^^^^
  File "K:\Scedule_Bot_1.0\.venv\Lib\site-packages\requests\sessions.py", line 703, in send
    r = adapter.send(request, **kwargs)
        ^^^^^^^^^^^^^^^^^^^^^^^^^^^^^^^
  File "K:\Scedule_Bot_1.0\.venv\Lib\site-packages\requests\adapters.py", line 713, in send
    raise ReadTimeout(e, request=request)
requests.exceptions.ReadTimeout: HTTPSConnectionPool(host='api.telegram.org', port=443): Read timed out. (read timeout=25)

2025-09-17 20:17:03 - INFO - Getting data from server
2025-09-17 20:17:04 - INFO - Start schedule normalization
2025-09-17 20:17:04 - INFO - Schedule is the same. Cancel.
2025-09-17 20:17:04 - INFO - Data received from server
2025-09-17 20:22:04 - INFO - Getting data from server
2025-09-17 20:22:06 - INFO - Start schedule normalization
2025-09-17 20:22:06 - INFO - Schedule is the same. Cancel.
2025-09-17 20:22:06 - INFO - Data received from server
2025-09-17 20:27:06 - INFO - Getting data from server
2025-09-17 20:27:07 - INFO - Start schedule normalization
2025-09-17 20:27:07 - INFO - Schedule is the same. Cancel.
2025-09-17 20:27:07 - INFO - Data received from server
2025-09-17 20:32:07 - INFO - Getting data from server
2025-09-17 20:32:09 - INFO - Start schedule normalization
2025-09-17 20:32:09 - INFO - Schedule is the same. Cancel.
2025-09-17 20:32:09 - INFO - Data received from server
2025-09-17 20:37:09 - INFO - Getting data from server
2025-09-17 20:37:10 - INFO - Start schedule normalization
2025-09-17 20:37:10 - INFO - Schedule is the same. Cancel.
2025-09-17 20:37:10 - INFO - Data received from server
2025-09-17 20:42:10 - INFO - Getting data from server
2025-09-17 20:42:12 - INFO - Start schedule normalization
2025-09-17 20:42:12 - INFO - Schedule is the same. Cancel.
2025-09-17 20:42:12 - INFO - Data received from server
2025-09-17 20:47:12 - INFO - Getting data from server
2025-09-17 20:47:13 - INFO - Start schedule normalization
2025-09-17 20:47:13 - INFO - Schedule is the same. Cancel.
2025-09-17 20:47:13 - INFO - Data received from server
2025-09-17 20:52:13 - INFO - Getting data from server
2025-09-17 20:52:14 - INFO - Start schedule normalization
2025-09-17 20:52:15 - INFO - Schedule is the same. Cancel.
2025-09-17 20:52:15 - INFO - Data received from server
2025-09-17 20:57:15 - INFO - Getting data from server
2025-09-17 20:57:36 - INFO - Data received from server
