2025-09-16 06:49:42 - INFO - ###############################
2025-09-16 06:49:42 - INFO - TEST INFO LOGGING FINALLY
2025-09-16 06:49:42 - WARNING - TEST WARNING LOGGING FINALLY
2025-09-16 06:49:42 - ERROR - Error to: utils.my_logger | Index: 0
NoneType: None
2025-09-16 06:49:42 - CRITICAL - TEST FATAL LOGGING FINALLY
2025-09-16 06:49:42 - INFO - LOGGER STARTED
2025-09-16 06:49:42 - INFO - ###############################
2025-09-16 06:49:42 - INFO - Stated connect to db
2025-09-16 06:49:42 - INFO - Users db created/exist
2025-09-16 06:49:42 - INFO - WS Parser started!
2025-09-16 06:49:42 - INFO - Getting data from server
2025-09-16 06:49:44 - INFO - Start schedule normalization
2025-09-16 06:49:44 - INFO - Schedule is the same. Cancel.
2025-09-16 06:49:44 - INFO - Data received from server
2025-09-16 06:51:38 - INFO - ###############################
2025-09-16 06:51:38 - INFO - TEST INFO LOGGING FINALLY
2025-09-16 06:51:38 - WARNING - TEST WARNING LOGGING FINALLY
2025-09-16 06:51:38 - ERROR - Error to: utils.my_logger | Index: 0
NoneType: None
2025-09-16 06:51:38 - CRITICAL - TEST FATAL LOGGING FINALLY
2025-09-16 06:51:38 - INFO - LOGGER STARTED
2025-09-16 06:51:38 - INFO - ###############################
2025-09-16 06:51:38 - INFO - Stated connect to db
2025-09-16 06:51:38 - INFO - Users db created/exist
2025-09-16 06:51:38 - INFO - WS Parser started!
2025-09-16 06:51:38 - INFO - Getting data from server
2025-09-16 06:51:39 - INFO - Start schedule normalization
2025-09-16 06:51:39 - INFO - Schedule is the same. Cancel.
2025-09-16 06:51:39 - INFO - Data received from server
2025-09-16 06:56:20 - INFO - 6983370282 used GET SCHEDULE FUNC and choice Среда
2025-09-16 06:56:29 - INFO - 6983370282 used GET SCHEDULE FUNC and choice Вторник
2025-09-16 06:56:39 - INFO - Getting data from server
2025-09-16 06:56:41 - INFO - Start schedule normalization
2025-09-16 06:56:41 - INFO - Schedule normalized
2025-09-16 06:56:41 - INFO - Data received from server
2025-09-16 07:01:41 - INFO - Getting data from server
2025-09-16 07:01:42 - INFO - Start schedule normalization
2025-09-16 07:01:43 - INFO - Schedule normalized
2025-09-16 07:01:43 - INFO - Data received from server
2025-09-16 07:06:43 - INFO - Getting data from server
2025-09-16 07:06:44 - INFO - Start schedule normalization
2025-09-16 07:06:44 - INFO - Schedule is the same. Cancel.
2025-09-16 07:06:44 - INFO - Data received from server
2025-09-16 07:11:44 - INFO - Getting data from server
2025-09-16 07:11:45 - INFO - Start schedule normalization
2025-09-16 07:11:46 - INFO - Schedule is the same. Cancel.
2025-09-16 07:11:46 - INFO - Data received from server
2025-09-16 07:16:46 - INFO - Getting data from server
2025-09-16 07:16:47 - INFO - Start schedule normalization
2025-09-16 07:16:47 - INFO - Schedule is the same. Cancel.
2025-09-16 07:16:47 - INFO - Data received from server
2025-09-16 07:21:47 - INFO - Getting data from server
2025-09-16 07:22:08 - INFO - Data received from server
2025-09-16 07:27:08 - INFO - Getting data from server
2025-09-16 07:27:10 - INFO - Start schedule normalization
2025-09-16 07:27:10 - INFO - Schedule normalized
2025-09-16 07:27:10 - INFO - Data received from server
2025-09-16 07:32:10 - INFO - Getting data from server
2025-09-16 07:32:11 - INFO - Start schedule normalization
2025-09-16 07:32:11 - INFO - Schedule is the same. Cancel.
2025-09-16 07:32:11 - INFO - Data received from server
2025-09-16 07:33:52 - INFO - 6983370282 used GET SCHEDULE FUNC and choice Вторник
2025-09-16 07:37:11 - INFO - Getting data from server
2025-09-16 07:37:13 - INFO - Start schedule normalization
2025-09-16 07:37:13 - INFO - Schedule is the same. Cancel.
2025-09-16 07:37:13 - INFO - Data received from server
2025-09-16 07:41:21 - INFO - 2045262706 used START MESSAGE FUNC
2025-09-16 07:41:26 - INFO - 2045262706 used CHOICE PARALLEL FUNC
2025-09-16 07:41:29 - INFO - 2045262706 used CHOICE CLASS FUNC and choice 8 классы
2025-09-16 07:41:44 - INFO - 2045262706 used START MESSAGE FUNC
2025-09-16 07:41:49 - ERROR - Infinity polling exception: ('Connection aborted.', RemoteDisconnected('Remote end closed connection without response'))
2025-09-16 07:41:49 - ERROR - Exception traceback:
Traceback (most recent call last):
  File "K:\Scedule_Bot_1.0\.venv\Lib\site-packages\urllib3\connectionpool.py", line 787, in urlopen
    response = self._make_request(
               ^^^^^^^^^^^^^^^^^^^
  File "K:\Scedule_Bot_1.0\.venv\Lib\site-packages\urllib3\connectionpool.py", line 534, in _make_request
    response = conn.getresponse()
               ^^^^^^^^^^^^^^^^^^
  File "K:\Scedule_Bot_1.0\.venv\Lib\site-packages\urllib3\connection.py", line 565, in getresponse
    httplib_response = super().getresponse()
                       ^^^^^^^^^^^^^^^^^^^^^
  File "C:\Users\kazak\AppData\Local\Programs\Python\Python312\Lib\http\client.py", line 1430, in getresponse
    response.begin()
  File "C:\Users\kazak\AppData\Local\Programs\Python\Python312\Lib\http\client.py", line 331, in begin
    version, status, reason = self._read_status()
                              ^^^^^^^^^^^^^^^^^^^
  File "C:\Users\kazak\AppData\Local\Programs\Python\Python312\Lib\http\client.py", line 300, in _read_status
    raise RemoteDisconnected("Remote end closed connection without"
http.client.RemoteDisconnected: Remote end closed connection without response

During handling of the above exception, another exception occurred:

Traceback (most recent call last):
  File "K:\Scedule_Bot_1.0\.venv\Lib\site-packages\requests\adapters.py", line 667, in send
    resp = conn.urlopen(
           ^^^^^^^^^^^^^
  File "K:\Scedule_Bot_1.0\.venv\Lib\site-packages\urllib3\connectionpool.py", line 841, in urlopen
    retries = retries.increment(
              ^^^^^^^^^^^^^^^^^^
  File "K:\Scedule_Bot_1.0\.venv\Lib\site-packages\urllib3\util\retry.py", line 474, in increment
    raise reraise(type(error), error, _stacktrace)
          ^^^^^^^^^^^^^^^^^^^^^^^^^^^^^^^^^^^^^^^^
  File "K:\Scedule_Bot_1.0\.venv\Lib\site-packages\urllib3\util\util.py", line 38, in reraise
    raise value.with_traceback(tb)
  File "K:\Scedule_Bot_1.0\.venv\Lib\site-packages\urllib3\connectionpool.py", line 787, in urlopen
    response = self._make_request(
               ^^^^^^^^^^^^^^^^^^^
  File "K:\Scedule_Bot_1.0\.venv\Lib\site-packages\urllib3\connectionpool.py", line 534, in _make_request
    response = conn.getresponse()
               ^^^^^^^^^^^^^^^^^^
  File "K:\Scedule_Bot_1.0\.venv\Lib\site-packages\urllib3\connection.py", line 565, in getresponse
    httplib_response = super().getresponse()
                       ^^^^^^^^^^^^^^^^^^^^^
  File "C:\Users\kazak\AppData\Local\Programs\Python\Python312\Lib\http\client.py", line 1430, in getresponse
    response.begin()
  File "C:\Users\kazak\AppData\Local\Programs\Python\Python312\Lib\http\client.py", line 331, in begin
    version, status, reason = self._read_status()
                              ^^^^^^^^^^^^^^^^^^^
  File "C:\Users\kazak\AppData\Local\Programs\Python\Python312\Lib\http\client.py", line 300, in _read_status
    raise RemoteDisconnected("Remote end closed connection without"
urllib3.exceptions.ProtocolError: ('Connection aborted.', RemoteDisconnected('Remote end closed connection without response'))

During handling of the above exception, another exception occurred:

Traceback (most recent call last):
  File "K:\Scedule_Bot_1.0\.venv\Lib\site-packages\telebot\__init__.py", line 1110, in infinity_polling
    self.polling(non_stop=True, timeout=timeout, long_polling_timeout=long_polling_timeout,
  File "K:\Scedule_Bot_1.0\.venv\Lib\site-packages\telebot\__init__.py", line 1198, in polling
    self.__threaded_polling(non_stop=non_stop, interval=interval, timeout=timeout, long_polling_timeout=long_polling_timeout,
  File "K:\Scedule_Bot_1.0\.venv\Lib\site-packages\telebot\__init__.py", line 1273, in __threaded_polling
    raise e
  File "K:\Scedule_Bot_1.0\.venv\Lib\site-packages\telebot\__init__.py", line 1235, in __threaded_polling
    self.worker_pool.raise_exceptions()
  File "K:\Scedule_Bot_1.0\.venv\Lib\site-packages\telebot\util.py", line 150, in raise_exceptions
    raise self.exception_info
  File "K:\Scedule_Bot_1.0\.venv\Lib\site-packages\telebot\util.py", line 93, in run
    task(*args, **kwargs)
  File "K:\Scedule_Bot_1.0\.venv\Lib\site-packages\telebot\__init__.py", line 9759, in _run_middlewares_and_handler
    result = handler['function'](message)
             ^^^^^^^^^^^^^^^^^^^^^^^^^^^^
  File "K:\Scedule_Bot_1.0\telegram_bot\main.py", line 231, in get_choice_class
    bot.send_message(message.from_user.id, CHOICE_CLASS_MESSAGE, reply_markup=markup_class)
  File "K:\Scedule_Bot_1.0\.venv\Lib\site-packages\telebot\__init__.py", line 1800, in send_message
    apihelper.send_message(
  File "K:\Scedule_Bot_1.0\.venv\Lib\site-packages\telebot\apihelper.py", line 275, in send_message
    return _make_request(token, method_url, params=payload, method='post')
           ^^^^^^^^^^^^^^^^^^^^^^^^^^^^^^^^^^^^^^^^^^^^^^^^^^^^^^^^^^^^^^^
  File "K:\Scedule_Bot_1.0\.venv\Lib\site-packages\telebot\apihelper.py", line 162, in _make_request
    result = _get_req_session().request(
             ^^^^^^^^^^^^^^^^^^^^^^^^^^^
  File "K:\Scedule_Bot_1.0\.venv\Lib\site-packages\requests\sessions.py", line 589, in request
    resp = self.send(prep, **send_kwargs)
           ^^^^^^^^^^^^^^^^^^^^^^^^^^^^^^
  File "K:\Scedule_Bot_1.0\.venv\Lib\site-packages\requests\sessions.py", line 703, in send
    r = adapter.send(request, **kwargs)
        ^^^^^^^^^^^^^^^^^^^^^^^^^^^^^^^
  File "K:\Scedule_Bot_1.0\.venv\Lib\site-packages\requests\adapters.py", line 682, in send
    raise ConnectionError(err, request=request)
requests.exceptions.ConnectionError: ('Connection aborted.', RemoteDisconnected('Remote end closed connection without response'))

2025-09-16 07:42:03 - INFO - 2045262706 used START MESSAGE FUNC
2025-09-16 07:42:06 - INFO - 2045262706 used CHOICE PARALLEL FUNC
2025-09-16 07:42:09 - INFO - 2045262706 used CHOICE CLASS FUNC and choice 8 классы
2025-09-16 07:42:13 - INFO - Getting data from server
2025-09-16 07:42:14 - INFO - Start schedule normalization
2025-09-16 07:42:14 - INFO - Schedule is the same. Cancel.
2025-09-16 07:42:14 - INFO - Data received from server
2025-09-16 07:42:17 - INFO - 2045262706 used SAVE CHOICE CLASS FUNC and choice 8К
2025-09-16 07:42:28 - INFO - 2045262706 used GET SCHEDULE FUNC and choice Понедельник
2025-09-16 07:42:31 - INFO - 2045262706 used GET SCHEDULE FUNC and choice Вторник
2025-09-16 07:46:33 - INFO - 321729372 used START MESSAGE FUNC
2025-09-16 07:46:52 - ERROR - Infinity polling exception: ('Connection aborted.', RemoteDisconnected('Remote end closed connection without response'))
2025-09-16 07:46:52 - ERROR - Exception traceback:
Traceback (most recent call last):
  File "K:\Scedule_Bot_1.0\.venv\Lib\site-packages\urllib3\connectionpool.py", line 787, in urlopen
    response = self._make_request(
               ^^^^^^^^^^^^^^^^^^^
  File "K:\Scedule_Bot_1.0\.venv\Lib\site-packages\urllib3\connectionpool.py", line 534, in _make_request
    response = conn.getresponse()
               ^^^^^^^^^^^^^^^^^^
  File "K:\Scedule_Bot_1.0\.venv\Lib\site-packages\urllib3\connection.py", line 565, in getresponse
    httplib_response = super().getresponse()
                       ^^^^^^^^^^^^^^^^^^^^^
  File "C:\Users\kazak\AppData\Local\Programs\Python\Python312\Lib\http\client.py", line 1430, in getresponse
    response.begin()
  File "C:\Users\kazak\AppData\Local\Programs\Python\Python312\Lib\http\client.py", line 331, in begin
    version, status, reason = self._read_status()
                              ^^^^^^^^^^^^^^^^^^^
  File "C:\Users\kazak\AppData\Local\Programs\Python\Python312\Lib\http\client.py", line 300, in _read_status
    raise RemoteDisconnected("Remote end closed connection without"
http.client.RemoteDisconnected: Remote end closed connection without response

During handling of the above exception, another exception occurred:

Traceback (most recent call last):
  File "K:\Scedule_Bot_1.0\.venv\Lib\site-packages\requests\adapters.py", line 667, in send
    resp = conn.urlopen(
           ^^^^^^^^^^^^^
  File "K:\Scedule_Bot_1.0\.venv\Lib\site-packages\urllib3\connectionpool.py", line 841, in urlopen
    retries = retries.increment(
              ^^^^^^^^^^^^^^^^^^
  File "K:\Scedule_Bot_1.0\.venv\Lib\site-packages\urllib3\util\retry.py", line 474, in increment
    raise reraise(type(error), error, _stacktrace)
          ^^^^^^^^^^^^^^^^^^^^^^^^^^^^^^^^^^^^^^^^
  File "K:\Scedule_Bot_1.0\.venv\Lib\site-packages\urllib3\util\util.py", line 38, in reraise
    raise value.with_traceback(tb)
  File "K:\Scedule_Bot_1.0\.venv\Lib\site-packages\urllib3\connectionpool.py", line 787, in urlopen
    response = self._make_request(
               ^^^^^^^^^^^^^^^^^^^
  File "K:\Scedule_Bot_1.0\.venv\Lib\site-packages\urllib3\connectionpool.py", line 534, in _make_request
    response = conn.getresponse()
               ^^^^^^^^^^^^^^^^^^
  File "K:\Scedule_Bot_1.0\.venv\Lib\site-packages\urllib3\connection.py", line 565, in getresponse
    httplib_response = super().getresponse()
                       ^^^^^^^^^^^^^^^^^^^^^
  File "C:\Users\kazak\AppData\Local\Programs\Python\Python312\Lib\http\client.py", line 1430, in getresponse
    response.begin()
  File "C:\Users\kazak\AppData\Local\Programs\Python\Python312\Lib\http\client.py", line 331, in begin
    version, status, reason = self._read_status()
                              ^^^^^^^^^^^^^^^^^^^
  File "C:\Users\kazak\AppData\Local\Programs\Python\Python312\Lib\http\client.py", line 300, in _read_status
    raise RemoteDisconnected("Remote end closed connection without"
urllib3.exceptions.ProtocolError: ('Connection aborted.', RemoteDisconnected('Remote end closed connection without response'))

During handling of the above exception, another exception occurred:

Traceback (most recent call last):
  File "K:\Scedule_Bot_1.0\.venv\Lib\site-packages\telebot\__init__.py", line 1110, in infinity_polling
    self.polling(non_stop=True, timeout=timeout, long_polling_timeout=long_polling_timeout,
  File "K:\Scedule_Bot_1.0\.venv\Lib\site-packages\telebot\__init__.py", line 1198, in polling
    self.__threaded_polling(non_stop=non_stop, interval=interval, timeout=timeout, long_polling_timeout=long_polling_timeout,
  File "K:\Scedule_Bot_1.0\.venv\Lib\site-packages\telebot\__init__.py", line 1273, in __threaded_polling
    raise e
  File "K:\Scedule_Bot_1.0\.venv\Lib\site-packages\telebot\__init__.py", line 1235, in __threaded_polling
    self.worker_pool.raise_exceptions()
  File "K:\Scedule_Bot_1.0\.venv\Lib\site-packages\telebot\util.py", line 150, in raise_exceptions
    raise self.exception_info
  File "K:\Scedule_Bot_1.0\.venv\Lib\site-packages\telebot\util.py", line 93, in run
    task(*args, **kwargs)
  File "K:\Scedule_Bot_1.0\.venv\Lib\site-packages\telebot\__init__.py", line 9759, in _run_middlewares_and_handler
    result = handler['function'](message)
             ^^^^^^^^^^^^^^^^^^^^^^^^^^^^
  File "K:\Scedule_Bot_1.0\telegram_bot\main.py", line 81, in start_func
    bot.send_message(user_data["tg_id"], START_MESSAGE.format(user_first_name=user_data["tg_first_name"]), reply_markup=markup_menu_buttons)
  File "K:\Scedule_Bot_1.0\.venv\Lib\site-packages\telebot\__init__.py", line 1800, in send_message
    apihelper.send_message(
  File "K:\Scedule_Bot_1.0\.venv\Lib\site-packages\telebot\apihelper.py", line 275, in send_message
    return _make_request(token, method_url, params=payload, method='post')
           ^^^^^^^^^^^^^^^^^^^^^^^^^^^^^^^^^^^^^^^^^^^^^^^^^^^^^^^^^^^^^^^
  File "K:\Scedule_Bot_1.0\.venv\Lib\site-packages\telebot\apihelper.py", line 162, in _make_request
    result = _get_req_session().request(
             ^^^^^^^^^^^^^^^^^^^^^^^^^^^
  File "K:\Scedule_Bot_1.0\.venv\Lib\site-packages\requests\sessions.py", line 589, in request
    resp = self.send(prep, **send_kwargs)
           ^^^^^^^^^^^^^^^^^^^^^^^^^^^^^^
  File "K:\Scedule_Bot_1.0\.venv\Lib\site-packages\requests\sessions.py", line 703, in send
    r = adapter.send(request, **kwargs)
        ^^^^^^^^^^^^^^^^^^^^^^^^^^^^^^^
  File "K:\Scedule_Bot_1.0\.venv\Lib\site-packages\requests\adapters.py", line 682, in send
    raise ConnectionError(err, request=request)
requests.exceptions.ConnectionError: ('Connection aborted.', RemoteDisconnected('Remote end closed connection without response'))

2025-09-16 07:46:58 - INFO - 321729372 used START MESSAGE FUNC
2025-09-16 07:47:02 - INFO - 321729372 used CHOICE PARALLEL FUNC
2025-09-16 07:47:05 - INFO - 321729372 used CHOICE CLASS FUNC and choice 9 классы
2025-09-16 07:47:09 - INFO - 321729372 used SAVE CHOICE CLASS FUNC and choice 9Д
2025-09-16 07:47:14 - INFO - Getting data from server
2025-09-16 07:47:15 - INFO - 321729372 used GET SCHEDULE FUNC and choice Пятница
2025-09-16 07:47:16 - INFO - Start schedule normalization
2025-09-16 07:47:16 - INFO - Schedule normalized
2025-09-16 07:47:16 - INFO - Data received from server
2025-09-16 07:47:22 - INFO - 321729372 used GET SCHEDULE FUNC and choice Вторник
2025-09-16 07:47:25 - INFO - 321729372 used GET SCHEDULE FUNC and choice Пятница
2025-09-16 07:47:52 - INFO - 321729372 used GET SCHEDULE FUNC and choice Понедельник
2025-09-16 07:47:58 - INFO - 321729372 used START MESSAGE FUNC
2025-09-16 07:48:04 - INFO - 321729372 used GET HELP FUNC
2025-09-16 07:48:35 - INFO - 321729372 used GET HELP FUNC 2
2025-09-16 07:52:16 - INFO - Getting data from server
2025-09-16 07:52:17 - INFO - Start schedule normalization
2025-09-16 07:52:17 - INFO - Schedule is the same. Cancel.
2025-09-16 07:52:17 - INFO - Data received from server
2025-09-16 07:57:17 - INFO - Getting data from server
2025-09-16 07:57:19 - INFO - Start schedule normalization
2025-09-16 07:57:19 - INFO - Schedule is the same. Cancel.
2025-09-16 07:57:19 - INFO - Data received from server
2025-09-16 08:02:19 - INFO - Getting data from server
2025-09-16 08:02:21 - INFO - Start schedule normalization
2025-09-16 08:02:21 - INFO - Schedule is the same. Cancel.
2025-09-16 08:02:21 - INFO - Data received from server
2025-09-16 08:07:21 - INFO - Getting data from server
2025-09-16 08:07:22 - INFO - Start schedule normalization
2025-09-16 08:07:22 - INFO - Schedule is the same. Cancel.
2025-09-16 08:07:22 - INFO - Data received from server
2025-09-16 08:09:33 - INFO - 6983370282 used GET SCHEDULE FUNC and choice Среда
2025-09-16 08:12:22 - INFO - Getting data from server
2025-09-16 08:12:24 - INFO - Start schedule normalization
2025-09-16 08:12:24 - INFO - Schedule is the same. Cancel.
2025-09-16 08:12:24 - INFO - Data received from server
2025-09-16 08:17:24 - INFO - Getting data from server
2025-09-16 08:17:25 - INFO - Start schedule normalization
2025-09-16 08:17:25 - INFO - Schedule is the same. Cancel.
2025-09-16 08:17:25 - INFO - Data received from server
2025-09-16 08:22:25 - INFO - Getting data from server
2025-09-16 08:22:27 - INFO - Start schedule normalization
2025-09-16 08:22:27 - INFO - Schedule is the same. Cancel.
2025-09-16 08:22:27 - INFO - Data received from server
2025-09-16 08:27:27 - INFO - Getting data from server
2025-09-16 08:27:28 - INFO - Start schedule normalization
2025-09-16 08:27:28 - INFO - Schedule is the same. Cancel.
2025-09-16 08:27:28 - INFO - Data received from server
2025-09-16 08:32:28 - INFO - Getting data from server
2025-09-16 08:32:30 - INFO - Start schedule normalization
2025-09-16 08:32:30 - INFO - Schedule is the same. Cancel.
2025-09-16 08:32:30 - INFO - Data received from server
2025-09-16 08:32:35 - INFO - 6983370282 used GET SCHEDULE FUNC and choice Вторник
2025-09-16 08:37:30 - INFO - Getting data from server
2025-09-16 08:37:31 - INFO - Start schedule normalization
2025-09-16 08:37:31 - INFO - Schedule is the same. Cancel.
2025-09-16 08:37:31 - INFO - Data received from server
2025-09-16 08:42:31 - INFO - Getting data from server
2025-09-16 08:42:33 - INFO - Start schedule normalization
2025-09-16 08:42:33 - INFO - Schedule is the same. Cancel.
2025-09-16 08:42:33 - INFO - Data received from server
2025-09-16 08:44:10 - INFO - 1220581221 used START MESSAGE FUNC
2025-09-16 08:44:12 - INFO - 1220581221 used CHOICE PARALLEL FUNC
2025-09-16 08:44:14 - INFO - 1220581221 used CHOICE CLASS FUNC and choice 8 классы
2025-09-16 08:44:16 - INFO - 1220581221 used SAVE CHOICE CLASS FUNC and choice 8К
2025-09-16 08:44:21 - INFO - 1220581221 used GET SCHEDULE FUNC and choice Вторник
2025-09-16 08:46:55 - INFO - 6983370282 used GET SCHEDULE FUNC and choice Среда
2025-09-16 08:47:33 - INFO - Getting data from server
2025-09-16 08:47:34 - INFO - Start schedule normalization
2025-09-16 08:47:35 - INFO - Schedule is the same. Cancel.
2025-09-16 08:47:35 - INFO - Data received from server
2025-09-16 08:52:35 - INFO - Getting data from server
2025-09-16 08:52:36 - INFO - Start schedule normalization
2025-09-16 08:52:36 - INFO - Schedule normalized
2025-09-16 08:52:36 - INFO - Data received from server
2025-09-16 08:57:36 - INFO - Getting data from server
2025-09-16 08:57:38 - INFO - Start schedule normalization
2025-09-16 08:57:38 - INFO - Schedule is the same. Cancel.
2025-09-16 08:57:38 - INFO - Data received from server
2025-09-16 09:02:38 - INFO - Getting data from server
2025-09-16 09:02:39 - INFO - Start schedule normalization
2025-09-16 09:02:39 - INFO - Schedule is the same. Cancel.
2025-09-16 09:02:39 - INFO - Data received from server
2025-09-16 09:07:39 - INFO - Getting data from server
2025-09-16 09:07:41 - INFO - Start schedule normalization
2025-09-16 09:07:41 - INFO - Schedule is the same. Cancel.
2025-09-16 09:07:41 - INFO - Data received from server
2025-09-16 09:12:41 - INFO - Getting data from server
2025-09-16 09:12:42 - INFO - Start schedule normalization
2025-09-16 09:12:42 - INFO - Schedule is the same. Cancel.
2025-09-16 09:12:42 - INFO - Data received from server
2025-09-16 09:17:42 - INFO - Getting data from server
2025-09-16 09:17:44 - INFO - Start schedule normalization
2025-09-16 09:17:44 - INFO - Schedule is the same. Cancel.
2025-09-16 09:17:44 - INFO - Data received from server
2025-09-16 09:22:44 - INFO - Getting data from server
2025-09-16 09:22:46 - INFO - Start schedule normalization
2025-09-16 09:22:46 - INFO - Schedule is the same. Cancel.
2025-09-16 09:22:46 - INFO - Data received from server
2025-09-16 09:27:46 - INFO - Getting data from server
2025-09-16 09:27:47 - INFO - Start schedule normalization
2025-09-16 09:27:47 - INFO - Schedule is the same. Cancel.
2025-09-16 09:27:47 - INFO - Data received from server
2025-09-16 09:32:47 - INFO - Getting data from server
2025-09-16 09:32:49 - INFO - Start schedule normalization
2025-09-16 09:32:49 - INFO - Schedule is the same. Cancel.
2025-09-16 09:32:49 - INFO - Data received from server
2025-09-16 09:37:49 - INFO - Getting data from server
2025-09-16 09:37:50 - INFO - Start schedule normalization
2025-09-16 09:37:50 - INFO - Schedule is the same. Cancel.
2025-09-16 09:37:50 - INFO - Data received from server
2025-09-16 09:38:32 - INFO - 6983370282 used UPD FUNC
2025-09-16 09:38:32 - INFO - Getting data from server
2025-09-16 09:38:33 - INFO - Start schedule normalization
2025-09-16 09:38:33 - INFO - Schedule is the same. Cancel.
2025-09-16 09:38:33 - INFO - Data received from server
2025-09-16 09:38:37 - INFO - 6983370282 used GET SCHEDULE FUNC and choice Пятница
2025-09-16 09:38:43 - INFO - 6983370282 used GET SCHEDULE FUNC and choice Вторник
2025-09-16 09:42:50 - INFO - Getting data from server
2025-09-16 09:42:52 - INFO - Start schedule normalization
2025-09-16 09:42:52 - INFO - Schedule is the same. Cancel.
2025-09-16 09:42:52 - INFO - Data received from server
2025-09-16 09:47:52 - INFO - Getting data from server
2025-09-16 09:47:53 - INFO - Start schedule normalization
2025-09-16 09:47:53 - INFO - Schedule is the same. Cancel.
2025-09-16 09:47:53 - INFO - Data received from server
2025-09-16 09:52:53 - INFO - Getting data from server
2025-09-16 09:52:55 - INFO - Start schedule normalization
2025-09-16 09:52:55 - INFO - Schedule is the same. Cancel.
2025-09-16 09:52:55 - INFO - Data received from server
2025-09-16 09:54:22 - INFO - 6983370282 used GET SCHEDULE FUNC and choice Среда
2025-09-16 09:57:55 - INFO - Getting data from server
2025-09-16 09:57:56 - INFO - Start schedule normalization
2025-09-16 09:57:56 - INFO - Schedule is the same. Cancel.
2025-09-16 09:57:56 - INFO - Data received from server
2025-09-16 09:58:48 - INFO - 948334132 used START MESSAGE FUNC
2025-09-16 09:59:07 - ERROR - Infinity polling exception: ('Connection aborted.', RemoteDisconnected('Remote end closed connection without response'))
2025-09-16 09:59:07 - ERROR - Exception traceback:
Traceback (most recent call last):
  File "K:\Scedule_Bot_1.0\.venv\Lib\site-packages\urllib3\connectionpool.py", line 787, in urlopen
    response = self._make_request(
               ^^^^^^^^^^^^^^^^^^^
  File "K:\Scedule_Bot_1.0\.venv\Lib\site-packages\urllib3\connectionpool.py", line 534, in _make_request
    response = conn.getresponse()
               ^^^^^^^^^^^^^^^^^^
  File "K:\Scedule_Bot_1.0\.venv\Lib\site-packages\urllib3\connection.py", line 565, in getresponse
    httplib_response = super().getresponse()
                       ^^^^^^^^^^^^^^^^^^^^^
  File "C:\Users\kazak\AppData\Local\Programs\Python\Python312\Lib\http\client.py", line 1430, in getresponse
    response.begin()
  File "C:\Users\kazak\AppData\Local\Programs\Python\Python312\Lib\http\client.py", line 331, in begin
    version, status, reason = self._read_status()
                              ^^^^^^^^^^^^^^^^^^^
  File "C:\Users\kazak\AppData\Local\Programs\Python\Python312\Lib\http\client.py", line 300, in _read_status
    raise RemoteDisconnected("Remote end closed connection without"
http.client.RemoteDisconnected: Remote end closed connection without response

During handling of the above exception, another exception occurred:

Traceback (most recent call last):
  File "K:\Scedule_Bot_1.0\.venv\Lib\site-packages\requests\adapters.py", line 667, in send
    resp = conn.urlopen(
           ^^^^^^^^^^^^^
  File "K:\Scedule_Bot_1.0\.venv\Lib\site-packages\urllib3\connectionpool.py", line 841, in urlopen
    retries = retries.increment(
              ^^^^^^^^^^^^^^^^^^
  File "K:\Scedule_Bot_1.0\.venv\Lib\site-packages\urllib3\util\retry.py", line 474, in increment
    raise reraise(type(error), error, _stacktrace)
          ^^^^^^^^^^^^^^^^^^^^^^^^^^^^^^^^^^^^^^^^
  File "K:\Scedule_Bot_1.0\.venv\Lib\site-packages\urllib3\util\util.py", line 38, in reraise
    raise value.with_traceback(tb)
  File "K:\Scedule_Bot_1.0\.venv\Lib\site-packages\urllib3\connectionpool.py", line 787, in urlopen
    response = self._make_request(
               ^^^^^^^^^^^^^^^^^^^
  File "K:\Scedule_Bot_1.0\.venv\Lib\site-packages\urllib3\connectionpool.py", line 534, in _make_request
    response = conn.getresponse()
               ^^^^^^^^^^^^^^^^^^
  File "K:\Scedule_Bot_1.0\.venv\Lib\site-packages\urllib3\connection.py", line 565, in getresponse
    httplib_response = super().getresponse()
                       ^^^^^^^^^^^^^^^^^^^^^
  File "C:\Users\kazak\AppData\Local\Programs\Python\Python312\Lib\http\client.py", line 1430, in getresponse
    response.begin()
  File "C:\Users\kazak\AppData\Local\Programs\Python\Python312\Lib\http\client.py", line 331, in begin
    version, status, reason = self._read_status()
                              ^^^^^^^^^^^^^^^^^^^
  File "C:\Users\kazak\AppData\Local\Programs\Python\Python312\Lib\http\client.py", line 300, in _read_status
    raise RemoteDisconnected("Remote end closed connection without"
urllib3.exceptions.ProtocolError: ('Connection aborted.', RemoteDisconnected('Remote end closed connection without response'))

During handling of the above exception, another exception occurred:

Traceback (most recent call last):
  File "K:\Scedule_Bot_1.0\.venv\Lib\site-packages\telebot\__init__.py", line 1110, in infinity_polling
    self.polling(non_stop=True, timeout=timeout, long_polling_timeout=long_polling_timeout,
  File "K:\Scedule_Bot_1.0\.venv\Lib\site-packages\telebot\__init__.py", line 1198, in polling
    self.__threaded_polling(non_stop=non_stop, interval=interval, timeout=timeout, long_polling_timeout=long_polling_timeout,
  File "K:\Scedule_Bot_1.0\.venv\Lib\site-packages\telebot\__init__.py", line 1273, in __threaded_polling
    raise e
  File "K:\Scedule_Bot_1.0\.venv\Lib\site-packages\telebot\__init__.py", line 1235, in __threaded_polling
    self.worker_pool.raise_exceptions()
  File "K:\Scedule_Bot_1.0\.venv\Lib\site-packages\telebot\util.py", line 150, in raise_exceptions
    raise self.exception_info
  File "K:\Scedule_Bot_1.0\.venv\Lib\site-packages\telebot\util.py", line 93, in run
    task(*args, **kwargs)
  File "K:\Scedule_Bot_1.0\.venv\Lib\site-packages\telebot\__init__.py", line 9759, in _run_middlewares_and_handler
    result = handler['function'](message)
             ^^^^^^^^^^^^^^^^^^^^^^^^^^^^
  File "K:\Scedule_Bot_1.0\telegram_bot\main.py", line 81, in start_func
    bot.send_message(user_data["tg_id"], START_MESSAGE.format(user_first_name=user_data["tg_first_name"]), reply_markup=markup_menu_buttons)
  File "K:\Scedule_Bot_1.0\.venv\Lib\site-packages\telebot\__init__.py", line 1800, in send_message
    apihelper.send_message(
  File "K:\Scedule_Bot_1.0\.venv\Lib\site-packages\telebot\apihelper.py", line 275, in send_message
    return _make_request(token, method_url, params=payload, method='post')
           ^^^^^^^^^^^^^^^^^^^^^^^^^^^^^^^^^^^^^^^^^^^^^^^^^^^^^^^^^^^^^^^
  File "K:\Scedule_Bot_1.0\.venv\Lib\site-packages\telebot\apihelper.py", line 162, in _make_request
    result = _get_req_session().request(
             ^^^^^^^^^^^^^^^^^^^^^^^^^^^
  File "K:\Scedule_Bot_1.0\.venv\Lib\site-packages\requests\sessions.py", line 589, in request
    resp = self.send(prep, **send_kwargs)
           ^^^^^^^^^^^^^^^^^^^^^^^^^^^^^^
  File "K:\Scedule_Bot_1.0\.venv\Lib\site-packages\requests\sessions.py", line 703, in send
    r = adapter.send(request, **kwargs)
        ^^^^^^^^^^^^^^^^^^^^^^^^^^^^^^^
  File "K:\Scedule_Bot_1.0\.venv\Lib\site-packages\requests\adapters.py", line 682, in send
    raise ConnectionError(err, request=request)
requests.exceptions.ConnectionError: ('Connection aborted.', RemoteDisconnected('Remote end closed connection without response'))

2025-09-16 10:02:56 - INFO - Getting data from server
2025-09-16 10:02:58 - INFO - Start schedule normalization
2025-09-16 10:02:58 - INFO - Schedule is the same. Cancel.
2025-09-16 10:02:58 - INFO - Data received from server
2025-09-16 10:07:58 - INFO - Getting data from server
2025-09-16 10:07:59 - INFO - Start schedule normalization
2025-09-16 10:07:59 - INFO - Schedule is the same. Cancel.
2025-09-16 10:07:59 - INFO - Data received from server
2025-09-16 10:12:59 - INFO - Getting data from server
2025-09-16 10:13:01 - INFO - Start schedule normalization
2025-09-16 10:13:01 - INFO - Schedule is the same. Cancel.
2025-09-16 10:13:01 - INFO - Data received from server
2025-09-16 10:16:59 - INFO - 6983370282 used GET SCHEDULE FUNC and choice Пятница
2025-09-16 10:17:05 - INFO - 6983370282 used GET SCHEDULE FUNC and choice Четверг
2025-09-16 10:18:01 - INFO - Getting data from server
2025-09-16 10:18:02 - INFO - 6983370282 used CHOICE PARALLEL FUNC
2025-09-16 10:18:02 - INFO - Start schedule normalization
2025-09-16 10:18:02 - INFO - Schedule is the same. Cancel.
2025-09-16 10:18:02 - INFO - Data received from server
2025-09-16 10:18:05 - INFO - 6983370282 used CHOICE CLASS FUNC and choice 5 классы
2025-09-16 10:18:07 - INFO - 6983370282 used SAVE CHOICE CLASS FUNC and choice 5К
2025-09-16 10:18:08 - INFO - 6983370282 used GET SCHEDULE FUNC and choice Понедельник
2025-09-16 10:18:10 - INFO - 6983370282 used GET SCHEDULE FUNC and choice Вторник
2025-09-16 10:18:14 - INFO - 6983370282 used CHOICE PARALLEL FUNC
2025-09-16 10:18:16 - INFO - 6983370282 used CHOICE CLASS FUNC and choice 8 классы
2025-09-16 10:18:16 - INFO - 6983370282 used SAVE CHOICE CLASS FUNC and choice 8К
2025-09-16 10:18:21 - INFO - 6983370282 used GET SCHEDULE FUNC and choice Вторник
2025-09-16 10:23:02 - INFO - Getting data from server
2025-09-16 10:23:04 - INFO - Start schedule normalization
2025-09-16 10:23:04 - INFO - Schedule is the same. Cancel.
2025-09-16 10:23:04 - INFO - Data received from server
2025-09-16 10:28:04 - INFO - Getting data from server
2025-09-16 10:28:05 - INFO - Start schedule normalization
2025-09-16 10:28:05 - INFO - Schedule is the same. Cancel.
2025-09-16 10:28:05 - INFO - Data received from server
2025-09-16 10:33:02 - INFO - 6983370282 used HELP MESSAGE FUNC
2025-09-16 10:33:05 - INFO - Getting data from server
2025-09-16 10:33:07 - INFO - Start schedule normalization
2025-09-16 10:33:07 - INFO - Schedule is the same. Cancel.
2025-09-16 10:33:07 - INFO - Data received from server
2025-09-16 10:33:20 - INFO - 6983370282 used START MESSAGE FUNC
2025-09-16 10:33:21 - INFO - 6983370282 used CHOICE PARALLEL FUNC
2025-09-16 10:33:23 - INFO - 6983370282 used CHOICE CLASS FUNC and choice 8 классы
2025-09-16 10:33:24 - INFO - 6983370282 used SAVE CHOICE CLASS FUNC and choice 8К
2025-09-16 10:34:52 - INFO - 7979171504 used START MESSAGE FUNC
2025-09-16 10:34:58 - INFO - 7979171504 used CHOICE PARALLEL FUNC
2025-09-16 10:34:59 - INFO - 6056126903 used START MESSAGE FUNC
2025-09-16 10:35:01 - INFO - 6056126903 used CHOICE PARALLEL FUNC
2025-09-16 10:35:04 - INFO - 6056126903 used CHOICE CLASS FUNC and choice 8 классы
2025-09-16 10:35:08 - INFO - 6056126903 used SAVE CHOICE CLASS FUNC and choice 8К
2025-09-16 10:35:16 - INFO - 6056126903 used GET SCHEDULE FUNC and choice Среда
2025-09-16 10:38:07 - INFO - Getting data from server
2025-09-16 10:38:09 - INFO - Start schedule normalization
2025-09-16 10:38:09 - INFO - Schedule is the same. Cancel.
2025-09-16 10:38:09 - INFO - Data received from server
2025-09-16 10:39:19 - INFO - 6983370282 used START MESSAGE FUNC
2025-09-16 10:39:24 - INFO - 6983370282 used START MESSAGE FUNC
2025-09-16 10:39:38 - ERROR - Infinity polling exception: ('Connection aborted.', RemoteDisconnected('Remote end closed connection without response'))
2025-09-16 10:39:38 - ERROR - Exception traceback:
Traceback (most recent call last):
  File "K:\Scedule_Bot_1.0\.venv\Lib\site-packages\urllib3\connectionpool.py", line 787, in urlopen
    response = self._make_request(
               ^^^^^^^^^^^^^^^^^^^
  File "K:\Scedule_Bot_1.0\.venv\Lib\site-packages\urllib3\connectionpool.py", line 534, in _make_request
    response = conn.getresponse()
               ^^^^^^^^^^^^^^^^^^
  File "K:\Scedule_Bot_1.0\.venv\Lib\site-packages\urllib3\connection.py", line 565, in getresponse
    httplib_response = super().getresponse()
                       ^^^^^^^^^^^^^^^^^^^^^
  File "C:\Users\kazak\AppData\Local\Programs\Python\Python312\Lib\http\client.py", line 1430, in getresponse
    response.begin()
  File "C:\Users\kazak\AppData\Local\Programs\Python\Python312\Lib\http\client.py", line 331, in begin
    version, status, reason = self._read_status()
                              ^^^^^^^^^^^^^^^^^^^
  File "C:\Users\kazak\AppData\Local\Programs\Python\Python312\Lib\http\client.py", line 300, in _read_status
    raise RemoteDisconnected("Remote end closed connection without"
http.client.RemoteDisconnected: Remote end closed connection without response

During handling of the above exception, another exception occurred:

Traceback (most recent call last):
  File "K:\Scedule_Bot_1.0\.venv\Lib\site-packages\requests\adapters.py", line 667, in send
    resp = conn.urlopen(
           ^^^^^^^^^^^^^
  File "K:\Scedule_Bot_1.0\.venv\Lib\site-packages\urllib3\connectionpool.py", line 841, in urlopen
    retries = retries.increment(
              ^^^^^^^^^^^^^^^^^^
  File "K:\Scedule_Bot_1.0\.venv\Lib\site-packages\urllib3\util\retry.py", line 474, in increment
    raise reraise(type(error), error, _stacktrace)
          ^^^^^^^^^^^^^^^^^^^^^^^^^^^^^^^^^^^^^^^^
  File "K:\Scedule_Bot_1.0\.venv\Lib\site-packages\urllib3\util\util.py", line 38, in reraise
    raise value.with_traceback(tb)
  File "K:\Scedule_Bot_1.0\.venv\Lib\site-packages\urllib3\connectionpool.py", line 787, in urlopen
    response = self._make_request(
               ^^^^^^^^^^^^^^^^^^^
  File "K:\Scedule_Bot_1.0\.venv\Lib\site-packages\urllib3\connectionpool.py", line 534, in _make_request
    response = conn.getresponse()
               ^^^^^^^^^^^^^^^^^^
  File "K:\Scedule_Bot_1.0\.venv\Lib\site-packages\urllib3\connection.py", line 565, in getresponse
    httplib_response = super().getresponse()
                       ^^^^^^^^^^^^^^^^^^^^^
  File "C:\Users\kazak\AppData\Local\Programs\Python\Python312\Lib\http\client.py", line 1430, in getresponse
    response.begin()
  File "C:\Users\kazak\AppData\Local\Programs\Python\Python312\Lib\http\client.py", line 331, in begin
    version, status, reason = self._read_status()
                              ^^^^^^^^^^^^^^^^^^^
  File "C:\Users\kazak\AppData\Local\Programs\Python\Python312\Lib\http\client.py", line 300, in _read_status
    raise RemoteDisconnected("Remote end closed connection without"
urllib3.exceptions.ProtocolError: ('Connection aborted.', RemoteDisconnected('Remote end closed connection without response'))

During handling of the above exception, another exception occurred:

Traceback (most recent call last):
  File "K:\Scedule_Bot_1.0\.venv\Lib\site-packages\telebot\__init__.py", line 1110, in infinity_polling
    self.polling(non_stop=True, timeout=timeout, long_polling_timeout=long_polling_timeout,
  File "K:\Scedule_Bot_1.0\.venv\Lib\site-packages\telebot\__init__.py", line 1198, in polling
    self.__threaded_polling(non_stop=non_stop, interval=interval, timeout=timeout, long_polling_timeout=long_polling_timeout,
  File "K:\Scedule_Bot_1.0\.venv\Lib\site-packages\telebot\__init__.py", line 1273, in __threaded_polling
    raise e
  File "K:\Scedule_Bot_1.0\.venv\Lib\site-packages\telebot\__init__.py", line 1235, in __threaded_polling
    self.worker_pool.raise_exceptions()
  File "K:\Scedule_Bot_1.0\.venv\Lib\site-packages\telebot\util.py", line 150, in raise_exceptions
    raise self.exception_info
  File "K:\Scedule_Bot_1.0\.venv\Lib\site-packages\telebot\util.py", line 93, in run
    task(*args, **kwargs)
  File "K:\Scedule_Bot_1.0\.venv\Lib\site-packages\telebot\__init__.py", line 9759, in _run_middlewares_and_handler
    result = handler['function'](message)
             ^^^^^^^^^^^^^^^^^^^^^^^^^^^^
  File "K:\Scedule_Bot_1.0\telegram_bot\main.py", line 81, in start_func
    bot.send_message(user_data["tg_id"], START_MESSAGE.format(user_first_name=user_data["tg_first_name"]), reply_markup=markup_menu_buttons)
  File "K:\Scedule_Bot_1.0\.venv\Lib\site-packages\telebot\__init__.py", line 1800, in send_message
    apihelper.send_message(
  File "K:\Scedule_Bot_1.0\.venv\Lib\site-packages\telebot\apihelper.py", line 275, in send_message
    return _make_request(token, method_url, params=payload, method='post')
           ^^^^^^^^^^^^^^^^^^^^^^^^^^^^^^^^^^^^^^^^^^^^^^^^^^^^^^^^^^^^^^^
  File "K:\Scedule_Bot_1.0\.venv\Lib\site-packages\telebot\apihelper.py", line 162, in _make_request
    result = _get_req_session().request(
             ^^^^^^^^^^^^^^^^^^^^^^^^^^^
  File "K:\Scedule_Bot_1.0\.venv\Lib\site-packages\requests\sessions.py", line 589, in request
    resp = self.send(prep, **send_kwargs)
           ^^^^^^^^^^^^^^^^^^^^^^^^^^^^^^
  File "K:\Scedule_Bot_1.0\.venv\Lib\site-packages\requests\sessions.py", line 703, in send
    r = adapter.send(request, **kwargs)
        ^^^^^^^^^^^^^^^^^^^^^^^^^^^^^^^
  File "K:\Scedule_Bot_1.0\.venv\Lib\site-packages\requests\adapters.py", line 682, in send
    raise ConnectionError(err, request=request)
requests.exceptions.ConnectionError: ('Connection aborted.', RemoteDisconnected('Remote end closed connection without response'))

2025-09-16 10:39:38 - INFO - 6983370282 used HELP MESSAGE FUNC
2025-09-16 10:39:39 - INFO - 6983370282 used GET HELP FUNC 2
2025-09-16 10:39:43 - ERROR - Infinity polling exception: ('Connection aborted.', RemoteDisconnected('Remote end closed connection without response'))
2025-09-16 10:39:43 - ERROR - Exception traceback:
Traceback (most recent call last):
  File "K:\Scedule_Bot_1.0\.venv\Lib\site-packages\urllib3\connectionpool.py", line 787, in urlopen
    response = self._make_request(
               ^^^^^^^^^^^^^^^^^^^
  File "K:\Scedule_Bot_1.0\.venv\Lib\site-packages\urllib3\connectionpool.py", line 534, in _make_request
    response = conn.getresponse()
               ^^^^^^^^^^^^^^^^^^
  File "K:\Scedule_Bot_1.0\.venv\Lib\site-packages\urllib3\connection.py", line 565, in getresponse
    httplib_response = super().getresponse()
                       ^^^^^^^^^^^^^^^^^^^^^
  File "C:\Users\kazak\AppData\Local\Programs\Python\Python312\Lib\http\client.py", line 1430, in getresponse
    response.begin()
  File "C:\Users\kazak\AppData\Local\Programs\Python\Python312\Lib\http\client.py", line 331, in begin
    version, status, reason = self._read_status()
                              ^^^^^^^^^^^^^^^^^^^
  File "C:\Users\kazak\AppData\Local\Programs\Python\Python312\Lib\http\client.py", line 300, in _read_status
    raise RemoteDisconnected("Remote end closed connection without"
http.client.RemoteDisconnected: Remote end closed connection without response

During handling of the above exception, another exception occurred:

Traceback (most recent call last):
  File "K:\Scedule_Bot_1.0\.venv\Lib\site-packages\requests\adapters.py", line 667, in send
    resp = conn.urlopen(
           ^^^^^^^^^^^^^
  File "K:\Scedule_Bot_1.0\.venv\Lib\site-packages\urllib3\connectionpool.py", line 841, in urlopen
    retries = retries.increment(
              ^^^^^^^^^^^^^^^^^^
  File "K:\Scedule_Bot_1.0\.venv\Lib\site-packages\urllib3\util\retry.py", line 474, in increment
    raise reraise(type(error), error, _stacktrace)
          ^^^^^^^^^^^^^^^^^^^^^^^^^^^^^^^^^^^^^^^^
  File "K:\Scedule_Bot_1.0\.venv\Lib\site-packages\urllib3\util\util.py", line 38, in reraise
    raise value.with_traceback(tb)
  File "K:\Scedule_Bot_1.0\.venv\Lib\site-packages\urllib3\connectionpool.py", line 787, in urlopen
    response = self._make_request(
               ^^^^^^^^^^^^^^^^^^^
  File "K:\Scedule_Bot_1.0\.venv\Lib\site-packages\urllib3\connectionpool.py", line 534, in _make_request
    response = conn.getresponse()
               ^^^^^^^^^^^^^^^^^^
  File "K:\Scedule_Bot_1.0\.venv\Lib\site-packages\urllib3\connection.py", line 565, in getresponse
    httplib_response = super().getresponse()
                       ^^^^^^^^^^^^^^^^^^^^^
  File "C:\Users\kazak\AppData\Local\Programs\Python\Python312\Lib\http\client.py", line 1430, in getresponse
    response.begin()
  File "C:\Users\kazak\AppData\Local\Programs\Python\Python312\Lib\http\client.py", line 331, in begin
    version, status, reason = self._read_status()
                              ^^^^^^^^^^^^^^^^^^^
  File "C:\Users\kazak\AppData\Local\Programs\Python\Python312\Lib\http\client.py", line 300, in _read_status
    raise RemoteDisconnected("Remote end closed connection without"
urllib3.exceptions.ProtocolError: ('Connection aborted.', RemoteDisconnected('Remote end closed connection without response'))

During handling of the above exception, another exception occurred:

Traceback (most recent call last):
  File "K:\Scedule_Bot_1.0\.venv\Lib\site-packages\telebot\__init__.py", line 1110, in infinity_polling
    self.polling(non_stop=True, timeout=timeout, long_polling_timeout=long_polling_timeout,
  File "K:\Scedule_Bot_1.0\.venv\Lib\site-packages\telebot\__init__.py", line 1198, in polling
    self.__threaded_polling(non_stop=non_stop, interval=interval, timeout=timeout, long_polling_timeout=long_polling_timeout,
  File "K:\Scedule_Bot_1.0\.venv\Lib\site-packages\telebot\__init__.py", line 1273, in __threaded_polling
    raise e
  File "K:\Scedule_Bot_1.0\.venv\Lib\site-packages\telebot\__init__.py", line 1235, in __threaded_polling
    self.worker_pool.raise_exceptions()
  File "K:\Scedule_Bot_1.0\.venv\Lib\site-packages\telebot\util.py", line 150, in raise_exceptions
    raise self.exception_info
  File "K:\Scedule_Bot_1.0\.venv\Lib\site-packages\telebot\util.py", line 93, in run
    task(*args, **kwargs)
  File "K:\Scedule_Bot_1.0\.venv\Lib\site-packages\telebot\__init__.py", line 9759, in _run_middlewares_and_handler
    result = handler['function'](message)
             ^^^^^^^^^^^^^^^^^^^^^^^^^^^^
  File "K:\Scedule_Bot_1.0\telegram_bot\main.py", line 81, in start_func
    bot.send_message(user_data["tg_id"], START_MESSAGE.format(user_first_name=user_data["tg_first_name"]), reply_markup=markup_menu_buttons)
  File "K:\Scedule_Bot_1.0\.venv\Lib\site-packages\telebot\__init__.py", line 1800, in send_message
    apihelper.send_message(
  File "K:\Scedule_Bot_1.0\.venv\Lib\site-packages\telebot\apihelper.py", line 275, in send_message
    return _make_request(token, method_url, params=payload, method='post')
           ^^^^^^^^^^^^^^^^^^^^^^^^^^^^^^^^^^^^^^^^^^^^^^^^^^^^^^^^^^^^^^^
  File "K:\Scedule_Bot_1.0\.venv\Lib\site-packages\telebot\apihelper.py", line 162, in _make_request
    result = _get_req_session().request(
             ^^^^^^^^^^^^^^^^^^^^^^^^^^^
  File "K:\Scedule_Bot_1.0\.venv\Lib\site-packages\requests\sessions.py", line 589, in request
    resp = self.send(prep, **send_kwargs)
           ^^^^^^^^^^^^^^^^^^^^^^^^^^^^^^
  File "K:\Scedule_Bot_1.0\.venv\Lib\site-packages\requests\sessions.py", line 703, in send
    r = adapter.send(request, **kwargs)
        ^^^^^^^^^^^^^^^^^^^^^^^^^^^^^^^
  File "K:\Scedule_Bot_1.0\.venv\Lib\site-packages\requests\adapters.py", line 682, in send
    raise ConnectionError(err, request=request)
requests.exceptions.ConnectionError: ('Connection aborted.', RemoteDisconnected('Remote end closed connection without response'))

2025-09-16 10:39:47 - INFO - 6983370282 used START MESSAGE FUNC
2025-09-16 10:39:49 - INFO - 6983370282 used CHOICE PARALLEL FUNC
2025-09-16 10:39:51 - INFO - 6983370282 used CHOICE CLASS FUNC and choice 8 классы
2025-09-16 10:39:52 - INFO - 6983370282 used SAVE CHOICE CLASS FUNC and choice 8К
2025-09-16 10:40:52 - INFO - 6166278713 used START MESSAGE FUNC
2025-09-16 10:43:09 - INFO - Getting data from server
2025-09-16 10:43:10 - INFO - Start schedule normalization
2025-09-16 10:43:10 - INFO - Schedule is the same. Cancel.
2025-09-16 10:43:10 - INFO - Data received from server
2025-09-16 10:44:39 - INFO - 7979171504 used CHOICE CLASS FUNC and choice 8 классы
2025-09-16 10:44:42 - INFO - 7979171504 used SAVE CHOICE CLASS FUNC and choice 8К
2025-09-16 10:44:48 - INFO - 7979171504 used GET SCHEDULE FUNC and choice Вторник
2025-09-16 10:44:55 - INFO - 7979171504 used GET SCHEDULE FUNC and choice Среда
2025-09-16 10:48:10 - INFO - Getting data from server
2025-09-16 10:48:12 - INFO - Start schedule normalization
2025-09-16 10:48:12 - INFO - Schedule is the same. Cancel.
2025-09-16 10:48:12 - INFO - Data received from server
2025-09-16 10:53:12 - INFO - Getting data from server
2025-09-16 10:53:13 - INFO - Start schedule normalization
2025-09-16 10:53:13 - INFO - Schedule is the same. Cancel.
2025-09-16 10:53:13 - INFO - Data received from server
2025-09-16 10:58:13 - INFO - Getting data from server
2025-09-16 10:58:15 - INFO - Start schedule normalization
2025-09-16 10:58:15 - INFO - Schedule is the same. Cancel.
2025-09-16 10:58:15 - INFO - Data received from server
2025-09-16 11:00:50 - INFO - 6166278713 used START MESSAGE FUNC
2025-09-16 11:01:05 - INFO - 6166278713 used CHOICE PARALLEL FUNC
2025-09-16 11:01:08 - INFO - 6166278713 used CHOICE CLASS FUNC and choice 8 классы
2025-09-16 11:01:13 - INFO - 6166278713 used SAVE CHOICE CLASS FUNC and choice 8К
2025-09-16 11:01:23 - INFO - 6166278713 used GET SCHEDULE FUNC and choice Четверг
2025-09-16 11:01:27 - INFO - 6166278713 used GET SCHEDULE FUNC and choice Пятница
2025-09-16 11:01:30 - INFO - 6166278713 used GET SCHEDULE FUNC and choice Понедельник
2025-09-16 11:01:35 - INFO - 6166278713 used GET SCHEDULE FUNC and choice Среда
2025-09-16 11:03:15 - INFO - Getting data from server
2025-09-16 11:03:17 - INFO - Start schedule normalization
2025-09-16 11:03:17 - INFO - Schedule is the same. Cancel.
2025-09-16 11:03:17 - INFO - Data received from server
2025-09-16 11:08:17 - INFO - Getting data from server
2025-09-16 11:08:18 - INFO - Start schedule normalization
2025-09-16 11:08:18 - INFO - Schedule normalized
2025-09-16 11:08:18 - INFO - Data received from server
2025-09-16 11:13:18 - INFO - Getting data from server
2025-09-16 11:13:20 - INFO - Start schedule normalization
2025-09-16 11:13:20 - INFO - Schedule is the same. Cancel.
2025-09-16 11:13:20 - INFO - Data received from server
2025-09-16 11:17:56 - INFO - 6983370282 used GET SCHEDULE FUNC and choice Вторник
2025-09-16 11:17:57 - INFO - 6983370282 used GET SCHEDULE FUNC and choice Среда
2025-09-16 11:18:20 - INFO - Getting data from server
2025-09-16 11:18:21 - INFO - Start schedule normalization
2025-09-16 11:18:21 - INFO - Schedule is the same. Cancel.
2025-09-16 11:18:21 - INFO - Data received from server
2025-09-16 11:20:52 - INFO - 6983370282 used GET SCHEDULE FUNC and choice Вторник
2025-09-16 11:20:52 - INFO - 7979171504 used GET SCHEDULE FUNC and choice Среда
2025-09-16 11:23:21 - INFO - Getting data from server
2025-09-16 11:23:23 - INFO - Start schedule normalization
2025-09-16 11:23:23 - INFO - Schedule is the same. Cancel.
2025-09-16 11:23:23 - INFO - Data received from server
2025-09-16 11:28:23 - INFO - Getting data from server
2025-09-16 11:28:24 - INFO - Start schedule normalization
2025-09-16 11:28:25 - INFO - Schedule is the same. Cancel.
2025-09-16 11:28:25 - INFO - Data received from server
2025-09-16 11:33:25 - INFO - Getting data from server
2025-09-16 11:33:26 - INFO - Start schedule normalization
2025-09-16 11:33:26 - INFO - Schedule is the same. Cancel.
2025-09-16 11:33:26 - INFO - Data received from server
2025-09-16 11:38:26 - INFO - Getting data from server
2025-09-16 11:38:27 - INFO - Start schedule normalization
2025-09-16 11:38:28 - INFO - Schedule is the same. Cancel.
2025-09-16 11:38:28 - INFO - Data received from server
2025-09-16 11:43:28 - INFO - Getting data from server
2025-09-16 11:43:29 - INFO - Start schedule normalization
2025-09-16 11:43:29 - INFO - Schedule normalized
2025-09-16 11:43:29 - INFO - Data received from server
2025-09-16 11:48:29 - INFO - Getting data from server
2025-09-16 11:48:30 - INFO - Start schedule normalization
2025-09-16 11:48:31 - INFO - Schedule is the same. Cancel.
2025-09-16 11:48:31 - INFO - Data received from server
2025-09-16 11:53:31 - INFO - Getting data from server
2025-09-16 11:53:32 - INFO - Start schedule normalization
2025-09-16 11:53:32 - INFO - Schedule is the same. Cancel.
2025-09-16 11:53:32 - INFO - Data received from server
2025-09-16 11:58:32 - INFO - Getting data from server
2025-09-16 11:58:33 - INFO - Start schedule normalization
2025-09-16 11:58:33 - INFO - Schedule is the same. Cancel.
2025-09-16 11:58:33 - INFO - Data received from server
2025-09-16 12:03:33 - INFO - Getting data from server
2025-09-16 12:03:35 - INFO - Start schedule normalization
2025-09-16 12:03:35 - INFO - Schedule is the same. Cancel.
2025-09-16 12:03:35 - INFO - Data received from server
2025-09-16 12:08:35 - INFO - Getting data from server
2025-09-16 12:08:37 - INFO - Start schedule normalization
2025-09-16 12:08:37 - INFO - Schedule is the same. Cancel.
2025-09-16 12:08:37 - INFO - Data received from server
2025-09-16 12:13:37 - INFO - Getting data from server
2025-09-16 12:13:38 - INFO - Start schedule normalization
2025-09-16 12:13:38 - INFO - Schedule is the same. Cancel.
2025-09-16 12:13:38 - INFO - Data received from server
2025-09-16 12:18:16 - INFO - 6983370282 used GET SCHEDULE FUNC and choice Вторник
2025-09-16 12:18:38 - INFO - Getting data from server
2025-09-16 12:18:39 - INFO - Start schedule normalization
2025-09-16 12:18:40 - INFO - Schedule is the same. Cancel.
2025-09-16 12:18:40 - INFO - Data received from server
2025-09-16 12:18:51 - INFO - 5360263241 used START MESSAGE FUNC
2025-09-16 12:19:03 - INFO - 5360263241 used CHOICE PARALLEL FUNC
2025-09-16 12:19:07 - INFO - 5360263241 used CHOICE CLASS FUNC and choice 11 классы
2025-09-16 12:19:10 - INFO - 5360263241 used SAVE CHOICE CLASS FUNC and choice 11А
2025-09-16 12:19:12 - INFO - 5360263241 used GET SCHEDULE FUNC and choice Понедельник
2025-09-16 12:20:00 - INFO - 5360263241 used GET SCHEDULE FUNC and choice Понедельник
2025-09-16 12:20:06 - INFO - 5360263241 used CHOICE PARALLEL FUNC
2025-09-16 12:20:07 - INFO - 5360263241 used CHOICE CLASS FUNC and choice 11 классы
2025-09-16 12:23:33 - INFO - 6983370282 used CHOICE PARALLEL FUNC
2025-09-16 12:23:40 - INFO - Getting data from server
2025-09-16 12:23:41 - INFO - Start schedule normalization
2025-09-16 12:23:41 - INFO - Schedule is the same. Cancel.
2025-09-16 12:23:41 - INFO - Data received from server
2025-09-16 12:23:52 - ERROR - Infinity polling exception: ('Connection aborted.', RemoteDisconnected('Remote end closed connection without response'))
2025-09-16 12:23:52 - ERROR - Exception traceback:
Traceback (most recent call last):
  File "K:\Scedule_Bot_1.0\.venv\Lib\site-packages\urllib3\connectionpool.py", line 787, in urlopen
    response = self._make_request(
               ^^^^^^^^^^^^^^^^^^^
  File "K:\Scedule_Bot_1.0\.venv\Lib\site-packages\urllib3\connectionpool.py", line 534, in _make_request
    response = conn.getresponse()
               ^^^^^^^^^^^^^^^^^^
  File "K:\Scedule_Bot_1.0\.venv\Lib\site-packages\urllib3\connection.py", line 565, in getresponse
    httplib_response = super().getresponse()
                       ^^^^^^^^^^^^^^^^^^^^^
  File "C:\Users\kazak\AppData\Local\Programs\Python\Python312\Lib\http\client.py", line 1430, in getresponse
    response.begin()
  File "C:\Users\kazak\AppData\Local\Programs\Python\Python312\Lib\http\client.py", line 331, in begin
    version, status, reason = self._read_status()
                              ^^^^^^^^^^^^^^^^^^^
  File "C:\Users\kazak\AppData\Local\Programs\Python\Python312\Lib\http\client.py", line 300, in _read_status
    raise RemoteDisconnected("Remote end closed connection without"
http.client.RemoteDisconnected: Remote end closed connection without response

During handling of the above exception, another exception occurred:

Traceback (most recent call last):
  File "K:\Scedule_Bot_1.0\.venv\Lib\site-packages\requests\adapters.py", line 667, in send
    resp = conn.urlopen(
           ^^^^^^^^^^^^^
  File "K:\Scedule_Bot_1.0\.venv\Lib\site-packages\urllib3\connectionpool.py", line 841, in urlopen
    retries = retries.increment(
              ^^^^^^^^^^^^^^^^^^
  File "K:\Scedule_Bot_1.0\.venv\Lib\site-packages\urllib3\util\retry.py", line 474, in increment
    raise reraise(type(error), error, _stacktrace)
          ^^^^^^^^^^^^^^^^^^^^^^^^^^^^^^^^^^^^^^^^
  File "K:\Scedule_Bot_1.0\.venv\Lib\site-packages\urllib3\util\util.py", line 38, in reraise
    raise value.with_traceback(tb)
  File "K:\Scedule_Bot_1.0\.venv\Lib\site-packages\urllib3\connectionpool.py", line 787, in urlopen
    response = self._make_request(
               ^^^^^^^^^^^^^^^^^^^
  File "K:\Scedule_Bot_1.0\.venv\Lib\site-packages\urllib3\connectionpool.py", line 534, in _make_request
    response = conn.getresponse()
               ^^^^^^^^^^^^^^^^^^
  File "K:\Scedule_Bot_1.0\.venv\Lib\site-packages\urllib3\connection.py", line 565, in getresponse
    httplib_response = super().getresponse()
                       ^^^^^^^^^^^^^^^^^^^^^
  File "C:\Users\kazak\AppData\Local\Programs\Python\Python312\Lib\http\client.py", line 1430, in getresponse
    response.begin()
  File "C:\Users\kazak\AppData\Local\Programs\Python\Python312\Lib\http\client.py", line 331, in begin
    version, status, reason = self._read_status()
                              ^^^^^^^^^^^^^^^^^^^
  File "C:\Users\kazak\AppData\Local\Programs\Python\Python312\Lib\http\client.py", line 300, in _read_status
    raise RemoteDisconnected("Remote end closed connection without"
urllib3.exceptions.ProtocolError: ('Connection aborted.', RemoteDisconnected('Remote end closed connection without response'))

During handling of the above exception, another exception occurred:

Traceback (most recent call last):
  File "K:\Scedule_Bot_1.0\.venv\Lib\site-packages\telebot\__init__.py", line 1110, in infinity_polling
    self.polling(non_stop=True, timeout=timeout, long_polling_timeout=long_polling_timeout,
  File "K:\Scedule_Bot_1.0\.venv\Lib\site-packages\telebot\__init__.py", line 1198, in polling
    self.__threaded_polling(non_stop=non_stop, interval=interval, timeout=timeout, long_polling_timeout=long_polling_timeout,
  File "K:\Scedule_Bot_1.0\.venv\Lib\site-packages\telebot\__init__.py", line 1273, in __threaded_polling
    raise e
  File "K:\Scedule_Bot_1.0\.venv\Lib\site-packages\telebot\__init__.py", line 1235, in __threaded_polling
    self.worker_pool.raise_exceptions()
  File "K:\Scedule_Bot_1.0\.venv\Lib\site-packages\telebot\util.py", line 150, in raise_exceptions
    raise self.exception_info
  File "K:\Scedule_Bot_1.0\.venv\Lib\site-packages\telebot\util.py", line 93, in run
    task(*args, **kwargs)
  File "K:\Scedule_Bot_1.0\.venv\Lib\site-packages\telebot\__init__.py", line 9759, in _run_middlewares_and_handler
    result = handler['function'](message)
             ^^^^^^^^^^^^^^^^^^^^^^^^^^^^
  File "K:\Scedule_Bot_1.0\telegram_bot\main.py", line 203, in get_choice_parallel
    bot.send_message(message.from_user.id, CHOICE_PARALLEL_MESSAGE, reply_markup=markup_parallel)
  File "K:\Scedule_Bot_1.0\.venv\Lib\site-packages\telebot\__init__.py", line 1800, in send_message
    apihelper.send_message(
  File "K:\Scedule_Bot_1.0\.venv\Lib\site-packages\telebot\apihelper.py", line 275, in send_message
    return _make_request(token, method_url, params=payload, method='post')
           ^^^^^^^^^^^^^^^^^^^^^^^^^^^^^^^^^^^^^^^^^^^^^^^^^^^^^^^^^^^^^^^
  File "K:\Scedule_Bot_1.0\.venv\Lib\site-packages\telebot\apihelper.py", line 162, in _make_request
    result = _get_req_session().request(
             ^^^^^^^^^^^^^^^^^^^^^^^^^^^
  File "K:\Scedule_Bot_1.0\.venv\Lib\site-packages\requests\sessions.py", line 589, in request
    resp = self.send(prep, **send_kwargs)
           ^^^^^^^^^^^^^^^^^^^^^^^^^^^^^^
  File "K:\Scedule_Bot_1.0\.venv\Lib\site-packages\requests\sessions.py", line 703, in send
    r = adapter.send(request, **kwargs)
        ^^^^^^^^^^^^^^^^^^^^^^^^^^^^^^^
  File "K:\Scedule_Bot_1.0\.venv\Lib\site-packages\requests\adapters.py", line 682, in send
    raise ConnectionError(err, request=request)
requests.exceptions.ConnectionError: ('Connection aborted.', RemoteDisconnected('Remote end closed connection without response'))

2025-09-16 12:28:41 - INFO - Getting data from server
2025-09-16 12:28:42 - INFO - Start schedule normalization
2025-09-16 12:28:43 - INFO - Schedule is the same. Cancel.
2025-09-16 12:28:43 - INFO - Data received from server
2025-09-16 12:33:43 - INFO - Getting data from server
2025-09-16 12:33:44 - INFO - Start schedule normalization
2025-09-16 12:33:44 - INFO - Schedule is the same. Cancel.
2025-09-16 12:33:44 - INFO - Data received from server
2025-09-16 12:38:44 - INFO - Getting data from server
2025-09-16 12:38:45 - INFO - Start schedule normalization
2025-09-16 12:38:46 - INFO - Schedule is the same. Cancel.
2025-09-16 12:38:46 - INFO - Data received from server
2025-09-16 12:43:46 - INFO - Getting data from server
2025-09-16 12:43:47 - INFO - Start schedule normalization
2025-09-16 12:43:47 - INFO - Schedule is the same. Cancel.
2025-09-16 12:43:47 - INFO - Data received from server
2025-09-16 12:48:47 - INFO - Getting data from server
2025-09-16 12:48:49 - INFO - Start schedule normalization
2025-09-16 12:48:49 - INFO - Schedule is the same. Cancel.
2025-09-16 12:48:49 - INFO - Data received from server
2025-09-16 12:53:49 - INFO - Getting data from server
2025-09-16 12:53:50 - INFO - Start schedule normalization
2025-09-16 12:53:50 - INFO - Schedule normalized
2025-09-16 12:53:50 - INFO - Data received from server
2025-09-16 12:58:50 - INFO - Getting data from server
2025-09-16 12:58:52 - INFO - Start schedule normalization
2025-09-16 12:58:52 - INFO - Schedule is the same. Cancel.
2025-09-16 12:58:52 - INFO - Data received from server
2025-09-16 13:03:52 - INFO - Getting data from server
2025-09-16 13:03:53 - INFO - Start schedule normalization
2025-09-16 13:03:53 - INFO - Schedule is the same. Cancel.
2025-09-16 13:03:53 - INFO - Data received from server
2025-09-16 13:08:53 - INFO - Getting data from server
2025-09-16 13:08:55 - INFO - Start schedule normalization
2025-09-16 13:08:55 - INFO - Schedule is the same. Cancel.
2025-09-16 13:08:55 - INFO - Data received from server
2025-09-16 13:13:55 - INFO - Getting data from server
2025-09-16 13:13:56 - INFO - Start schedule normalization
2025-09-16 13:13:56 - INFO - Schedule is the same. Cancel.
2025-09-16 13:13:56 - INFO - Data received from server
2025-09-16 13:18:56 - INFO - Getting data from server
2025-09-16 13:18:58 - INFO - Start schedule normalization
2025-09-16 13:18:58 - INFO - Schedule is the same. Cancel.
2025-09-16 13:18:58 - INFO - Data received from server
2025-09-16 13:23:58 - INFO - Getting data from server
2025-09-16 13:23:59 - INFO - Start schedule normalization
2025-09-16 13:23:59 - INFO - Schedule is the same. Cancel.
2025-09-16 13:23:59 - INFO - Data received from server
2025-09-16 13:28:59 - INFO - Getting data from server
2025-09-16 13:29:01 - INFO - Start schedule normalization
2025-09-16 13:29:01 - INFO - Schedule is the same. Cancel.
2025-09-16 13:29:01 - INFO - Data received from server
2025-09-16 13:34:01 - INFO - Getting data from server
2025-09-16 13:34:02 - INFO - Start schedule normalization
2025-09-16 13:34:02 - INFO - Schedule is the same. Cancel.
2025-09-16 13:34:02 - INFO - Data received from server
2025-09-16 13:39:02 - INFO - Getting data from server
2025-09-16 13:39:04 - INFO - Start schedule normalization
2025-09-16 13:39:04 - INFO - Schedule is the same. Cancel.
2025-09-16 13:39:04 - INFO - Data received from server
2025-09-16 13:43:56 - INFO - 6983370282 used GET SCHEDULE FUNC and choice Вторник
2025-09-16 13:43:58 - INFO - 6983370282 used CHOICE PARALLEL FUNC
2025-09-16 13:44:01 - INFO - 6983370282 used CHOICE CLASS FUNC and choice 8 классы
2025-09-16 13:44:02 - INFO - 6983370282 used SAVE CHOICE CLASS FUNC and choice 8К
2025-09-16 13:44:04 - INFO - Getting data from server
2025-09-16 13:44:05 - INFO - Start schedule normalization
2025-09-16 13:44:06 - INFO - Schedule is the same. Cancel.
2025-09-16 13:44:06 - INFO - Data received from server
2025-09-16 13:44:06 - INFO - 6983370282 used GET SCHEDULE FUNC and choice Пятница
2025-09-16 13:44:15 - INFO - 6983370282 used GET SCHEDULE FUNC and choice Среда
2025-09-16 13:44:26 - INFO - 6983370282 used STOP FUNC
2025-09-16 17:20:21 - INFO - ###############################
2025-09-16 17:20:21 - INFO - TEST INFO LOGGING FINALLY
2025-09-16 17:20:21 - WARNING - TEST WARNING LOGGING FINALLY
2025-09-16 17:20:21 - ERROR - Error to: utils.my_logger | Index: 0
NoneType: None
2025-09-16 17:20:21 - CRITICAL - TEST FATAL LOGGING FINALLY
2025-09-16 17:20:21 - INFO - LOGGER STARTED
2025-09-16 17:20:21 - INFO - ###############################
2025-09-16 17:20:21 - INFO - Stated connect to db
2025-09-16 17:20:21 - INFO - Users db created/exist
2025-09-16 17:20:21 - INFO - WS Parser started!
2025-09-16 17:20:21 - INFO - Getting data from server
2025-09-16 17:20:22 - INFO - 2045262706 used GET SCHEDULE FUNC and choice Среда
2025-09-16 17:20:22 - INFO - 2045262706 used GET SCHEDULE FUNC and choice Среда
2025-09-16 17:20:22 - INFO - 2045262706 used CHOICE PARALLEL FUNC
2025-09-16 17:20:22 - INFO - 2045262706 used CHOICE PARALLEL FUNC
2025-09-16 17:20:22 - INFO - 6983370282 used GET SCHEDULE FUNC and choice Вторник
2025-09-16 17:20:22 - INFO - Start schedule normalization
2025-09-16 17:20:22 - INFO - Schedule normalized
2025-09-16 17:20:22 - INFO - Data received from server
2025-09-16 17:24:41 - INFO - 6983370282 used GET SCHEDULE FUNC and choice Среда
2025-09-16 17:24:49 - INFO - 6983370282 used GET SCHEDULE FUNC and choice Среда
2025-09-16 17:25:03 - ERROR - Infinity polling exception: ('Connection aborted.', RemoteDisconnected('Remote end closed connection without response'))
2025-09-16 17:25:03 - ERROR - Exception traceback:
Traceback (most recent call last):
  File "K:\Scedule_Bot_1.0\.venv\Lib\site-packages\urllib3\connectionpool.py", line 787, in urlopen
    response = self._make_request(
               ^^^^^^^^^^^^^^^^^^^
  File "K:\Scedule_Bot_1.0\.venv\Lib\site-packages\urllib3\connectionpool.py", line 534, in _make_request
    response = conn.getresponse()
               ^^^^^^^^^^^^^^^^^^
  File "K:\Scedule_Bot_1.0\.venv\Lib\site-packages\urllib3\connection.py", line 565, in getresponse
    httplib_response = super().getresponse()
                       ^^^^^^^^^^^^^^^^^^^^^
  File "C:\Users\kazak\AppData\Local\Programs\Python\Python312\Lib\http\client.py", line 1430, in getresponse
    response.begin()
  File "C:\Users\kazak\AppData\Local\Programs\Python\Python312\Lib\http\client.py", line 331, in begin
    version, status, reason = self._read_status()
                              ^^^^^^^^^^^^^^^^^^^
  File "C:\Users\kazak\AppData\Local\Programs\Python\Python312\Lib\http\client.py", line 300, in _read_status
    raise RemoteDisconnected("Remote end closed connection without"
http.client.RemoteDisconnected: Remote end closed connection without response

During handling of the above exception, another exception occurred:

Traceback (most recent call last):
  File "K:\Scedule_Bot_1.0\.venv\Lib\site-packages\requests\adapters.py", line 667, in send
    resp = conn.urlopen(
           ^^^^^^^^^^^^^
  File "K:\Scedule_Bot_1.0\.venv\Lib\site-packages\urllib3\connectionpool.py", line 841, in urlopen
    retries = retries.increment(
              ^^^^^^^^^^^^^^^^^^
  File "K:\Scedule_Bot_1.0\.venv\Lib\site-packages\urllib3\util\retry.py", line 474, in increment
    raise reraise(type(error), error, _stacktrace)
          ^^^^^^^^^^^^^^^^^^^^^^^^^^^^^^^^^^^^^^^^
  File "K:\Scedule_Bot_1.0\.venv\Lib\site-packages\urllib3\util\util.py", line 38, in reraise
    raise value.with_traceback(tb)
  File "K:\Scedule_Bot_1.0\.venv\Lib\site-packages\urllib3\connectionpool.py", line 787, in urlopen
    response = self._make_request(
               ^^^^^^^^^^^^^^^^^^^
  File "K:\Scedule_Bot_1.0\.venv\Lib\site-packages\urllib3\connectionpool.py", line 534, in _make_request
    response = conn.getresponse()
               ^^^^^^^^^^^^^^^^^^
  File "K:\Scedule_Bot_1.0\.venv\Lib\site-packages\urllib3\connection.py", line 565, in getresponse
    httplib_response = super().getresponse()
                       ^^^^^^^^^^^^^^^^^^^^^
  File "C:\Users\kazak\AppData\Local\Programs\Python\Python312\Lib\http\client.py", line 1430, in getresponse
    response.begin()
  File "C:\Users\kazak\AppData\Local\Programs\Python\Python312\Lib\http\client.py", line 331, in begin
    version, status, reason = self._read_status()
                              ^^^^^^^^^^^^^^^^^^^
  File "C:\Users\kazak\AppData\Local\Programs\Python\Python312\Lib\http\client.py", line 300, in _read_status
    raise RemoteDisconnected("Remote end closed connection without"
urllib3.exceptions.ProtocolError: ('Connection aborted.', RemoteDisconnected('Remote end closed connection without response'))

During handling of the above exception, another exception occurred:

Traceback (most recent call last):
  File "K:\Scedule_Bot_1.0\.venv\Lib\site-packages\telebot\__init__.py", line 1110, in infinity_polling
    self.polling(non_stop=True, timeout=timeout, long_polling_timeout=long_polling_timeout,
  File "K:\Scedule_Bot_1.0\.venv\Lib\site-packages\telebot\__init__.py", line 1198, in polling
    self.__threaded_polling(non_stop=non_stop, interval=interval, timeout=timeout, long_polling_timeout=long_polling_timeout,
  File "K:\Scedule_Bot_1.0\.venv\Lib\site-packages\telebot\__init__.py", line 1273, in __threaded_polling
    raise e
  File "K:\Scedule_Bot_1.0\.venv\Lib\site-packages\telebot\__init__.py", line 1235, in __threaded_polling
    self.worker_pool.raise_exceptions()
  File "K:\Scedule_Bot_1.0\.venv\Lib\site-packages\telebot\util.py", line 150, in raise_exceptions
    raise self.exception_info
  File "K:\Scedule_Bot_1.0\.venv\Lib\site-packages\telebot\util.py", line 93, in run
    task(*args, **kwargs)
  File "K:\Scedule_Bot_1.0\.venv\Lib\site-packages\telebot\__init__.py", line 9759, in _run_middlewares_and_handler
    result = handler['function'](message)
             ^^^^^^^^^^^^^^^^^^^^^^^^^^^^
  File "K:\Scedule_Bot_1.0\telegram_bot\main.py", line 273, in get_schedule_for_user
    bot.send_message(message.from_user.id,
  File "K:\Scedule_Bot_1.0\.venv\Lib\site-packages\telebot\__init__.py", line 1800, in send_message
    apihelper.send_message(
  File "K:\Scedule_Bot_1.0\.venv\Lib\site-packages\telebot\apihelper.py", line 275, in send_message
    return _make_request(token, method_url, params=payload, method='post')
           ^^^^^^^^^^^^^^^^^^^^^^^^^^^^^^^^^^^^^^^^^^^^^^^^^^^^^^^^^^^^^^^
  File "K:\Scedule_Bot_1.0\.venv\Lib\site-packages\telebot\apihelper.py", line 162, in _make_request
    result = _get_req_session().request(
             ^^^^^^^^^^^^^^^^^^^^^^^^^^^
  File "K:\Scedule_Bot_1.0\.venv\Lib\site-packages\requests\sessions.py", line 589, in request
    resp = self.send(prep, **send_kwargs)
           ^^^^^^^^^^^^^^^^^^^^^^^^^^^^^^
  File "K:\Scedule_Bot_1.0\.venv\Lib\site-packages\requests\sessions.py", line 703, in send
    r = adapter.send(request, **kwargs)
        ^^^^^^^^^^^^^^^^^^^^^^^^^^^^^^^
  File "K:\Scedule_Bot_1.0\.venv\Lib\site-packages\requests\adapters.py", line 682, in send
    raise ConnectionError(err, request=request)
requests.exceptions.ConnectionError: ('Connection aborted.', RemoteDisconnected('Remote end closed connection without response'))

2025-09-16 17:25:03 - INFO - 6983370282 used GET SCHEDULE FUNC and choice Среда
2025-09-16 17:25:04 - INFO - 6983370282 used GET SCHEDULE FUNC and choice Среда
2025-09-16 17:25:08 - ERROR - Infinity polling exception: ('Connection aborted.', RemoteDisconnected('Remote end closed connection without response'))
2025-09-16 17:25:08 - ERROR - Exception traceback:
Traceback (most recent call last):
  File "K:\Scedule_Bot_1.0\.venv\Lib\site-packages\urllib3\connectionpool.py", line 787, in urlopen
    response = self._make_request(
               ^^^^^^^^^^^^^^^^^^^
  File "K:\Scedule_Bot_1.0\.venv\Lib\site-packages\urllib3\connectionpool.py", line 534, in _make_request
    response = conn.getresponse()
               ^^^^^^^^^^^^^^^^^^
  File "K:\Scedule_Bot_1.0\.venv\Lib\site-packages\urllib3\connection.py", line 565, in getresponse
    httplib_response = super().getresponse()
                       ^^^^^^^^^^^^^^^^^^^^^
  File "C:\Users\kazak\AppData\Local\Programs\Python\Python312\Lib\http\client.py", line 1430, in getresponse
    response.begin()
  File "C:\Users\kazak\AppData\Local\Programs\Python\Python312\Lib\http\client.py", line 331, in begin
    version, status, reason = self._read_status()
                              ^^^^^^^^^^^^^^^^^^^
  File "C:\Users\kazak\AppData\Local\Programs\Python\Python312\Lib\http\client.py", line 300, in _read_status
    raise RemoteDisconnected("Remote end closed connection without"
http.client.RemoteDisconnected: Remote end closed connection without response

During handling of the above exception, another exception occurred:

Traceback (most recent call last):
  File "K:\Scedule_Bot_1.0\.venv\Lib\site-packages\requests\adapters.py", line 667, in send
    resp = conn.urlopen(
           ^^^^^^^^^^^^^
  File "K:\Scedule_Bot_1.0\.venv\Lib\site-packages\urllib3\connectionpool.py", line 841, in urlopen
    retries = retries.increment(
              ^^^^^^^^^^^^^^^^^^
  File "K:\Scedule_Bot_1.0\.venv\Lib\site-packages\urllib3\util\retry.py", line 474, in increment
    raise reraise(type(error), error, _stacktrace)
          ^^^^^^^^^^^^^^^^^^^^^^^^^^^^^^^^^^^^^^^^
  File "K:\Scedule_Bot_1.0\.venv\Lib\site-packages\urllib3\util\util.py", line 38, in reraise
    raise value.with_traceback(tb)
  File "K:\Scedule_Bot_1.0\.venv\Lib\site-packages\urllib3\connectionpool.py", line 787, in urlopen
    response = self._make_request(
               ^^^^^^^^^^^^^^^^^^^
  File "K:\Scedule_Bot_1.0\.venv\Lib\site-packages\urllib3\connectionpool.py", line 534, in _make_request
    response = conn.getresponse()
               ^^^^^^^^^^^^^^^^^^
  File "K:\Scedule_Bot_1.0\.venv\Lib\site-packages\urllib3\connection.py", line 565, in getresponse
    httplib_response = super().getresponse()
                       ^^^^^^^^^^^^^^^^^^^^^
  File "C:\Users\kazak\AppData\Local\Programs\Python\Python312\Lib\http\client.py", line 1430, in getresponse
    response.begin()
  File "C:\Users\kazak\AppData\Local\Programs\Python\Python312\Lib\http\client.py", line 331, in begin
    version, status, reason = self._read_status()
                              ^^^^^^^^^^^^^^^^^^^
  File "C:\Users\kazak\AppData\Local\Programs\Python\Python312\Lib\http\client.py", line 300, in _read_status
    raise RemoteDisconnected("Remote end closed connection without"
urllib3.exceptions.ProtocolError: ('Connection aborted.', RemoteDisconnected('Remote end closed connection without response'))

During handling of the above exception, another exception occurred:

Traceback (most recent call last):
  File "K:\Scedule_Bot_1.0\.venv\Lib\site-packages\telebot\__init__.py", line 1110, in infinity_polling
    self.polling(non_stop=True, timeout=timeout, long_polling_timeout=long_polling_timeout,
  File "K:\Scedule_Bot_1.0\.venv\Lib\site-packages\telebot\__init__.py", line 1198, in polling
    self.__threaded_polling(non_stop=non_stop, interval=interval, timeout=timeout, long_polling_timeout=long_polling_timeout,
  File "K:\Scedule_Bot_1.0\.venv\Lib\site-packages\telebot\__init__.py", line 1273, in __threaded_polling
    raise e
  File "K:\Scedule_Bot_1.0\.venv\Lib\site-packages\telebot\__init__.py", line 1235, in __threaded_polling
    self.worker_pool.raise_exceptions()
  File "K:\Scedule_Bot_1.0\.venv\Lib\site-packages\telebot\util.py", line 150, in raise_exceptions
    raise self.exception_info
  File "K:\Scedule_Bot_1.0\.venv\Lib\site-packages\telebot\util.py", line 93, in run
    task(*args, **kwargs)
  File "K:\Scedule_Bot_1.0\.venv\Lib\site-packages\telebot\__init__.py", line 9759, in _run_middlewares_and_handler
    result = handler['function'](message)
             ^^^^^^^^^^^^^^^^^^^^^^^^^^^^
  File "K:\Scedule_Bot_1.0\telegram_bot\main.py", line 273, in get_schedule_for_user
    bot.send_message(message.from_user.id,
  File "K:\Scedule_Bot_1.0\.venv\Lib\site-packages\telebot\__init__.py", line 1800, in send_message
    apihelper.send_message(
  File "K:\Scedule_Bot_1.0\.venv\Lib\site-packages\telebot\apihelper.py", line 275, in send_message
    return _make_request(token, method_url, params=payload, method='post')
           ^^^^^^^^^^^^^^^^^^^^^^^^^^^^^^^^^^^^^^^^^^^^^^^^^^^^^^^^^^^^^^^
  File "K:\Scedule_Bot_1.0\.venv\Lib\site-packages\telebot\apihelper.py", line 162, in _make_request
    result = _get_req_session().request(
             ^^^^^^^^^^^^^^^^^^^^^^^^^^^
  File "K:\Scedule_Bot_1.0\.venv\Lib\site-packages\requests\sessions.py", line 589, in request
    resp = self.send(prep, **send_kwargs)
           ^^^^^^^^^^^^^^^^^^^^^^^^^^^^^^
  File "K:\Scedule_Bot_1.0\.venv\Lib\site-packages\requests\sessions.py", line 703, in send
    r = adapter.send(request, **kwargs)
        ^^^^^^^^^^^^^^^^^^^^^^^^^^^^^^^
  File "K:\Scedule_Bot_1.0\.venv\Lib\site-packages\requests\adapters.py", line 682, in send
    raise ConnectionError(err, request=request)
requests.exceptions.ConnectionError: ('Connection aborted.', RemoteDisconnected('Remote end closed connection without response'))

2025-09-16 17:25:20 - INFO - 6983370282 used GET SCHEDULE FUNC and choice Среда
2025-09-16 17:25:22 - INFO - Getting data from server
2025-09-16 17:25:24 - INFO - Start schedule normalization
2025-09-16 17:25:24 - INFO - Schedule is the same. Cancel.
2025-09-16 17:25:24 - INFO - Data received from server
2025-09-16 17:30:24 - INFO - Getting data from server
2025-09-16 17:30:26 - INFO - Start schedule normalization
2025-09-16 17:30:26 - INFO - Schedule is the same. Cancel.
2025-09-16 17:30:26 - INFO - Data received from server
2025-09-16 17:35:26 - INFO - Getting data from server
2025-09-16 17:35:28 - INFO - Start schedule normalization
2025-09-16 17:35:28 - INFO - Schedule is the same. Cancel.
2025-09-16 17:35:28 - INFO - Data received from server
2025-09-16 17:40:10 - INFO - 321729372 used START MESSAGE FUNC
2025-09-16 17:40:12 - INFO - 321729372 used CHOICE PARALLEL FUNC
2025-09-16 17:40:15 - INFO - 321729372 used CHOICE CLASS FUNC and choice 8 классы
2025-09-16 17:40:16 - INFO - 321729372 used SAVE CHOICE CLASS FUNC and choice 8К
2025-09-16 17:40:19 - INFO - 321729372 used GET SCHEDULE FUNC and choice Среда
2025-09-16 17:40:28 - INFO - Getting data from server
2025-09-16 17:40:30 - INFO - Start schedule normalization
2025-09-16 17:40:30 - INFO - Schedule is the same. Cancel.
2025-09-16 17:40:30 - INFO - Data received from server
2025-09-16 17:41:02 - INFO - 321729372 used GET SCHEDULE FUNC and choice Четверг
2025-09-16 17:41:08 - INFO - 321729372 used GET SCHEDULE FUNC and choice Пятница
2025-09-16 17:41:15 - INFO - 321729372 used GET SCHEDULE FUNC and choice Понедельник
2025-09-16 17:45:30 - INFO - Getting data from server
2025-09-16 17:45:32 - INFO - Start schedule normalization
2025-09-16 17:45:32 - INFO - Schedule is the same. Cancel.
2025-09-16 17:45:32 - INFO - Data received from server
2025-09-16 17:50:32 - INFO - Getting data from server
2025-09-16 17:50:35 - INFO - Start schedule normalization
2025-09-16 17:50:35 - INFO - Schedule is the same. Cancel.
2025-09-16 17:50:35 - INFO - Data received from server
2025-09-16 17:53:31 - INFO - 321729372 used GET SCHEDULE FUNC and choice Понедельник
2025-09-16 17:53:56 - INFO - 321729372 used GET SCHEDULE FUNC and choice Вторник
2025-09-16 17:55:35 - INFO - Getting data from server
2025-09-16 17:55:37 - INFO - Start schedule normalization
2025-09-16 17:55:37 - INFO - Schedule is the same. Cancel.
2025-09-16 17:55:37 - INFO - Data received from server
2025-09-16 17:56:09 - INFO - 321729372 used GET SCHEDULE FUNC and choice Вторник
2025-09-16 17:56:26 - INFO - 321729372 used GET SCHEDULE FUNC and choice Среда
2025-09-16 17:57:33 - INFO - 321729372 used GET SCHEDULE FUNC and choice Четверг
2025-09-16 17:58:20 - INFO - 321729372 used GET SCHEDULE FUNC and choice Пятница
2025-09-16 17:59:12 - INFO - 2045262706 used CHOICE CLASS FUNC and choice 8 классы
2025-09-16 17:59:16 - INFO - 2045262706 used SAVE CHOICE CLASS FUNC and choice 8К
2025-09-16 17:59:20 - INFO - 2045262706 used GET SCHEDULE FUNC and choice Среда
2025-09-16 17:59:40 - ERROR - Infinity polling exception: ('Connection aborted.', RemoteDisconnected('Remote end closed connection without response'))
2025-09-16 17:59:40 - ERROR - Exception traceback:
Traceback (most recent call last):
  File "K:\Scedule_Bot_1.0\.venv\Lib\site-packages\urllib3\connectionpool.py", line 787, in urlopen
    response = self._make_request(
               ^^^^^^^^^^^^^^^^^^^
  File "K:\Scedule_Bot_1.0\.venv\Lib\site-packages\urllib3\connectionpool.py", line 534, in _make_request
    response = conn.getresponse()
               ^^^^^^^^^^^^^^^^^^
  File "K:\Scedule_Bot_1.0\.venv\Lib\site-packages\urllib3\connection.py", line 565, in getresponse
    httplib_response = super().getresponse()
                       ^^^^^^^^^^^^^^^^^^^^^
  File "C:\Users\kazak\AppData\Local\Programs\Python\Python312\Lib\http\client.py", line 1430, in getresponse
    response.begin()
  File "C:\Users\kazak\AppData\Local\Programs\Python\Python312\Lib\http\client.py", line 331, in begin
    version, status, reason = self._read_status()
                              ^^^^^^^^^^^^^^^^^^^
  File "C:\Users\kazak\AppData\Local\Programs\Python\Python312\Lib\http\client.py", line 300, in _read_status
    raise RemoteDisconnected("Remote end closed connection without"
http.client.RemoteDisconnected: Remote end closed connection without response

During handling of the above exception, another exception occurred:

Traceback (most recent call last):
  File "K:\Scedule_Bot_1.0\.venv\Lib\site-packages\requests\adapters.py", line 667, in send
    resp = conn.urlopen(
           ^^^^^^^^^^^^^
  File "K:\Scedule_Bot_1.0\.venv\Lib\site-packages\urllib3\connectionpool.py", line 841, in urlopen
    retries = retries.increment(
              ^^^^^^^^^^^^^^^^^^
  File "K:\Scedule_Bot_1.0\.venv\Lib\site-packages\urllib3\util\retry.py", line 474, in increment
    raise reraise(type(error), error, _stacktrace)
          ^^^^^^^^^^^^^^^^^^^^^^^^^^^^^^^^^^^^^^^^
  File "K:\Scedule_Bot_1.0\.venv\Lib\site-packages\urllib3\util\util.py", line 38, in reraise
    raise value.with_traceback(tb)
  File "K:\Scedule_Bot_1.0\.venv\Lib\site-packages\urllib3\connectionpool.py", line 787, in urlopen
    response = self._make_request(
               ^^^^^^^^^^^^^^^^^^^
  File "K:\Scedule_Bot_1.0\.venv\Lib\site-packages\urllib3\connectionpool.py", line 534, in _make_request
    response = conn.getresponse()
               ^^^^^^^^^^^^^^^^^^
  File "K:\Scedule_Bot_1.0\.venv\Lib\site-packages\urllib3\connection.py", line 565, in getresponse
    httplib_response = super().getresponse()
                       ^^^^^^^^^^^^^^^^^^^^^
  File "C:\Users\kazak\AppData\Local\Programs\Python\Python312\Lib\http\client.py", line 1430, in getresponse
    response.begin()
  File "C:\Users\kazak\AppData\Local\Programs\Python\Python312\Lib\http\client.py", line 331, in begin
    version, status, reason = self._read_status()
                              ^^^^^^^^^^^^^^^^^^^
  File "C:\Users\kazak\AppData\Local\Programs\Python\Python312\Lib\http\client.py", line 300, in _read_status
    raise RemoteDisconnected("Remote end closed connection without"
urllib3.exceptions.ProtocolError: ('Connection aborted.', RemoteDisconnected('Remote end closed connection without response'))

During handling of the above exception, another exception occurred:

Traceback (most recent call last):
  File "K:\Scedule_Bot_1.0\.venv\Lib\site-packages\telebot\__init__.py", line 1110, in infinity_polling
    self.polling(non_stop=True, timeout=timeout, long_polling_timeout=long_polling_timeout,
  File "K:\Scedule_Bot_1.0\.venv\Lib\site-packages\telebot\__init__.py", line 1198, in polling
    self.__threaded_polling(non_stop=non_stop, interval=interval, timeout=timeout, long_polling_timeout=long_polling_timeout,
  File "K:\Scedule_Bot_1.0\.venv\Lib\site-packages\telebot\__init__.py", line 1273, in __threaded_polling
    raise e
  File "K:\Scedule_Bot_1.0\.venv\Lib\site-packages\telebot\__init__.py", line 1235, in __threaded_polling
    self.worker_pool.raise_exceptions()
  File "K:\Scedule_Bot_1.0\.venv\Lib\site-packages\telebot\util.py", line 150, in raise_exceptions
    raise self.exception_info
  File "K:\Scedule_Bot_1.0\.venv\Lib\site-packages\telebot\util.py", line 93, in run
    task(*args, **kwargs)
  File "K:\Scedule_Bot_1.0\.venv\Lib\site-packages\telebot\__init__.py", line 9759, in _run_middlewares_and_handler
    result = handler['function'](message)
             ^^^^^^^^^^^^^^^^^^^^^^^^^^^^
  File "K:\Scedule_Bot_1.0\telegram_bot\main.py", line 273, in get_schedule_for_user
    bot.send_message(message.from_user.id,
  File "K:\Scedule_Bot_1.0\.venv\Lib\site-packages\telebot\__init__.py", line 1800, in send_message
    apihelper.send_message(
  File "K:\Scedule_Bot_1.0\.venv\Lib\site-packages\telebot\apihelper.py", line 275, in send_message
    return _make_request(token, method_url, params=payload, method='post')
           ^^^^^^^^^^^^^^^^^^^^^^^^^^^^^^^^^^^^^^^^^^^^^^^^^^^^^^^^^^^^^^^
  File "K:\Scedule_Bot_1.0\.venv\Lib\site-packages\telebot\apihelper.py", line 162, in _make_request
    result = _get_req_session().request(
             ^^^^^^^^^^^^^^^^^^^^^^^^^^^
  File "K:\Scedule_Bot_1.0\.venv\Lib\site-packages\requests\sessions.py", line 589, in request
    resp = self.send(prep, **send_kwargs)
           ^^^^^^^^^^^^^^^^^^^^^^^^^^^^^^
  File "K:\Scedule_Bot_1.0\.venv\Lib\site-packages\requests\sessions.py", line 703, in send
    r = adapter.send(request, **kwargs)
        ^^^^^^^^^^^^^^^^^^^^^^^^^^^^^^^
  File "K:\Scedule_Bot_1.0\.venv\Lib\site-packages\requests\adapters.py", line 682, in send
    raise ConnectionError(err, request=request)
requests.exceptions.ConnectionError: ('Connection aborted.', RemoteDisconnected('Remote end closed connection without response'))

2025-09-16 18:00:37 - INFO - Getting data from server
2025-09-16 18:00:38 - INFO - Start schedule normalization
2025-09-16 18:00:38 - INFO - Schedule is the same. Cancel.
2025-09-16 18:00:38 - INFO - Data received from server
2025-09-16 18:05:38 - INFO - Getting data from server
2025-09-16 18:05:40 - INFO - Start schedule normalization
2025-09-16 18:05:40 - INFO - Schedule is the same. Cancel.
2025-09-16 18:05:40 - INFO - Data received from server
2025-09-16 18:10:40 - INFO - Getting data from server
2025-09-16 18:10:42 - INFO - Start schedule normalization
2025-09-16 18:10:42 - INFO - Schedule is the same. Cancel.
2025-09-16 18:10:42 - INFO - Data received from server
2025-09-16 18:15:34 - INFO - 6983370282 used GET SCHEDULE FUNC and choice Среда
2025-09-16 18:15:42 - INFO - Getting data from server
2025-09-16 18:15:44 - INFO - Start schedule normalization
2025-09-16 18:15:44 - INFO - Schedule is the same. Cancel.
2025-09-16 18:15:44 - INFO - Data received from server
2025-09-16 18:20:44 - INFO - Getting data from server
2025-09-16 18:20:45 - INFO - Start schedule normalization
2025-09-16 18:20:45 - INFO - Schedule is the same. Cancel.
2025-09-16 18:20:45 - INFO - Data received from server
2025-09-16 18:25:45 - INFO - Getting data from server
2025-09-16 18:25:47 - INFO - Start schedule normalization
2025-09-16 18:25:47 - INFO - Schedule is the same. Cancel.
2025-09-16 18:25:47 - INFO - Data received from server
2025-09-16 18:30:47 - INFO - Getting data from server
2025-09-16 18:30:49 - INFO - Start schedule normalization
2025-09-16 18:30:49 - INFO - Schedule is the same. Cancel.
2025-09-16 18:30:49 - INFO - Data received from server
2025-09-16 18:35:49 - INFO - Getting data from server
2025-09-16 18:35:50 - INFO - Start schedule normalization
2025-09-16 18:35:50 - INFO - Schedule is the same. Cancel.
2025-09-16 18:35:50 - INFO - Data received from server
2025-09-16 18:40:50 - INFO - Getting data from server
2025-09-16 18:40:52 - INFO - Start schedule normalization
2025-09-16 18:40:52 - INFO - Schedule is the same. Cancel.
2025-09-16 18:40:52 - INFO - Data received from server
2025-09-16 18:45:52 - INFO - Getting data from server
2025-09-16 18:45:53 - INFO - Start schedule normalization
2025-09-16 18:45:53 - INFO - Schedule is the same. Cancel.
2025-09-16 18:45:53 - INFO - Data received from server
2025-09-16 18:50:53 - INFO - Getting data from server
2025-09-16 18:50:55 - INFO - Start schedule normalization
2025-09-16 18:50:55 - INFO - Schedule is the same. Cancel.
2025-09-16 18:50:55 - INFO - Data received from server
2025-09-16 18:55:55 - INFO - Getting data from server
2025-09-16 18:55:56 - INFO - Start schedule normalization
2025-09-16 18:55:56 - INFO - Schedule is the same. Cancel.
2025-09-16 18:55:56 - INFO - Data received from server
2025-09-16 19:00:56 - INFO - Getting data from server
2025-09-16 19:00:58 - INFO - Start schedule normalization
2025-09-16 19:00:58 - INFO - Schedule is the same. Cancel.
2025-09-16 19:00:58 - INFO - Data received from server
2025-09-16 19:05:58 - INFO - Getting data from server
2025-09-16 19:05:59 - INFO - Start schedule normalization
2025-09-16 19:05:59 - INFO - Schedule is the same. Cancel.
2025-09-16 19:05:59 - INFO - Data received from server
2025-09-16 19:10:59 - INFO - Getting data from server
2025-09-16 19:11:01 - INFO - Start schedule normalization
2025-09-16 19:11:01 - INFO - Schedule is the same. Cancel.
2025-09-16 19:11:01 - INFO - Data received from server
2025-09-16 19:16:01 - INFO - Getting data from server
2025-09-16 19:16:02 - INFO - Start schedule normalization
2025-09-16 19:16:03 - INFO - Schedule is the same. Cancel.
2025-09-16 19:16:03 - INFO - Data received from server
2025-09-16 19:21:03 - INFO - Getting data from server
2025-09-16 19:21:04 - INFO - Start schedule normalization
2025-09-16 19:21:04 - INFO - Schedule is the same. Cancel.
2025-09-16 19:21:04 - INFO - Data received from server
2025-09-16 19:26:04 - INFO - Getting data from server
2025-09-16 19:26:05 - INFO - Start schedule normalization
2025-09-16 19:26:05 - INFO - Schedule is the same. Cancel.
2025-09-16 19:26:05 - INFO - Data received from server
2025-09-16 19:31:05 - INFO - Getting data from server
2025-09-16 19:31:07 - INFO - Start schedule normalization
2025-09-16 19:31:07 - INFO - Schedule is the same. Cancel.
2025-09-16 19:31:07 - INFO - Data received from server
2025-09-16 19:35:17 - INFO - 7687504267 used START MESSAGE FUNC
2025-09-16 19:35:22 - INFO - 7687504267 used GET HELP FUNC
2025-09-16 19:35:24 - INFO - 7687504267 used GET HELP FUNC 2
2025-09-16 19:35:26 - INFO - 7687504267 used CHOICE PARALLEL FUNC
2025-09-16 19:35:31 - INFO - 7687504267 used CHOICE CLASS FUNC and choice 9 классы
2025-09-16 19:35:34 - INFO - 7687504267 used SAVE CHOICE CLASS FUNC and choice 9Б
2025-09-16 19:35:36 - INFO - 7687504267 used GET SCHEDULE FUNC and choice Вторник
2025-09-16 19:36:07 - INFO - Getting data from server
2025-09-16 19:36:09 - INFO - Start schedule normalization
2025-09-16 19:36:09 - INFO - Schedule is the same. Cancel.
2025-09-16 19:36:09 - INFO - Data received from server
2025-09-16 19:41:09 - INFO - Getting data from server
2025-09-16 19:41:10 - INFO - Start schedule normalization
2025-09-16 19:41:10 - INFO - Schedule is the same. Cancel.
2025-09-16 19:41:10 - INFO - Data received from server
2025-09-16 19:46:10 - INFO - Getting data from server
2025-09-16 19:46:12 - INFO - Start schedule normalization
2025-09-16 19:46:12 - INFO - Schedule is the same. Cancel.
2025-09-16 19:46:12 - INFO - Data received from server
2025-09-16 19:51:12 - INFO - Getting data from server
2025-09-16 19:51:13 - INFO - Start schedule normalization
2025-09-16 19:51:13 - INFO - Schedule is the same. Cancel.
2025-09-16 19:51:13 - INFO - Data received from server
2025-09-16 19:56:13 - INFO - Getting data from server
2025-09-16 19:56:14 - INFO - Start schedule normalization
2025-09-16 19:56:14 - INFO - Schedule is the same. Cancel.
2025-09-16 19:56:14 - INFO - Data received from server
2025-09-16 20:01:14 - INFO - Getting data from server
2025-09-16 20:01:16 - INFO - Start schedule normalization
2025-09-16 20:01:16 - INFO - Schedule is the same. Cancel.
2025-09-16 20:01:16 - INFO - Data received from server
2025-09-16 20:06:16 - INFO - Getting data from server
2025-09-16 20:06:17 - INFO - Start schedule normalization
2025-09-16 20:06:17 - INFO - Schedule normalized
2025-09-16 20:06:17 - INFO - Data received from server
2025-09-16 20:11:17 - INFO - Getting data from server
2025-09-16 20:11:19 - INFO - Start schedule normalization
2025-09-16 20:11:19 - INFO - Schedule normalized
2025-09-16 20:11:19 - INFO - Data received from server
2025-09-16 20:16:19 - INFO - Getting data from server
2025-09-16 20:16:20 - INFO - Start schedule normalization
2025-09-16 20:16:20 - INFO - Schedule is the same. Cancel.
2025-09-16 20:16:20 - INFO - Data received from server
2025-09-16 20:17:42 - INFO - 6983370282 used GET SCHEDULE FUNC and choice Понедельник
2025-09-16 20:17:43 - INFO - 6983370282 used GET SCHEDULE FUNC and choice Среда
2025-09-16 20:21:20 - INFO - Getting data from server
2025-09-16 20:21:22 - INFO - Start schedule normalization
2025-09-16 20:21:22 - INFO - Schedule normalized
2025-09-16 20:21:22 - INFO - Data received from server
2025-09-16 20:26:22 - INFO - Getting data from server
2025-09-16 20:26:24 - INFO - Start schedule normalization
2025-09-16 20:26:24 - INFO - Schedule is the same. Cancel.
2025-09-16 20:26:24 - INFO - Data received from server
2025-09-16 20:31:24 - INFO - Getting data from server
2025-09-16 20:31:26 - INFO - Start schedule normalization
2025-09-16 20:31:26 - INFO - Schedule is the same. Cancel.
2025-09-16 20:31:26 - INFO - Data received from server
2025-09-16 20:36:26 - INFO - Getting data from server
2025-09-16 20:36:27 - INFO - Start schedule normalization
2025-09-16 20:36:27 - INFO - Schedule is the same. Cancel.
2025-09-16 20:36:27 - INFO - Data received from server
2025-09-16 20:41:27 - INFO - Getting data from server
2025-09-16 20:41:29 - INFO - Start schedule normalization
2025-09-16 20:41:29 - INFO - Schedule is the same. Cancel.
2025-09-16 20:41:29 - INFO - Data received from server
2025-09-16 20:46:29 - INFO - Getting data from server
2025-09-16 20:46:30 - INFO - Start schedule normalization
2025-09-16 20:46:30 - INFO - Schedule is the same. Cancel.
2025-09-16 20:46:30 - INFO - Data received from server
2025-09-16 20:51:30 - INFO - Getting data from server
2025-09-16 20:51:32 - INFO - Start schedule normalization
2025-09-16 20:51:32 - INFO - Schedule is the same. Cancel.
2025-09-16 20:51:32 - INFO - Data received from server
2025-09-16 20:56:32 - INFO - Getting data from server
2025-09-16 20:56:33 - INFO - Start schedule normalization
2025-09-16 20:56:33 - INFO - Schedule is the same. Cancel.
2025-09-16 20:56:33 - INFO - Data received from server
2025-09-16 20:56:35 - ERROR - Infinity polling: polling exited
2025-09-16 20:56:35 - ERROR - Break infinity polling
